Workbook

Sheet Sheet4

Sheet LOOKUP
A1: SHIFT | B1: RIG TYPE | C1: ASET NUMBER | D1: REQUESTER | E1: APPROVED BY | F1: LEVEL | G1: ORDERED PARTS | H1: SUPPLIER | I1: ASIGNED PART
A2: D/S | B2: JUMBO | C2: DD122 | D2: LACHY | E2: J Tarbolton | F2: SOUTH | G2: SHANK T38 RD520/525 D45 L525 | H2: SANDVIK | I2: JUMBO
A3: N/S | B3: SOLO | C3: DD159 | D3: HOGES | E3: D Christensen | F3: NORTH | G3: COUPLING SLEEVE T38/T38 | H3: SANDVIK | I3: JUMBO
D4: TEX | E4: M Jimmi | G4: SHANK T45 RD520/525 D45 L525 | H4: SANDVIK | I4: JUMBO
D5: DELTON | G5: COUPLING SLEEVE T45/T38 | H5: SANDVIK | I5: JUMBO
D6: HAMISH | G6: BIT ADAPTOR T45F/T38M | H6: SANDVIK | I6: JUMBO
D7: DANIEL | G7: SPEEDY BIT A340 45MM XT49 | H7: SANDVIK | I7: JUMBO
D8: TRENT | G8: A340X43MM BUTTON BIT | H8: SANDVIK | I8: JUMBO
D9: NEWBOLT | G9: A340X45MM BUTTON BIT | H9: SANDVIK | I9: JUMBO
D10: EINO | G10: SPEEDY BIT A340 45MM | H10: SANDVIK | I10: JUMBO
D11: SIMON | G11: A340X48MM TC BUTTON BIT | H11: SANDVIK | I11: JUMBO
D12: BAREND | G12: A340X51MM RETRAC BIT | H12: SANDVIK | I12: JUMBO
D13: UNO | G13: REAMING BIT A340 102MM | H13: SANDVIK | I13: JUMBO
D14: VALDEZ | G14: T38X64MM BUTTON BIT | H14: SANDVIK | I14: JUMBO
D15: DARYL | G15: DRIFTER ROD T38 H35 A340 L=309 | H15: SANDVIK | I15: JUMBO
D16: GEOFREY | G16: DRIFTER ROD T38 H35 A340 L=370 | H16: SANDVIK | I16: JUMBO
... D23: MARISE | G23: MF ROD R32 | H23: SANDVIK | I23: JUMBO
D24: MARTIN
D25: DINNY | G25: T38 DOLLY 47MM | H25: SANDVIK | I25: JUMBO
G26: T38 DOLLY 39MM | H26: SANDVIK | I26: JUMBO
G28: MD BOLT DRIVER 900MM ""T"" THREA | H28: DSI | I28: JUMBO
G29: MD BOLT DRIVER 900MM T45 | H29: DSI | I29: JUMBO
G31: BOLTING CENTRALISER DIA 70MM FRONT | H31: MASPRO | I31: JUMBO
G32: BOLTING CENTRALISER DIA 70MM BACK | H32: MASPRO | I32: JUMBO
G33: BOLTING CENTRALISER DIA 66MM | H33: MASPRO | I33: JUMBO
G34: BORING CENTRALISER DIA 48MM | H34: MASPRO | I34: JUMBO
G35: BORING CENTRALISER DIA 41MM | H35: MASPRO | I35: JUMBO
G36: BOLTING CENTRALISER DIA 66MM | H36: SANDVIK - NAM | I36: JUMBO
G37: BORING CENTRALISER DIA 48MM | H37: SANDVIK - NAM | I37: JUMBO
G38: BORING CENTRALISER DIA 41MM | H38: SANDVIK - NAM | I38: JUMBO
H41: Above Portal
H42: 6.2 | I42: Height
H43: 18
I44: =H43*H42 -> 111.6
H47: Left of Portal
H48: 5.8 | I48: Height
H49: 3
I50: =H48*H49 -> 17.4
H53: Left of Portal
H54: 5.8 | I54: Height
...

Sheet JAN 26
E1: Unit Cost | J1: 308.1 | K1: 45.12 | L1: 68 | M1: 61.09 | N1: 61.09 | O1: 61.09 | P1: 498.85 | Q1: 513.01 | R1: 639 | S1: 443.78 | T1: 317.43 | U1: 184.75 | V1: 276.63 | W1: 439.59 | X1: 794.42 | Y1: 726.72 | Z1: 66.52 | AA1: 78.93 | AB1: 108.19 | AC1: 94.13 | AD1: 343.33 | AE1: 136.44 | AF1: 69.96 | AG1: 96.3 | AH1: 96.3
E2: Monthly Jumbo Cost | H2: =SUM(J2:AH2) -> 1880.73 | J2: =J1*J3 -> 924.3 | K2: =K1*K3 -> 0 | L2: =L1*L3 -> 0 | M2: =M1*M3 -> 0 | N2: =N1*N3 -> 0 | O2: =O1*O3 -> 0 | P2: =P1*P3 -> 0 | Q2: =Q1*Q3 -> 0 | ... AH2: =AH1*AH3 -> 0
J3: =SUM(J6:J417) -> 3 | K3: =SUM(K6:K417) -> 0 | L3: =SUM(L6:L417) -> 0 | M3: =SUM(M6:M417) -> 0 | N3: =SUM(N6:N417) -> 0 | O3: =SUM(O6:O417) -> 0 | P3: =SUM(P6:P417) -> 0 | Q3: =SUM(Q6:Q417) -> 0 | ... AH3: =SUM(AH6:AH417) -> 0
J4: SHANKS | K4: CENTRLALISER | P4: BORING STEELS | S4: BOLTING & EXTENSION STEELS | W4: SCALING STEELS | X4: MD ACCESSORIES | Z4: JUMBO BOLTING | AA4: JUMBO BORING | AD4: JUMBO REAMER & CABLES | AF4: COUPLING SLEEVES | AG4: DOLLY
B5: DATE | C5: MONTH | D5: RIG TYPE | E5: SHIFT | F5: RIG | G5: REQUESTER | H5: APPROVED BY | I5: LEVEL | J5: SHANK T38 RD520/525 D45 L525 | K5: BOLTING CENTRALISER DIA 70MM FRONT | L5: BOLTING CENTRALISER DIA 70MM BACK | M5: BOLTING CENTRALISER DIA 66MM | N5: BORING CENTRALISER DIA 48MM | O5: BORING CENTRALISER DIA 41MM | P5: DRIFTER ROD T38 H35 A340 L=370 | Q5: DRIFTER ROD T38 H35 A340 L=430 | R5: DRIFTER ROD T38 R39 A340 L=491 | S5: DRIFTER ROD T38 H35 A340 L=309 | T5: MF ROD T38 R39 L=3050MM | U5: EXTENSION ROD T38 R39 L = 915M | V5: MF ROD T38 R39 L=915MM | W5: T38 EXTENSION ROUND ROD L3050MM | X5: MD BOLT DRIVER 900MM ""T"" THREA | Y5: MD BOLT DRIVER 900MM T45 | Z5: A340X43MM BUTTON BIT | AA5: A340X45MM BUTTON BIT | AB5: A340X48MM TC BUTTON BIT | AC5: A340X51MM RETRAC BIT | AD5: REAMING BIT A340 102MM | AE5: T38X64MM BUTTON BIT | AF5: COUPLING SLEEVE T38/T38 | AG5: T38 DOLLY 47MM | AH5: T38 DOLLY 39MM
B6: 46024 | C6: =IF(B6="","",MONTH(B6)) -> 1 | D6: =VLOOKUP(F6,LOOKUP!$C$2:$C$8,2,0) -> #REF! | E6: NS | F6: DD122 | G6: W. Cox | H6: J. Tarbolton | I6: South Portal | J6: 3 | R6: 1 | T6: 1
C7: =IF(B7="","",MONTH(B7)) | D7: =VLOOKUP(F7,LOOKUP!$C$2:$C$8,2,0) -> #N/A
C8: =IF(B8="","",MONTH(B8)) | D8: =VLOOKUP(F8,LOOKUP!$C$2:$C$8,2,0) -> #N/A
C9: =IF(B9="","",MONTH(B9)) | D9: =VLOOKUP(F9,LOOKUP!$C$2:$C$8,2,0) -> #N/A
C10: =IF(B10="","",MONTH(B10)) | D10: =VLOOKUP(F10,LOOKUP!$C$2:$C$8,2,0) -> #N/A
C11: =IF(B11="","",MONTH(B11)) | D11: =VLOOKUP(F11,LOOKUP!$C$2:$C$8,2,0) -> #N/A
C12: =IF(B12="","",MONTH(B12)) | D12: =VLOOKUP(F12,LOOKUP!$C$2:$C$8,2,0) -> #N/A
C13: =IF(B13="","",MONTH(B13)) | D13: =VLOOKUP(F13,LOOKUP!$C$2:$C$8,2,0) -> #N/A
C14: =IF(B14="","",MONTH(B14)) | D14: =VLOOKUP(F14,LOOKUP!$C$2:$C$8,2,0) -> #N/A
C15: =IF(B15="","",MONTH(B15)) | D15: =VLOOKUP(F15,LOOKUP!$C$2:$C$8,2,0) -> #N/A
C16: =IF(B16="","",MONTH(B16)) | D16: =VLOOKUP(F16,LOOKUP!$C$2:$C$8,2,0) -> #N/A
C17: =IF(B17="","",MONTH(B17)) | D17: =VLOOKUP(F17,LOOKUP!$C$2:$C$8,2,0) -> #N/A
C18: =IF(B18="","",MONTH(B18)) | D18: =VLOOKUP(F18,LOOKUP!$C$2:$C$8,2,0) -> #N/A
... C180: =IF(B180="","",MONTH(B180)) | D180: =VLOOKUP(F180,LOOKUP!$C$2:$C$8,2,0) -> #N/A
C181: =IF(B181="","",MONTH(B181))
C182: =IF(B182="","",MONTH(B182))
C183: =IF(B183="","",MONTH(B183))
C184: =IF(B184="","",MONTH(B184))
C185: =IF(B185="","",MONTH(B185))
C186: =IF(B186="","",MONTH(B186))
C187: =IF(B187="","",MONTH(B187))
C188: =IF(B188="","",MONTH(B188))
C189: =IF(B189="","",MONTH(B189))
C190: =IF(B190="","",MONTH(B190))
C191: =IF(B191="","",MONTH(B191))
C192: =IF(B192="","",MONTH(B192))
... C417: =IF(B417="","",MONTH(B417))
B422: Row Labels | C422: Count of DRILL_ROD_ST68_SAND
B423: (blank)
B424: JESSE ANDERSON
B425: Grand Total

Sheet FEB 26
E1: Unit Cost | J1: 308.1 | K1: 45.12 | L1: 68 | M1: 61.09 | N1: 61.09 | O1: 61.09 | P1: 498.85 | Q1: 513.01 | R1: 639 | S1: 443.78 | T1: 317.43 | U1: 184.75 | V1: 276.63 | W1: 439.59 | X1: 794.42 | Y1: 726.72 | Z1: 66.52 | AA1: 78.93 | AB1: 108.19 | AC1: 94.13 | AD1: 343.33 | AE1: 136.44 | AF1: 69.96 | AG1: 96.3 | AH1: 96.3
E2: Monthly Jumbo Cost | H2: =SUM(J2:AH2) -> 19790.32 | J2: =J1*J3 -> 5237.7 | K2: =K1*K3 -> 0 | L2: =L1*L3 -> 0 | M2: =M1*M3 -> 549.81 | N2: =N1*N3 -> 0 | O2: =O1*O3 -> 122.18 | P2: =P1*P3 -> 0 | Q2: =Q1*Q3 -> 0 | ... AH2: =AH1*AH3 -> 0
J3: =SUM(J6:J420) -> 17 | K3: =SUM(K6:K420) -> 0 | L3: =SUM(L6:L420) -> 0 | M3: =SUM(M6:M420) -> 9 | N3: =SUM(N6:N420) -> 0 | O3: =SUM(O6:O420) -> 2 | P3: =SUM(P6:P420) -> 0 | Q3: =SUM(Q6:Q420) -> 0 | ... AH3: =SUM(AH6:AH420) -> 0
J4: SHANKS | K4: CENTRLALISER | P4: BORING STEELS | S4: BOLTING & EXTENSION STEELS | W4: SCALING STEELS | X4: MD ACCESSORIES | Z4: JUMBO BOLTING | AA4: JUMBO BORING | AD4: JUMBO REAMER & CABLES | AF4: COUPLING SLEEVES | AG4: DOLLY
B5: DATE | C5: MONTH | D5: RIG TYPE | E5: SHIFT | F5: RIG | G5: REQUESTER | H5: APPROVED BY | I5: LEVEL | J5: SHANK T38 RD520/525 D45 L525 | K5: BOLTING CENTRALISER DIA 70MM FRONT | L5: BOLTING CENTRALISER DIA 70MM BACK | M5: BOLTING CENTRALISER DIA 66MM | N5: BORING CENTRALISER DIA 48MM | O5: BORING CENTRALISER DIA 41MM | P5: DRIFTER ROD T38 H35 A340 L=370 | Q5: DRIFTER ROD T38 H35 A340 L=430 | R5: DRIFTER ROD T38 R39 A340 L=491 | S5: DRIFTER ROD T38 H35 A340 L=309 | T5: MF ROD T38 R39 L=3050MM | U5: EXTENSION ROD T38 R39 L = 915M | V5: MF ROD T38 R39 L=915MM | W5: T38 EXTENSION ROUND ROD L3050MM | X5: MD BOLT DRIVER 900MM ""T"" THREA | Y5: MD BOLT DRIVER 900MM T45 | Z5: A340X43MM BUTTON BIT | AA5: A340X45MM BUTTON BIT | AB5: A340X48MM TC BUTTON BIT | AC5: A340X51MM RETRAC BIT | AD5: REAMING BIT A340 102MM | AE5: T38X64MM BUTTON BIT | AF5: COUPLING SLEEVE T38/T38 | AG5: T38 DOLLY 47MM | AH5: T38 DOLLY 39MM
B6: 03.02.2026 | C6: FEB | D6: =VLOOKUP(F6,LOOKUP!$C$2:$C$8,2,0) -> #REF! | E6: NS | F6: DD122 | G6: Hoges | H6: J. Tarbolton | I6: South Portal | J6: 1 | R6: 1 | T6: 1
B7: 06.02.2026 | C7: FEB | D7: JUMBO | E7: NS | F7: DD122 | G7: Hoges | H7: J. Tarbolton | I7: South Portal | AF7: 1
B8: 07.02.2026 | C8: FEB | D8: JUMBO | E8: NS | F8: DD122 | G8: Hoges | H8: J. Tarbolton | I8: South Portal | J8: 2
B9: 07.02.2026 | C9: FEB | D9: JUMBO | E9: D/S | F9: DD122 | G9: Marise | H9: J. Tarbolton | I9: South Portal | M9: 2
B10: 09.02.2026 | C10: FEB | D10: JUMBO | E10: NS | F10: DD122 | G10: Hoges | H10: J. Tarbolton | I10: South Portal | J10: 2
B11: 10.02.2026 | C11: FEB | D11: JUMBO | E11: NS | F11: DD122 | G11: Hoges | H11: J. Tarbolton | I11: South Portal | M11: 2
B12: 11.02.2026 | C12: FEB | D12: JUMBO | E12: NS | F12: DD122 | G12: Hoges | H12: J. Tarbolton | I12: South Portal | J12: 1 | Z12: 10
B13: 12.02.2026 | C13: FEB | D13: JUMBO | E13: NS | F13: DD122 | G13: Hoges | H13: J. Tarbolton | I13: South Portal | J13: 2
B14: 14.02.2026 | C14: FEB | D14: JUMBO | E14: NS | F14: DD122 | G14: Hoges | H14: J. Tarbolton | I14: South Portal | J14: 1
B15: 16.02.2026 | C15: FEB | D15: JUMBO | E15: D/S | F15: DD122 | G15: Hoges | H15: J. Tarbolton | I15: South Portal | J15: 1 | X15: 1
B16: 16.02.2026 | C16: FEB | D16: JUMBO | E16: D/S | F16: DD122 | G16: Hoges | H16: J. Tarbolton | I16: South Portal | J16: 1 | X16: 1
B17: 21.02.2026 | C17: FEB | D17: JUMBO | G17: Pete | H17: J. Tarbolton | I17: South Portal | J17: 1 | AG17: 2
B18: 21.02.2026 | C18: FEB | D18: JUMBO | E18: D/S | F18: DD122 | G18: Hamish | H18: J. Tarbolton | I18: South Portal | J18: 1 | Z18: 10 | AA18: 10 | AG18: 2
B19: 22.02.2026 | C19: FEB | D19: JUMBO | F19: DD159 | G19: Tex | H19: J. Tarbolton | I19: South Portal | J19: 1 | O19: 2 | U19: 1 | V19: 1 | X19: 2 | Z19: 10 | AA19: 10 | AB19: 10 | AD19: 6 | AE19: 5 | AF19: 5
B20: 25.02.2026 | C20: FEB | D20: JUMBO | E20: D/S | F20: DD122 | G20: DELTON | H20: J. Tarbolton | I20: South Portal | M20: 2
B21: 27.02.2026 | C21: FEB | D21: JUMBO | E21: D/S | F21: DD122 | G21: DELTON | H21: J. Tarbolton | I21: South Portal | J21: 2 | M21: 3 | AB21: 10
B22: 28.02.2026 | C22: FEB | D22: JUMBO | E22: D/S | F22: DD122 | G22: DELTON | H22: J. Tarbolton | I22: South Portal | J22: 1
C23: =IF(B23="","",MONTH(B23)) | D23: =VLOOKUP(F23,LOOKUP!$C$2:$C$8,2,0) -> #N/A
C24: =IF(B24="","",MONTH(B24)) | D24: =VLOOKUP(F24,LOOKUP!$C$2:$C$8,2,0) -> #N/A
C25: =IF(B25="","",MONTH(B25)) | D25: =VLOOKUP(F25,LOOKUP!$C$2:$C$8,2,0) -> #N/A
C26: =IF(B26="","",MONTH(B26)) | D26: =VLOOKUP(F26,LOOKUP!$C$2:$C$8,2,0) -> #N/A
C27: =IF(B27="","",MONTH(B27)) | D27: =VLOOKUP(F27,LOOKUP!$C$2:$C$8,2,0) -> #N/A
C28: =IF(B28="","",MONTH(B28)) | D28: =VLOOKUP(F28,LOOKUP!$C$2:$C$8,2,0) -> #N/A
C29: =IF(B29="","",MONTH(B29)) | D29: =VLOOKUP(F29,LOOKUP!$C$2:$C$8,2,0) -> #N/A
C30: =IF(B30="","",MONTH(B30)) | D30: =VLOOKUP(F30,LOOKUP!$C$2:$C$8,2,0) -> #N/A
C31: =IF(B31="","",MONTH(B31)) | D31: =VLOOKUP(F31,LOOKUP!$C$2:$C$8,2,0) -> #N/A
C32: =IF(B32="","",MONTH(B32)) | D32: =VLOOKUP(F32,LOOKUP!$C$2:$C$8,2,0) -> #N/A
C33: =IF(B33="","",MONTH(B33)) | D33: =VLOOKUP(F33,LOOKUP!$C$2:$C$8,2,0) -> #N/A
C34: =IF(B34="","",MONTH(B34)) | D34: =VLOOKUP(F34,LOOKUP!$C$2:$C$8,2,0) -> #N/A
... C183: =IF(B183="","",MONTH(B183)) | D183: =VLOOKUP(F183,LOOKUP!$C$2:$C$8,2,0) -> #N/A
C184: =IF(B184="","",MONTH(B184))
C185: =IF(B185="","",MONTH(B185))
C186: =IF(B186="","",MONTH(B186))
C187: =IF(B187="","",MONTH(B187))
C188: =IF(B188="","",MONTH(B188))
...

Sheet MAR 26
E1: Unit Cost | J1: 308.1 | K1: 45.12 | L1: 68 | M1: 61.09 | N1: 61.09 | O1: 61.09 | P1: 498.85 | Q1: 513.01 | R1: 639 | S1: 443.78 | T1: 317.43 | U1: 184.75 | V1: 276.63 | W1: 439.59 | X1: 794.42 | Y1: 726.72 | Z1: 66.52 | AA1: 78.93 | AB1: 108.19 | AC1: 94.13 | AD1: 343.33 | AE1: 136.44 | AF1: 69.96 | AG1: 96.3 | AH1: 96.3
E2: Monthly Jumbo Cost | H2: =SUM(J2:AH2) -> 34267.76 | J2: =J1*J3 -> 4005.3 | K2: =K1*K3 -> 0 | L2: =L1*L3 -> 408 | M2: =M1*M3 -> 427.63 | N2: =N1*N3 -> 427.63 | O2: =O1*O3 -> 0 | P2: =P1*P3 -> 2494.25 | Q2: =Q1*Q3 -> 0 | ... AH2: =AH1*AH3 -> 0
J3: =SUM(J6:J403) -> 13 | K3: =SUM(K6:K403) -> 0 | L3: =SUM(L6:L403) -> 6 | M3: =SUM(M6:M403) -> 7 | N3: =SUM(N6:N403) -> 7 | O3: =SUM(O6:O403) -> 0 | P3: =SUM(P6:P403) -> 5 | Q3: =SUM(Q6:Q403) -> 0 | ... AH3: =SUM(AH6:AH403) -> 0
J4: SHANKS | K4: CENTRLALISER | P4: BORING STEELS | S4: BOLTING & EXTENSION STEELS | W4: SCALING STEELS | X4: MD ACCESSORIES | Z4: JUMBO BOLTING | AA4: JUMBO BORING | AD4: JUMBO REAMER & CABLES | AF4: COUPLING SLEEVES | AG4: DOLLY
B5: DATE | C5: MONTH | D5: RIG TYPE | E5: SHIFT | F5: RIG | G5: REQUESTER | H5: APPROVED BY | I5: LEVEL | J5: SHANK T38 RD520/525 D45 L525 | K5: BOLTING CENTRALISER DIA 70MM FRONT | L5: BOLTING CENTRALISER DIA 70MM BACK | M5: BOLTING CENTRALISER DIA 66MM | N5: BORING CENTRALISER DIA 48MM | O5: BORING CENTRALISER DIA 41MM | P5: DRIFTER ROD T38 H35 A340 L=370 | Q5: DRIFTER ROD T38 H35 A340 L=430 | R5: DRIFTER ROD T38 R39 A340 L=491 | S5: DRIFTER ROD T38 H35 A340 L=309 | T5: MF ROD T38 R39 L=3050MM | U5: EXTENSION ROD T38 R39 L = 915M | V5: MF ROD T38 R39 L=915MM | W5: T38 EXTENSION ROUND ROD L3050MM | X5: MD BOLT DRIVER 900MM ""T"" THREA | Y5: MD BOLT DRIVER 900MM T45 | Z5: A340X43MM BUTTON BIT | AA5: A340X45MM BUTTON BIT | AB5: A340X48MM TC BUTTON BIT | AC5: A340X51MM RETRAC BIT | AD5: REAMING BIT A340 102MM | AE5: T38X64MM BUTTON BIT | AF5: COUPLING SLEEVE T38/T38 | AG5: T38 DOLLY 47MM | AH5: T38 DOLLY 39MM
B6: 02.03.2026 | C6: MARCH | D6: JUMBO | E6: D/S | F6: DD122 | G6: DELTON | H6: J. Tarbolton | I6: South Portal | J6: 1 | M6: 2 | Z6: 10 | AA6: 10
B7: 02.03.2026 | C7: MARCH | D7: JUMBO | E7: D/S | F7: DD159 | G7: Marise | H7: J. Tarbolton | I7: South Portal | N7: 4
B8: 03.03.2027 | C8: MARCH | D8: JUMBO | E8: D/S | F8: DD159 | G8: DELTON | H8: J. Tarbolton | I8: South Portal | Z8: 10 | AA8: 10
B9: 06.03.2026 | C9: MARCH | D9: JUMBO | E9: D/S | F9: DD159 | G9: Marise | H9: J. Tarbolton | I9: South Portal | AB9: 10
B10: 06.03.2026 | C10: MARCH | D10: JUMBO | E10: D/S | F10: DD122 | G10: Hamish | H10: J. Tarbolton | I10: South Portal | AD10: 3
B11: 06.03.2026 | C11: MARCH | D11: JUMBO | E11: D/S | F11: DD159 | G11: Marise | H11: J. Tarbolton | I11: South Portal | S11: 1
B12: 06.03.2027 | C12: MARCH | D12: JUMBO | E12: D/S | F12: DD122 | G12: Hamish | H12: J. Tarbolton | I12: South Portal | U12: 1
B13: 07.03.2028 | C13: MARCH | D13: JUMBO | E13: D/S | F13: DD159 | G13: Hamish | H13: J. Tarbolton | I13: South Portal | J13: 2 | L13: 1 | Z13: 10 | AA13: 10
B14: 08.03.2029 | C14: MARCH | D14: JUMBO | E14: D/S | F14: DD122 | G14: DELTON | H14: J. Tarbolton | I14: South Portal | P14: 2 | S14: 2 | W14: 1
B15: 09.03.2026 | C15: MARCH | D15: JUMBO | E15: D/S | F15: DD122 | G15: Tex | H15: DARYL | I15: South Portal | J15: 2 | AF15: 2
B16: 10.03.2026 | C16: MARCH | D16: JUMBO | E16: D/S | F16: DD159 | G16: DANI | H16: DARYL | I16: South Portal | J16: 1 | S16: 1 | T16: 1 | W16: 2 | AF16: 1
B17: 10.03.2027 | C17: MARCH | D17: JUMBO | E17: D/S | F17: DD159 | G17: DANI | H17: DARYL | I17: South Portal | J17: 1
B18: 11.03.2028 | C18: MARCH | D18: JUMBO | E18: D/S | F18: DD159 | G18: KAMBATA | H18: DARYL | I18: South Portal | AE18: 5
B19: 12.03.2026 | C19: MARCH | D19: JUMBO | E19: D/S | F19: DD159 | G19: UNO | H19: DARYL | I19: South Portal | Z19: 10 | AF19: 1
B20: 12.03.2027 | C20: MARCH | D20: JUMBO | E20: D/S | F20: DD159 | G20: Marise | H20: DARYL | I20: South Portal | J20: 1
B21: 12.03.2028 | C21: MARCH | D21: JUMBO | E21: D/S | F21: DD159 | G21: UNO | H21: DARYL | I21: South Portal | J21: 1
B22: 12.03.2029 | C22: MARCH | D22: JUMBO | E22: NS | F22: DD159 | G22: KAMBATA | H22: DARYL | I22: South Portal | Z22: 1
B23: 13.03.2030 | C23: MARCH | D23: JUMBO | E23: NS | F23: DD159 | G23: JUNIAS | H23: DARYL | I23: South Portal | X23: 2
B24: 13.03.2031 | C24: MARCH | D24: JUMBO | E24: NS | F24: DD159 | G24: MG | H24: DARYL | I24: South Portal | X24: 1
B25: 13.03.2031 | C25: MARCH | D25: JUMBO | E25: NS | F25: DD159 | G25: MG | H25: DARYL | I25: South Portal | M25: 1
B26: 14.03.2031 | C26: MARCH | D26: JUMBO | E26: NS | F26: DD122 | G26: VALDEZ | H26: DARYL | I26: South Portal | J26: 1
B27: 14.03.2032 | C27: MARCH | D27: JUMBO | E27: NS | F27: DD122 | G27: Tex | H27: DARYL | I27: South Portal | J27: 1
B28: 14.03.2033 | C28: MARCH | D28: JUMBO | E28: NS | F28: DD159 | G28: Marise | H28: DARYL | I28: South Portal | AF28: 2
B29: 15.03.2034 | C29: MARCH | D29: JUMBO | E29: NS | F29: DD159 | G29: JK | H29: DARYL | I29: South Portal | N29: 3 | Z29: 10 | AA29: 10 | AD29: 4
B30: 15.03.2035 | C30: MARCH | D30: JUMBO | E30: NS | F30: DD122 | G30: Marise | H30: DARYL | I30: South Portal | AF30: 2
B31: 16.03.2036 | C31: MARCH | D31: JUMBO | E31: NS | F31: DD159 | G31: MG | H31: DARYL | I31: South Portal | Z31: 10 | AA31: 10
B32: 16.03.2037 | C32: MARCH | D32: JUMBO | E32: D/S | F32: DD159 | G32: JUNIAS | H32: DARYL | I32: South Portal | L32: 5
B33: 17.03.2038 | C33: MARCH | D33: JUMBO | E33: D/S | F33: DD159 | G33: DELTON | H33: DARYL | I33: South Portal | M33: 4
B34: 20.03.2026 | C34: MARCH | D34: JUMBO | E34: D/S | F34: DD159 | G34: DARREN | H34: DARYL | I34: South Portal | J34: 2
B35: 20.03.2026 | C35: MARCH | D35: JUMBO | E35: D/S | F35: DD122 | G35: MG | H35: DARYL | I35: South Portal | P35: 3 | Z35: 1
B36: 20.03.2026 | C36: MARCH | D36: JUMBO | E36: D/S | F36: DD159 | G36: MG | H36: DARYL | I36: South Portal | S36: 1 | Z36: 1 | AA36: 1
B37: 25.03.2026 | C37: MARCH | D37: JUMBO | E37: D/S | F37: DD159 | G37: SIMON | H37: DARYL | I37: South Portal | X37: 1
B38: 26.03.2026 | C38: MARCH | D38: JUMBO | E38: D/S | F38: DD159 | G38: DELTON | H38: DARYL | I38: South Portal | AB38: 10
B39: 27.03.2026 | C39: MARCH | D39: JUMBO | E39: D/S | F39: DD159 | G39: DANI | H39: DARYL | I39: South Portal | AB39: 10 | AD39: 4
B40: 29.03.2027 | C40: APRIL | D40: JUMBO | E40: D/S | F40: DD159 | G40: DANI | H40: DARYL | I40: South Portal | X40: 1 | Z40: 20
...

Sheet APR 26
E1: Unit Cost | J1: 308.1 | K1: 487.82742 | L1: 45.12 | M1: 68 | N1: 61.09 | O1: 61.09 | P1: 61.09 | Q1: 498.85 | R1: 513.01 | S1: 639 | T1: 443.78 | U1: 317.43 | V1: 184.75 | W1: 276.63 | X1: 439.59 | Y1: 794.42 | Z1: 726.72 | AB1: 66.52 | AC1: 78.93 | AD1: 79.93 | AE1: 108.19 | AF1: 94.13 | AG1: 343.33 | AH1: 136.44 | AI1: 69.96 | AJ1: 168.67893 | AK1: 390.14017 | AL1: 96.3 | AM1: 96.3
E2: Monthly Jumbo Cost | H2: =SUM(J2:AM2) -> 39065.177 | J2: =J1*J3 -> 616.2 | K2: =K1*K3 -> 2926.9645 | L2: =L1*L3 -> 541.44 | M2: =M1*M3 -> 136 | N2: =N1*N3 -> 122.18 | O2: =O1*O3 -> 122.18 | P2: =P1*P3 -> 122.18 | Q2: =Q1*Q3 -> 0 | ... AM2: =AM1*AM3 -> 0
J3: =SUM(J6:J403) -> 2 | K3: =SUM(K6:K403) -> 6 | L3: =SUM(L6:L403) -> 12 | M3: =SUM(M6:M403) -> 2 | N3: =SUM(N6:N403) -> 2 | O3: =SUM(O6:O403) -> 2 | P3: =SUM(P6:P403) -> 2 | Q3: =SUM(Q6:Q403) -> 0 | ... Z3: =SUM(Z6:Z403) -> 0 | AB3: =SUM(AB6:AB403) -> 80 | AC3: =SUM(AC6:AC403) -> 110 | AE3: =SUM(AE6:AE403) -> 30 | AF3: =SUM(AF6:AF403) -> 26 | AG3: =SUM(AG6:AG403) -> 13 | AH3: =SUM(AH6:AH403) -> 29 | AI3: =SUM(AI6:AI403) -> 0 | AJ3: =SUM(AJ6:AJ403) -> 7 | AK3: =SUM(AK6:AK403) -> 0 | AL3: =SUM(AL6:AL403) -> 1 | AM3: =SUM(AM6:AM403) -> 0
J4: SHANKS | L4: CENTRLALISER | Q4: BORING STEELS | T4: BOLTING & EXTENSION STEELS | X4: SCALING STEELS | Y4: MD ACCESSORIES | AB4: JUMBO BOLTING | AC4: JUMBO BORING | AG4: JUMBO REAMER & CABLES | AI4: COUPLING SLEEVES | AL4: DOLLY
B5: DATE | C5: MONTH | D5: RIG TYPE | E5: SHIFT | F5: RIG | G5: REQUESTER | H5: APPROVED BY | I5: LEVEL | J5: SHANK T38 RD520/525 D45 L525 | K5: SHANK T45 RD520/525 D45 L525 | L5: BOLTING CENTRALISER DIA 70MM FRONT | M5: BOLTING CENTRALISER DIA 70MM BACK | N5: BOLTING CENTRALISER DIA 66MM | O5: BORING CENTRALISER DIA 48MM | P5: BORING CENTRALISER DIA 41MM | Q5: DRIFTER ROD T38 H35 A340 L=370 | R5: DRIFTER ROD T38 H35 A340 L=430 | S5: DRIFTER ROD T38 R39 A340 L=491 | T5: DRIFTER ROD T38 H35 A340 L=309 | U5: MF ROD T38 R39 L=3050MM | V5: EXTENSION ROD T38 R39 L = 915M | W5: MF ROD T38 R39 L=915MM | X5: T38 EXTENSION ROUND ROD L3050MM | Y5: MD BOLT DRIVER 900MM ""T"" THREA | Z5: MD BOLT DRIVER 900MM T45 | AA5: BIT ADAPTOR T45F/T38M | AB5: A340X43MM BUTTON BIT | AC5: A340X45MM BUTTON BIT | AD5: SPEEDY BIT A340X45MM XT49 | AE5: A340X48MM TC BUTTON BIT | AF5: A340X51MM RETRAC BIT | AG5: REAMING BIT A340 102MM | AH5: T38X64MM BUTTON BIT | AI5: COUPLING SLEEVE T38/T38 | AJ5: COUPLING SLEEVE T45/T38 | AL5: T38 DOLLY 47MM | AM5: T38 DOLLY 39MM
B6: 46113 | C6: APRIL | D6: JUMBO | E6: D/S | F6: DD122 | G6: NEWBOLT | H6: D Christensen | I6: SOUTH
B7: 46113 | C7: APRIL | D7: JUMBO | E7: D/S | F7: DD122 | G7: QUINTEN | H7: D Christensen | I7: SOUTH | Y7: 1 | AE7: 2 | AG7: 5
B8: 46123 | C8: APRIL | D8: JUMBO | E8: D/S | F8: DD159 | G8: HAMISH | H8: D Christensen | I8: SOUTH | AB8: 10 | AC8: 10
B9: 46114 | C9: APRIL | D9: JUMBO | E9: D/S | F9: DD159 | G9: DANIEL | H9: D Christensen | I9: SOUTH | AG9: 2 | AH9: 2
B10: 46116 | C10: APRIL | D10: JUMBO | E10: D/S | F10: DD159 | G10: DANIEL | H10: D Christensen | I10: SOUTH | L10: 2 | Y10: 1
B11: 46117 | C11: APRIL | D11: JUMBO | E11: D/S | F11: DD159 | G11: SIMON | H11: D Christensen | I11: SOUTH | AH11: 5
B12: 46119 | C12: APRIL | D12: JUMBO | E12: D/S | F12: DD159 | G12: HAMISH | H12: D Christensen | I12: SOUTH | M12: 2 | AB12: 20
B13: 46120 | C13: APRIL | D13: JUMBO | E13: D/S | F13: DD122 | G13: HAMISH | H13: D Christensen | I13: SOUTH | J13: 1 | AC13: 10 | AE13: 10 | AH13: 5 | AJ13: 2
B14: 46120 | C14: APRIL | D14: JUMBO | E14: D/S | F14: DD159 | G14: QUINTEN | H14: D Christensen | I14: SOUTH | K14: 2
B15: 46121 | C15: APRIL | D15: JUMBO | E15: D/S | F15: DD159 | G15: GOMAA | H15: D Christensen | I15: SOUTH | J15: 1 | K15: 1 | U15: 1 | Y15: 1 | AL15: 1
B16: 46121 | C16: APRIL | D16: JUMBO | E16: D/S | F16: DD122 | G16: GOMAA | H16: D Christensen | I16: NORTH | AB16: 10
B17: 46124 | C17: APRIL | D17: JUMBO | E17: D/S | F17: DD122 | G17: NEWBOLT | H17: D Christensen | I17: NORTH | AH17: 2
B18: 46125 | C18: APRIL | D18: JUMBO | E18: D/S | F18: DD159 | G18: HOGES | H18: D Christensen | I18: SOUTH | AC18: 10 | AE18: 10
B19: 46125 | C19: APRIL | D19: JUMBO | E19: D/S | F19: DD122 | G19: GODFREY | H19: D Christensen | I19: NORTH | AH19: 6
B20: 46129 | C20: APRIL | D20: JUMBO | E20: D/S | F20: DD159 | G20: HAMISH | H20: D Christensen | I20: SOUTH | AC20: 10
B21: 46130 | C21: APRIL | D21: JUMBO | E21: D/S | F21: DD159 | G21: DELTON | H21: D Christensen | I21: SOUTH | AE21: 3 | AF21: 10
B22: 46130 | C22: APRIL | D22: JUMBO | E22: D/S | F22: DD122 | G22: DELTON | H22: D Christensen | I22: NORTH | O22: 2 | P22: 2
B23: 46131 | C23: APRIL | D23: JUMBO | E23: D/S | F23: DD159 | G23: HAMISH | H23: D Christensen | I23: SOUTH | L23: 2 | AF23: 6
B24: 46132 | C24: APRIL | D24: JUMBO | E24: N/S | F24: DD159 | G24: DELTON | H24: D Christensen | I24: SOUTH | Y24: 1 | AH24: 2
B25: 46133 | C25: APRIL | D25: JUMBO | E25: D/S | F25: DD122 | G25: GOMAA | H25: D Christensen | I25: NORTH | L25: 2 | N25: 2 | Y25: 1 | AC25: 10 | AF25: 10
B26: 46134 | C26: APRIL | D26: JUMBO | E26: D/S | F26: DD159 | G26: HOGES | H26: D Christensen | I26: SOUTH | K26: 1 | AC26: 20
B27: 46135 | C27: APRIL | D27: JUMBO | E27: D/S | F27: DD159 | G27: HOGES | H27: D Christensen | I27: SOUTH | L27: 3
B28: 46135 | C28: APRIL | D28: JUMBO | E28: N/S | F28: DD159 | G28: SIMON | H28: D Christensen | I28: SOUTH | AJ28: 5
B29: 46135 | C29: APRIL | D29: JUMBO | E29: N/S | F29: DD159 | G29: UNO | H29: D Christensen | I29: SOUTH
B30: 46136 | C30: APRIL | D30: JUMBO | E30: N/S | F30: DD159 | G30: HAMISH | H30: D Christensen | I30: SOUTH | AH30: 5
B31: 46136 | C31: APRIL | D31: JUMBO | E31: N/S | F31: DD122 | G31: VALDEZ | H31: D Christensen | I31: NORTH | K31: 2
B32: 46137 | C32: APRIL | D32: JUMBO | E32: D/S | F32: DD159 | G32: DARYL | H32: D Christensen | I32: SOUTH
B33: 46137 | C33: APRIL | D33: JUMBO | E33: D/S | F33: DD159 | G33: HOGES | H33: D Christensen | I33: SOUTH | AB33: 20 | AC33: 20
B34: 46141 | C34: APRIL | D34: JUMBO | E34: D/S | F34: DD122 | G34: HOGES | H34: D Christensen | I34: NORTH | AB34: 10 | AC34: 10
B35: 46142 | C35: APRIL | D35: JUMBO | E35: D/S | F35: DD159 | G35: HAMISH | H35: D Christensen | I35: SOUTH | L35: 3 | Y35: 1 | AB35: 10 | AC35: 10 | AD35: 20 | AE35: 5 | AG35: 6 | AH35: 2
C36: APRIL | D36: JUMBO
C37: APRIL | D37: JUMBO
C38: APRIL | D38: JUMBO
C39: APRIL | D39: JUMBO
C40: APRIL | D40: JUMBO
...

Sheet MAY 26
E1: Unit Cost | J1: 308.1 | K1: 487.82742 | L1: 45.12 | M1: 68 | N1: 61.09 | O1: 61.09 | P1: 61.09 | Q1: 498.85 | R1: 513.01 | S1: 639 | T1: 443.78 | U1: 317.43 | V1: 184.75 | W1: 276.63 | X1: 439.59 | Y1: 794.42 | Z1: 726.72 | AB1: 66.52 | AC1: 78.93 | AD1: 79.93 | AE1: 108.19 | AF1: 94.13 | AG1: 343.33 | AH1: 136.44 | AI1: 69.96 | AJ1: 168.67893 | AK1: 390.14017 | AL1: 96.3 | AM1: 96.3
E2: Monthly Jumbo Cost | H2: =SUM(J2:AM2) -> 39411.024 | J2: =J1*J3 -> 308.1 | K2: =K1*K3 -> 2926.9645 | L2: =L1*L3 -> 0 | M2: =M1*M3 -> 0 | N2: =N1*N3 -> 122.18 | O2: =O1*O3 -> 0 | P2: =P1*P3 -> 244.36 | Q2: =Q1*Q3 -> 498.85 | ... AM2: =AM1*AM3 -> 0
J3: =SUM(J6:J404) -> 1 | K3: =SUM(K6:K404) -> 6 | L3: =SUM(L6:L404) -> 0 | M3: =SUM(M6:M404) -> 0 | N3: =SUM(N6:N404) -> 2 | O3: =SUM(O6:O404) -> 0 | P3: =SUM(P6:P404) -> 4 | Q3: =SUM(Q6:Q404) -> 1 | ... Z3: =SUM(Z6:Z404) -> 0 | AB3: =SUM(AB6:AB404) -> 110 | AC3: =SUM(AC6:AC404) -> 62 | AE3: =SUM(AE6:AE404) -> 10 | AF3: =SUM(AF6:AF404) -> 8 | AG3: =SUM(AG6:AG404) -> 12 | AH3: =SUM(AH6:AH404) -> 27 | AI3: =SUM(AI6:AI404) -> 5 | AJ3: =SUM(AJ6:AJ404) -> 10 | AK3: =SUM(AK6:AK404) -> 0 | AL3: =SUM(AL6:AL404) -> 0 | AM3: =SUM(AM6:AM404) -> 0
J4: SHANKS | L4: CENTRLALISER | Q4: BORING STEELS | T4: BOLTING & EXTENSION STEELS | X4: SCALING STEELS | Y4: MD ACCESSORIES | AB4: JUMBO BOLTING | AC4: JUMBO BORING | AG4: JUMBO REAMER & CABLES | AI4: COUPLING SLEEVES | AL4: DOLLY
B5: DATE | C5: MONTH | D5: RIG TYPE | E5: SHIFT | F5: RIG | G5: REQUESTER | H5: APPROVED BY | I5: LEVEL | J5: SHANK T38 RD520/525 D45 L525 | K5: SHANK T45 RD520/525 D45 L525 | L5: BOLTING CENTRALISER DIA 70MM FRONT | M5: BOLTING CENTRALISER DIA 70MM BACK | N5: BOLTING CENTRALISER DIA 66MM | O5: BORING CENTRALISER DIA 48MM | P5: BORING CENTRALISER DIA 41MM | Q5: DRIFTER ROD T38 H35 A340 L=370 | R5: DRIFTER ROD T38 H35 A340 L=430 | S5: DRIFTER ROD T38 R39 A340 L=491 | T5: DRIFTER ROD T38 H35 A340 L=309 | U5: MF ROD T38 R39 L=3050MM | V5: EXTENSION ROD T38 R39 L = 915M | W5: MF ROD T38 R39 L=915MM | X5: T38 EXTENSION ROUND ROD L3050MM | Y5: MD BOLT DRIVER 900MM ""T"" THREA | Z5: MD BOLT DRIVER 900MM T45 | AA5: BIT ADAPTOR T45F/T38M | AB5: A340X43MM BUTTON BIT | AC5: A340X45MM BUTTON BIT | AD5: SPEEDY BIT A340X45MM XT49 | AE5: A340X48MM TC BUTTON BIT | AF5: A340X51MM RETRAC BIT | AG5: REAMING BIT A340 102MM | AH5: T38X64MM BUTTON BIT | AI5: COUPLING SLEEVE T38/T38 | AJ5: COUPLING SLEEVE T45/T38 | AL5: T38 DOLLY 47MM | AM5: T38 DOLLY 39MM
B6: 46143 | C6: =IF(B6="","",MONTH(B6)) -> 5 | D6: JUMBO | E6: D/S | F6: DD122 | G6: GEOFREY | H6: D Christensen | I6: NORTH | Y6: 1 | AA6: 1 | AH6: 1
B7: 46144 | C7: =IF(B7="","",MONTH(B7)) -> 5 | D7: JUMBO | E7: D/S | F7: DD159 | G7: DELTON | H7: D Christensen | I7: SOUTH | AB7: 10 | AC7: 10
B8: 46145 | C8: =IF(B8="","",MONTH(B8)) -> 5 | D8: JUMBO | E8: D/S | F8: DD122 | G8: GEOFREY | H8: D Christensen | I8: NORTH | N8: 2 | AA8: 2 | AD8: 10
B9: 46145 | C9: =IF(B9="","",MONTH(B9)) -> 5 | D9: JUMBO | E9: N/S | F9: DD159 | G9: HOGES | H9: D Christensen | I9: SOUTH | Y9: 1 | AB9: 10 | AC9: 10
B10: 46147 | C10: =IF(B10="","",MONTH(B10)) -> 5 | D10: JUMBO | E10: N/S | F10: DD159 | G10: JUNIAS | H10: D Christensen | I10: SOUTH | X10: 2 | AC10: 2
B11: 46147 | C11: =IF(B11="","",MONTH(B11)) -> 5 | D11: JUMBO | E11: D/S | F11: DD159 | G11: GEOFREY | H11: D Christensen | I11: SOUTH | AG11: 4
B12: 46147 | C12: =IF(B12="","",MONTH(B12)) -> 5 | D12: JUMBO | E12: N/S | F12: DD159 | G12: HOGES | H12: D Christensen | I12: SOUTH | AH12: 2
B13: 46150 | C13: =IF(B13="","",MONTH(B13)) -> 5 | D13: JUMBO | E13: N/S | F13: DD159 | G13: HOGES | H13: D Christensen | I13: SOUTH | AB13: 10 | AC13: 10 | AD13: 10 | AF13: 3
B14: 46150 | C14: =IF(B14="","",MONTH(B14)) -> 5 | D14: JUMBO | E14: N/S | F14: DD159 | G14: CHARL | H14: D Christensen | I14: NORTH | K14: 2
B15: 46152 | C15: =IF(B15="","",MONTH(B15)) -> 5 | D15: JUMBO | E15: N/S | F15: DD159 | G15: HOGES | H15: D Christensen | I15: NORTH | AB15: 10 | AC15: 10
B16: 46154 | C16: =IF(B16="","",MONTH(B16)) -> 5 | D16: JUMBO | E16: N/S | F16: DD122 | G16: HOGES | H16: D Christensen | I16: SOUTH | P16: 2 | AB16: 10 | AE16: 10
B17: 46156 | C17: =IF(B17="","",MONTH(B17)) -> 5 | D17: JUMBO | E17: N/S | F17: DD122 | G17: SIMON | H17: D Christensen | I17: NORTH | AG17: 5
B18: 46156 | C18: =IF(B18="","",MONTH(B18)) -> 5 | D18: JUMBO | E18: D/S | F18: DD159 | G18: HOGES | H18: D Christensen | I18: SOUTH | AB18: 10 | AJ18: 2
B19: 46156 | C19: =IF(B19="","",MONTH(B19)) -> 5 | D19: JUMBO | E19: N/S | F19: DD159 | G19: HAMISH | H19: D Christensen | I19: SOUTH | AC19: 10 | AD19: 10
B20: 46157 | C20: =IF(B20="","",MONTH(B20)) -> 5 | D20: JUMBO | E20: N/S | F20: DD159 | G20: HAMISH | H20: D Christensen | I20: SOUTH | Y20: 2 | AA20: 2
B21: 46157 | C21: =IF(B21="","",MONTH(B21)) -> 5 | D21: JUMBO | E21: N/S | F21: DD122 | G21: HAMISH | H21: D Christensen | I21: NORTH | AB21: 10 | AF21: 5
B22: 46158 | C22: =IF(B22="","",MONTH(B22)) -> 5 | D22: JUMBO | E22: D/S | F22: DD159 | G22: HOGES | H22: D Christensen | I22: SOUTH | AH22: 10
B23: 46159 | C23: =IF(B23="","",MONTH(B23)) -> 5 | D23: JUMBO | E23: N/S | F23: DD159 | G23: HAMISH | H23: D Christensen | I23: SOUTH | AB23: 20 | AC23: 10 | AD23: 10 | AG23: 3 | AJ23: 5
B24: 46162 | C24: 5 | D24: JUMBO | E24: N/S | F24: DD122 | G24: TEX | H24: D Christensen | I24: NORTH | J24: 1
B25: 46162 | C25: =IF(B25="","",MONTH(B25)) -> 5 | D25: JUMBO | E25: N/S | F25: DD159 | G25: HAMISH | H25: D Christensen | I25: SOUTH | AA25: 2
B26: 46162 | C26: =IF(B26="","",MONTH(B26)) -> 5 | D26: JUMBO | E26: N/S | F26: DD122 | G26: JL WILSON | H26: D Christensen | I26: NORTH | S26: 1
B27: 46163 | C27: =IF(B27="","",MONTH(B27)) -> 5 | D27: JUMBO | E27: N/S | F27: DD159 | G27: HAMISH | H27: D Christensen | I27: NORTH | K27: 1
B28: 46163 | C28: =IF(B28="","",MONTH(B28)) -> 5 | D28: JUMBO | E28: N/S | F28: DD159 | G28: HAMISH | H28: D Christensen | I28: NORTH | AH28: 5
B29: 46163 | C29: =IF(B29="","",MONTH(B29)) -> 5 | D29: JUMBO | E29: D/S | F29: DD159 | G29: DELTON | H29: D Christensen | I29: SOUTH | S29: 1 | T29: 1
B30: 46163 | C30: =IF(B30="","",MONTH(B30)) -> 5 | D30: JUMBO | E30: N/S | F30: DD122 | G30: TEX | H30: D Christensen | I30: NORTH | P30: 2
B31: 46164 | C31: =IF(B31="","",MONTH(B31)) -> 5 | D31: JUMBO | E31: N/S | F31: DD159 | G31: HAMISH | H31: D Christensen | I31: SOUTH | AH31: 5
B32: 46164 | C32: =IF(B32="","",MONTH(B32)) -> 5 | D32: JUMBO | E32: D/S | F32: DD122 | G32: DELTON | H32: D Christensen | I32: NORTH | Q32: 1
B33: 46165 | C33: =IF(B33="","",MONTH(B33)) -> 5 | D33: JUMBO | E33: N/S | F33: DD159 | G33: HAMISH | H33: D Christensen | I33: SOUTH | Y33: 2 | AA33: 2 | AD33: 10
B34: 46165 | C34: =IF(B34="","",MONTH(B34)) -> 5 | D34: JUMBO | E34: N/S | F34: DD159 | G34: JUNIAS | H34: D Christensen | I34: SOUTH | X34: 2 | Y34: 1 | AA34: 1
B35: 46166 | C35: =IF(B35="","",MONTH(B35)) -> 5 | D35: JUMBO | E35: D/S | F35: DD122 | G35: DELTON | H35: D Christensen | I35: NORTH | Y35: 1 | AA35: 2 | AI35: 5 | AJ35: 2
B36: 46170 | C36: =IF(B36="","",MONTH(B36)) -> 5 | D36: JUMBO | E36: N/S | F36: DD159 | G36: DELTON | I36: SOUTH | AB36: 10
B37: 46170 | C37: =IF(B37="","",MONTH(B37)) -> 5 | D37: JUMBO | E37: D/S | F37: DD122 | G37: SIMON | I37: NORTH | Y37: 1
B38: 46171 | C38: =IF(B38="","",MONTH(B38)) -> 5 | D38: JUMBO | E38: D/S | F38: DD122 | G38: SIMON | I38: NORTH | K38: 2 | AH38: 2 | AJ38: 1
B39: 46171 | C39: =IF(B39="","",MONTH(B39)) -> 5 | D39: JUMBO | E39: D/S | F39: DD159 | G39: SIMON | I39: SOUTH | AH39: 2
B40: 46173 | C40: =IF(B40="","",MONTH(B40)) -> 5 | D40: JUMBO | E40: D/S | F40: DD159 | G40: SIMON | I40: SOUTH | Y40: 1
...

Sheet JUNE 26
E1: Unit Cost | J1: 308.1 | K1: 487.82742 | L1: 45.12 | M1: 68 | N1: 61.09 | O1: 61.09 | P1: 61.09 | Q1: 498.85 | R1: 513.01 | S1: 639 | T1: 443.78 | U1: 317.43 | V1: 184.75 | W1: 276.63 | X1: 439.59 | Y1: 794.42 | Z1: 726.72 | AB1: 66.52 | AC1: 78.93 | AD1: 79.93 | AE1: 108.19 | AF1: 94.13 | AG1: 343.33 | AH1: 136.44 | AI1: 69.96 | AJ1: 168.67893 | AK1: 390.14017 | AL1: 96.3 | AM1: 96.3
E2: Monthly Jumbo Cost | H2: =SUM(J2:AM2) -> 34691.511 | J2: =J1*J3 -> 2156.7 | K2: =K1*K3 -> 9268.721 | L2: =L1*L3 -> 406.08 | M2: =M1*M3 -> 0 | N2: =N1*N3 -> 488.72 | O2: =O1*O3 -> 244.36 | P2: =P1*P3 -> 0 | Q2: =Q1*Q3 -> 0 | ... AM2: =AM1*AM3 -> 192.6
J3: =SUM(J6:J404) -> 7 | K3: =SUM(K6:K404) -> 19 | L3: =SUM(L6:L404) -> 9 | M3: =SUM(M6:M404) -> 0 | N3: =SUM(N6:N404) -> 8 | O3: =SUM(O6:O404) -> 4 | P3: =SUM(P6:P404) -> 0 | Q3: =SUM(Q6:Q404) -> 0 | ... Z3: =SUM(Z6:Z404) -> 7 | AB3: =SUM(AB6:AB404) -> 0 | AC3: =SUM(AC6:AC404) -> 0 | AE3: =SUM(AE6:AE404) -> 0 | AF3: =SUM(AF6:AF404) -> 15 | AG3: =SUM(AG6:AG404) -> 2 | AH3: =SUM(AH6:AH404) -> 20 | AI3: =SUM(AI6:AI404) -> 1 | AJ3: =SUM(AJ6:AJ404) -> 9 | AK3: =SUM(AK6:AK404) -> 0 | AL3: =SUM(AL6:AL404) -> 1 | AM3: =SUM(AM6:AM404) -> 2
J4: SHANKS | L4: CENTRLALISER | Q4: BORING STEELS | T4: BOLTING & EXTENSION STEELS | X4: SCALING STEELS | Y4: MD ACCESSORIES | AB4: JUMBO BOLTING | AC4: JUMBO BORING | AG4: JUMBO REAMER & CABLES | AI4: COUPLING SLEEVES | AL4: DOLLY
B5: DATE | C5: MONTH | D5: RIG TYPE | E5: SHIFT | F5: RIG | G5: REQUESTER | H5: APPROVED BY | I5: LEVEL | J5: SHANK T38 RD520/525 D45 L525 | K5: SHANK T45 RD520/525 D45 L525 | L5: BOLTING CENTRALISER DIA 70MM FRONT | M5: BOLTING CENTRALISER DIA 70MM BACK | N5: BOLTING CENTRALISER DIA 66MM | O5: BORING CENTRALISER DIA 48MM | P5: BORING CENTRALISER DIA 41MM | Q5: DRIFTER ROD T38 H35 A340 L=370 | R5: DRIFTER ROD T38 H35 A340 L=430 | S5: DRIFTER ROD T38 R39 A340 L=491 | T5: DRIFTER ROD T38 H35 A340 L=309 | U5: MF ROD T38 R39 L=3050MM | V5: EXTENSION ROD T38 R39 L = 915M | W5: MF ROD T38 R39 L=915MM | X5: T38 EXTENSION ROUND ROD L3050MM | Y5: MD BOLT DRIVER 900MM ""T"" THREA | Z5: MD BOLT DRIVER 900MM T45 | AA5: BIT ADAPTOR T45F/T38M | AB5: A340X43MM BUTTON BIT | AC5: A340X45MM BUTTON BIT | AD5: SPEEDY BIT A340X45MM XT49 | AE5: A340X48MM TC BUTTON BIT | AF5: A340X51MM RETRAC BIT | AG5: REAMING BIT A340 102MM | AH5: T38X64MM BUTTON BIT | AI5: COUPLING SLEEVE T38/T38 | AJ5: COUPLING SLEEVE T45/T38 | AL5: T38 DOLLY 47MM | AM5: T38 DOLLY 39MM
B6: 46174 | C6: 6 | D6: JUMBO | E6: N/S | F6: DD122 | G6: DELTON | I6: SOUTH | S6: 1 | X6: 1 | AF6: 5 | AJ6: 2
B7: 46174 | C7: 6 | D7: JUMBO | E7: D/S | F7: DD122 | G7: SIMON | I7: NORTH | Y7: 1
B8: 46176 | C8: 6 | D8: JUMBO | E8: D/S | F8: DD122 | G8: JUNIAS | I8: NORTH | K8: 1 | AJ8: 2
B9: 46176 | C9: 6 | D9: JUMBO | E9: N/S | F9: DD159 | G9: DELTON | I9: NORTH | Y9: 1
B10: 46176 | C10: 6 | D10: JUMBO | E10: D/S | F10: DD159 | G10: JUNIAS | I10: SOUTH | K10: 1 | Z10: 1 | AG10: 2 | AH10: 3
B11: 46176 | C11: 6 | D11: JUMBO | E11: N/S | F11: DD122 | G11: SIMON | I11: NORTH | L11: 2 | Z11: 1 | AD11: 10
B12: 46176 | C12: 6 | D12: JUMBO | E12: N/S | F12: DD159 | G12: SIMON | I12: SOUTH | Z12: 1 | AA12: 2
B13: 46178 | C13: 6 | D13: JUMBO | E13: N/S | F13: DD159 | G13: BRETT | I13: SOUTH | AF13: 6
B14: 46180 | C14: 6 | D14: JUMBO | E14: N/S | F14: DD159 | G14: BRETT | I14: SOUTH | J14: 1 | K14: 1 | AH14: 2
B15: 46181 | C15: 6 | D15: JUMBO | E15: N/S | F15: DD159 | G15: TEX | I15: SOUTH | K15: 1 | L15: 2 | V15: 1 | AL15: 1
B16: 46181 | C16: 6 | D16: JUMBO | E16: D/S | F16: DD159 | G16: BAREND | I16: SOUTH | AH16: 2
B17: 46181 | C17: 6 | D17: JUMBO | E17: D/S | F17: DD122 | G17: JUNIAS | I17: NORTH | Z17: 1
B18: 46182 | C18: 6 | D18: JUMBO | E18: N/S | F18: DD159 | G18: TEX | I18: SOUTH | W18: 2 | X18: 1
B19: 46184 | C19: 6 | D19: JUMBO | E19: D/S | F19: DD159 | G19: DANIEL | I19: SOUTH | X19: 1 | AH19: 3
B20: 46184 | C20: 6 | D20: JUMBO | E20: N/S | F20: DD122 | G20: TEX | I20: NORTH | X20: 1
B21: 46184 | C21: 6 | D21: JUMBO | E21: D/S | F21: DD122 | G21: DELTON | I21: SOUTH | R21: 2
B22: 46185 | C22: 6 | D22: JUMBO | E22: N/S | F22: DD159 | G22: EINO | I22: SOUTH | K22: 1
B23: 46185 | C23: 6 | D23: JUMBO | E23: D/S | F23: DD122 | G23: DELTON | I23: NORTH | K23: 1
B24: 46186 | C24: 6 | D24: JUMBO | E24: N/S | F24: DD159 | G24: JUNIAS | I24: SOUTH | V24: 1 | W24: 1
B25: 46186 | C25: 6 | D25: JUMBO | E25: D/S | F25: DD122 | G25: DELTON | I25: NORTH | V25: 2 | AM25: 2
B26: 46186 | C26: 6 | D26: JUMBO | E26: D/S | F26: DD122 | G26: DELTON | I26: NORTH | K26: 1 | Z26: 1
B27: 46188 | C27: 6 | D27: JUMBO | E27: D/S | F27: DD122 | G27: DELTON | I27: NORTH | Z27: 1
B28: 46188 | C28: 6 | D28: JUMBO | E28: D/S | F28: DD159 | G28: DELTON | I28: SOUTH | K28: 2
B29: 46188 | C29: 6 | D29: JUMBO | E29: N/S | F29: DD159 | G29: DANIEL | I29: NORTH | AH29: 4
B30: 46188 | C30: 6 | D30: JUMBO | E30: N/S | F30: DD122 | G30: JUNIAS | I30: SOUTH | AH30: 3
B31: 46189 | C31: 6 | D31: JUMBO | E31: N/S | F31: DD122 | G31: LACHY | K31: 1
B32: 46191 | C32: 6 | D32: JUMBO | E32: D/S | F32: DD159 | G32: TRENT | I32: NORTH | K32: 1
B33: 46191 | C33: 6 | D33: JUMBO | E33: D/S | F33: DD159 | G33: TRENT | I33: NORTH | AH33: 1
B34: 46191 | C34: 6 | D34: JUMBO | E34: D/S | F34: DD122 | G34: SIMON | I34: SOUTH | J34: 1 | K34: 1 | AI34: 1
B35: 46192 | C35: 6 | D35: JUMBO | E35: N/S | F35: DD159 | G35: DANIEL | I35: NORTH | K35: 1 | L35: 2
B36: 46193 | C36: 6 | D36: JUMBO | E36: D/S | F36: DD122 | G36: CHRIS | I36: SOUTH | J36: 1 | K36: 1 | T36: 2 | Y36: 1
B37: 46193 | C37: 6 | D37: JUMBO | E37: D/S | F37: DD159 | G37: TRENT | I37: NORTH | K37: 1 | N37: 2 | AD37: 4 | AF37: 2
B38: 46194 | C38: 6 | D38: JUMBO | E38: N/S | F38: DD122 | G38: GEOFREY | I38: SOUTH | AD38: 10 | AH38: 2
B39: 46194 | C39: 6 | D39: JUMBO | E39: N/S | F39: DD159 | G39: DELTON | I39: NORTH | J39: 1 | K39: 2 | Y39: 1
B40: 46196 | C40: 6 | D40: JUMBO | E40: N/S | F40: DD159 | G40: DANIEL | I40: NORTH | J40: 1
...

Sheet JULY 26
E1: Unit Cost | J1: 308.1 | K1: 487.82742 | L1: 45.12 | M1: 68 | N1: 61.09 | O1: 61.09 | P1: 61.09 | Q1: 498.85 | R1: 513.01 | S1: 639 | T1: 443.78 | U1: 317.43 | V1: 184.75 | W1: 276.63 | X1: 439.59 | Y1: 794.42 | Z1: 726.72 | AB1: 66.52 | AC1: 78.93 | AD1: 79.93 | AE1: 108.19 | AF1: 94.13 | AG1: 343.33 | AH1: 136.44 | AI1: 69.96 | AJ1: 168.67893 | AK1: 390.14017 | AL1: 96.3 | AM1: 96.3
E2: Monthly Jumbo Cost | H2: =SUM(J2:AM2) -> 36141.856 | J2: =J1*J3 -> 308.1 | K2: =K1*K3 -> 13171.34 | L2: =L1*L3 -> 406.08 | M2: =M1*M3 -> 136 | N2: =N1*N3 -> 122.18 | O2: =O1*O3 -> 366.54 | P2: =P1*P3 -> 305.45 | Q2: =Q1*Q3 -> 0 | ... AM2: =AM1*AM3 -> 0
J3: =SUM(J6:J404) -> 1 | K3: =SUM(K6:K404) -> 27 | L3: =SUM(L6:L404) -> 9 | M3: =SUM(M6:M404) -> 2 | N3: =SUM(N6:N404) -> 2 | O3: =SUM(O6:O404) -> 6 | P3: =SUM(P6:P404) -> 5 | Q3: =SUM(Q6:Q404) -> 0 | ... Z3: =SUM(Z6:Z404) -> 2 | AB3: =SUM(AB6:AB404) -> 10 | AC3: =SUM(AC6:AC404) -> 10 | AE3: =SUM(AE6:AE404) -> 0 | AF3: =SUM(AF6:AF404) -> 10 | AG3: =SUM(AG6:AG404) -> 14 | AH3: =SUM(AH6:AH404) -> 1 | AI3: =SUM(AI6:AI404) -> 5 | AJ3: =SUM(AJ6:AJ404) -> 13 | AK3: =SUM(AK6:AK404) -> 0 | AL3: =SUM(AL6:AL404) -> 2 | AM3: =SUM(AM6:AM404) -> 0
J4: SHANKS | L4: CENTRLALISER | Q4: BORING STEELS | T4: BOLTING & EXTENSION STEELS | X4: SCALING STEELS | Y4: MD ACCESSORIES | AB4: JUMBO BOLTING | AC4: JUMBO BORING | AG4: JUMBO REAMER & CABLES | AI4: COUPLING SLEEVES | AL4: DOLLY
B5: DATE | C5: MONTH | D5: RIG TYPE | E5: SHIFT | F5: RIG | G5: REQUESTER | H5: APPROVED BY | I5: LEVEL | J5: SHANK T38 RD520/525 D45 L525 | K5: SHANK T45 RD520/525 D45 L525 | L5: BOLTING CENTRALISER DIA 70MM FRONT | M5: BOLTING CENTRALISER DIA 70MM BACK | N5: BOLTING CENTRALISER DIA 66MM | O5: BORING CENTRALISER DIA 48MM | P5: BORING CENTRALISER DIA 41MM | Q5: DRIFTER ROD T38 H35 A340 L=370 | R5: DRIFTER ROD T38 H35 A340 L=430 | S5: DRIFTER ROD T38 R39 A340 L=491 | T5: DRIFTER ROD T38 H35 A340 L=309 | U5: MF ROD T38 R39 L=3050MM | V5: EXTENSION ROD T38 R39 L = 915M | W5: MF ROD T38 R39 L=915MM | X5: T38 EXTENSION ROUND ROD L3050MM | Y5: MD BOLT DRIVER 900MM ""T"" THREA | Z5: MD BOLT DRIVER 900MM T45 | AA5: BIT ADAPTOR T45F/T38M | AB5: A340X43MM BUTTON BIT | AC5: A340X45MM BUTTON BIT | AD5: SPEEDY BIT A340X45MM XT49 | AE5: A340X48MM TC BUTTON BIT | AF5: A340X51MM RETRAC BIT | AG5: REAMING BIT A340 102MM | AH5: T38X64MM BUTTON BIT | AI5: COUPLING SLEEVE T38/T38 | AJ5: COUPLING SLEEVE T45/T38 | AL5: T38 DOLLY 47MM | AM5: T38 DOLLY 39MM
B6: 46204 | C6: =IF(B6="","",MONTH(B6)) -> 7 | D6: JUMBO | E6: D/S | F6: DD122 | G6: JUNIAS | H6: D Christensen | I6: SOUTH | T6: 3
B7: 46204 | C7: =IF(B7="","",MONTH(B7)) -> 7 | D7: JUMBO | E7: D/S | F7: DD159 | G7: DELTON | H7: D Christensen | I7: NORTH | T7: 3
B8: 46204 | C8: =IF(B8="","",MONTH(B8)) -> 7 | D8: JUMBO | E8: N/S | F8: DD159 | G8: HAMISH | H8: D Christensen | I8: NORTH | AB8: 10 | AG8: 2
B9: 46204 | C9: =IF(B9="","",MONTH(B9)) -> 7 | D9: JUMBO | E9: N/S | F9: DD122 | G9: HOGES | H9: D Christensen | I9: SOUTH | AG9: 2
B10: 46205 | C10: =IF(B10="","",MONTH(B10)) -> 7 | D10: JUMBO | E10: D/S | F10: DD159 | G10: DELTON | H10: D Christensen | I10: NORTH | K10: 1
B11: 46206 | C11: =IF(B11="","",MONTH(B11)) -> 7 | D11: JUMBO | E11: D/S | F11: DD159 | G11: DELTON | H11: D Christensen | I11: NORTH | K11: 1
B12: 46206 | C12: =IF(B12="","",MONTH(B12)) -> 7 | D12: JUMBO | E12: D/S | F12: DD122 | G12: DELTON | H12: D Christensen | I12: SOUTH | K12: 1
B13: 46206 | C13: =IF(B13="","",MONTH(B13)) -> 7 | D13: JUMBO | E13: D/S | F13: DD159 | G13: DELTON | H13: D Christensen | I13: NORTH | S13: 1
B14: 46207 | C14: =IF(B14="","",MONTH(B14)) -> 7 | D14: JUMBO | E14: D/S | F14: DD159 | G14: DELTON | H14: D Christensen | I14: NORTH | P14: 2 | AD14: 10 | AJ14: 1
B15: 46207 | C15: =IF(B15="","",MONTH(B15)) -> 7 | D15: JUMBO | E15: N/S | F15: DD159 | G15: HAMISH | H15: D Christensen | I15: NORTH | K15: 1 | AD15: 10
B16: 46207 | C16: =IF(B16="","",MONTH(B16)) -> 7 | D16: JUMBO | E16: N/S | F16: DD122 | G16: GEOFREY | H16: D Christensen | I16: SOUTH | L16: 2 | N16: 2
B17: 46208 | C17: =IF(B17="","",MONTH(B17)) -> 7 | D17: JUMBO | E17: D/S | F17: DD159 | G17: DELTON | H17: D Christensen | I17: NORTH | K17: 1 | L17: 2 | M17: 2 | AJ17: 2
B18: 46208 | C18: =IF(B18="","",MONTH(B18)) -> 7 | D18: JUMBO | E18: D/S | F18: DD122 | G18: MARISE | H18: D Christensen | I18: SOUTH | AH18: 1
B19: 46209 | C19: =IF(B19="","",MONTH(B19)) -> 7 | D19: JUMBO | E19: N/S | F19: DD159 | G19: HAMISH | H19: D Christensen | I19: NORTH | K19: 1 | AC19: 10
B20: 46209 | C20: =IF(B20="","",MONTH(B20)) -> 7 | D20: JUMBO | E20: N/S | F20: DD122 | G20: GEOFREY | H20: D Christensen | I20: SOUTH | K20: 1 | AA20: 2
B21: 46211 | C21: =IF(B21="","",MONTH(B21)) -> 7 | D21: JUMBO | E21: N/S | F21: DD159 | G21: DELTON | H21: D Christensen | I21: NORTH | K21: 1 | P21: 2
B22: 46211 | C22: =IF(B22="","",MONTH(B22)) -> 7 | D22: JUMBO | E22: N/S | F22: DD122 | G22: GEOFREY | H22: D Christensen | I22: SOUTH | AG22: 3
B23: 46211 | C23: =IF(B23="","",MONTH(B23)) -> 7 | D23: JUMBO | E23: D/S | F23: DD159 | G23: DELTON | H23: D Christensen | I23: NORTH | T23: 3
B24: 46213 | C24: =IF(B24="","",MONTH(B24)) -> 7 | D24: JUMBO | E24: D/S | F24: DD159 | G24: HAMISH | H24: D Christensen | I24: NORTH | K24: 2
B25: 46213 | C25: =IF(B25="","",MONTH(B25)) -> 7 | D25: JUMBO | E25: D/S | F25: DD122 | G25: HAMISH | H25: D Christensen | I25: SOUTH | K25: 1
B26: 46213 | C26: =IF(B26="","",MONTH(B26)) -> 7 | D26: JUMBO | E26: D/S | F26: DD159 | G26: SIMON | H26: D Christensen | I26: NORTH | S26: 1
B27: 46214 | C27: =IF(B27="","",MONTH(B27)) -> 7 | D27: JUMBO | E27: D/S | F27: DD159 | G27: SIMON | H27: D Christensen | I27: NORTH | K27: 1
B28: 46215 | C28: =IF(B28="","",MONTH(B28)) -> 7 | D28: JUMBO | E28: D/S | F28: DD159 | G28: MARTIN | H28: D Christensen | I28: NORTH | K28: 2 | AI28: 1 | AJ28: 1
B29: 46215 | C29: =IF(B29="","",MONTH(B29)) -> 7 | D29: JUMBO | E29: N/S | F29: DD122 | G29: GEOFREY | H29: D Christensen | I29: SOUTH | K29: 1 | W29: 1
B30: 46215 | C30: =IF(B30="","",MONTH(B30)) -> 7 | D30: JUMBO | E30: N/S | F30: DD159 | G30: HOGES | H30: D Christensen | I30: NORTH | K30: 2
B31: 46216 | C31: =IF(B31="","",MONTH(B31)) -> 7 | D31: JUMBO | E31: D/S | F31: DD159 | G31: HAMISH | H31: D Christensen | I31: NORTH | J31: 1 | L31: 1 | AI31: 2 | AL31: 1
B32: 46217 | C32: =IF(B32="","",MONTH(B32)) -> 7 | D32: JUMBO | E32: D/S | F32: DD122 | G32: MARTIN | H32: D Christensen | I32: SOUTH | K32: 2 | AF32: 2 | AG32: 3
B33: 46218 | C33: =IF(B33="","",MONTH(B33)) -> 7 | D33: JUMBO | E33: N/S | F33: DD122 | H33: D Christensen | I33: SOUTH | O33: 2 | P33: 1 | AF33: 6
B34: 46219 | C34: =IF(B34="","",MONTH(B34)) -> 7 | D34: JUMBO | E34: N/S | F34: DD122 | H34: D Christensen | I34: SOUTH | K34: 1 | AA34: 1
B35: 46219 | C35: =IF(B35="","",MONTH(B35)) -> 7 | D35: JUMBO | E35: N/S | F35: DD159 | G35: SIMON | H35: D Christensen | I35: NORTH | Y35: 1 | AI35: 2 | AJ35: 2
B36: 46220 | C36: =IF(B36="","",MONTH(B36)) -> 7 | D36: JUMBO | E36: D/S | F36: DD159 | G36: JUNIAS | H36: D Christensen | I36: NORTH | K36: 1
B37: 46220 | C37: =IF(B37="","",MONTH(B37)) -> 7 | D37: JUMBO | E37: N/S | F37: DD159 | G37: SIMON | H37: D Christensen | I37: NORTH | Y37: 1
B38: 46221 | C38: =IF(B38="","",MONTH(B38)) -> 7 | D38: JUMBO | E38: N/S | F38: DD159 | H38: D Christensen | I38: NORTH | L38: 4 | O38: 4 | AA38: 2 | AJ38: 2 | AL38: 1
B39: 46222 | C39: =IF(B39="","",MONTH(B39)) -> 7 | D39: JUMBO | E39: D/S | F39: DD122 | G39: JUNIAS | H39: D Christensen | I39: SOUTH | T39: 2
B40: 46222 | C40: =IF(B40="","",MONTH(B40)) -> 7 | D40: JUMBO | E40: D/S | F40: DD122 | G40: JUNIAS | H40: D Christensen | I40: SOUTH | AF40: 2
...

Sheet AUGUST 26
E1: Unit Cost | J1: 308.1 | K1: 487.82742 | L1: 45.12 | M1: 68 | N1: 61.09 | O1: 61.09 | P1: 61.09 | Q1: 498.85 | R1: 513.01 | S1: 639 | T1: 443.78 | U1: 317.43 | V1: 184.75 | W1: 276.63 | X1: 439.59 | Y1: 794.42 | Z1: 726.72 | AB1: 66.52 | AC1: 78.93 | AD1: 79.93 | AE1: 108.19 | AF1: 94.13 | AG1: 343.33 | AH1: 136.44 | AI1: 69.96 | AJ1: 168.67893 | AK1: 390.14017 | AL1: 96.3 | AM1: 96.3
E2: Monthly Jumbo Cost | H2: =SUM(J2:AM2) -> 42943.178 | J2: =J1*J3 -> 616.2 | K2: =K1*K3 -> 12683.513 | L2: =L1*L3 -> 360.96 | M2: =M1*M3 -> 0 | N2: =N1*N3 -> 0 | O2: =O1*O3 -> 366.54 | P2: =P1*P3 -> 122.18 | Q2: =Q1*Q3 -> 498.85 | ... AM2: =AM1*AM3 -> 0
J3: =SUM(J6:J404) -> 2 | K3: =SUM(K6:K404) -> 26 | L3: =SUM(L6:L404) -> 8 | M3: =SUM(M6:M404) -> 0 | N3: =SUM(N6:N404) -> 0 | O3: =SUM(O6:O404) -> 6 | P3: =SUM(P6:P404) -> 2 | Q3: =SUM(Q6:Q404) -> 1 | ... Z3: =SUM(Z6:Z404) -> 0 | AB3: =SUM(AB6:AB404) -> 2 | AC3: =SUM(AC6:AC404) -> 34 | AD3: =SUM(AD6:AD404) -> 70 | AE3: =SUM(AE6:AE404) -> 30 | AF3: =SUM(AF6:AF404) -> 15 | AG3: =SUM(AG6:AG404) -> 8 | AH3: =SUM(AH6:AH404) -> 18 | AI3: =SUM(AI6:AI404) -> 2 | ... AM3: =SUM(AM6:AM404) -> 0
J4: SHANKS | L4: CENTRLALISER | Q4: BORING STEELS | T4: BOLTING & EXTENSION STEELS | X4: SCALING STEELS | Y4: MD ACCESSORIES | AB4: JUMBO BOLTING | AC4: JUMBO BORING | AG4: JUMBO REAMER & CABLES | AI4: COUPLING SLEEVES | AL4: DOLLY
B5: DATE | C5: MONTH | D5: RIG TYPE | E5: SHIFT | F5: RIG | G5: REQUESTER | H5: APPROVED BY | I5: LEVEL | J5: SHANK T38 RD520/525 D45 L525 | K5: SHANK T45 RD520/525 D45 L525 | L5: BOLTING CENTRALISER DIA 70MM FRONT | M5: BOLTING CENTRALISER DIA 70MM BACK | N5: BOLTING CENTRALISER DIA 66MM | O5: BORING CENTRALISER DIA 48MM | P5: BORING CENTRALISER DIA 41MM | Q5: DRIFTER ROD T38 H35 A340 L=370 | R5: DRIFTER ROD T38 H35 A340 L=430 | S5: DRIFTER ROD T38 R39 A340 L=491 | T5: DRIFTER ROD T38 H35 A340 L=309 | U5: MF ROD T38 R39 L=3050MM | V5: EXTENSION ROD T38 R39 L = 915M | W5: MF ROD T38 R39 L=915MM | X5: T38 EXTENSION ROUND ROD L3050MM | Y5: MD BOLT DRIVER 900MM ""T"" THREA | Z5: MD BOLT DRIVER 900MM T45 | AA5: BIT ADAPTOR T45F/T38M | AB5: A340X43MM BUTTON BIT | AC5: A340X45MM BUTTON BIT | AD5: SPEEDY BIT A340X45MM XT49 | AE5: A340X48MM TC BUTTON BIT | AF5: A340X51MM RETRAC BIT | AG5: REAMING BIT A340 102MM | AH5: T38X64MM BUTTON BIT | AI5: COUPLING SLEEVE T38/T38 | AJ5: COUPLING SLEEVE T45/T38 | AL5: T38 DOLLY 47MM | AM5: T38 DOLLY 39MM
B6: 46235 | C6: 8 | D6: JUMBO | E6: N/S | F6: DD159 | G6: HOGES | H6: D Christensen | I6: NORTH | J6: 1
B7: 46235 | C7: 8 | D7: JUMBO | E7: N/S | F7: DD159 | G7: HOGES | H7: D Christensen | I7: NORTH | AD7: 10
B8: 46235 | C8: 8 | D8: JUMBO | E8: N/S | F8: DD159 | G8: HOGES | H8: D Christensen | I8: NORTH | AE8: 10
B9: 46235 | C9: 8 | D9: JUMBO | E9: N/S | F9: DD122 | G9: TEX | H9: D Christensen | I9: SOUTH | AH9: 2
B10: 46236 | C10: 8 | D10: JUMBO | E10: D/S | F10: DD159 | G10: TEX | H10: D Christensen | I10: NORTH | K10: 1
B11: 46236 | C11: 8 | D11: JUMBO | E11: D/S | F11: DD159 | G11: ANDY | H11: D Christensen | I11: SOUTH | K11: 2
B12: 46237 | C12: 8 | D12: JUMBO | E12: D/S | F12: DD159 | G12: SIMON | H12: D Christensen | I12: NORTH | K12: 1 | AD12: 10
B13: 46237 | C13: 8 | D13: JUMBO | E13: D/S | F13: DD159 | G13: SIMON | H13: D Christensen | I13: NORTH | AA13: 2
B14: 46238 | C14: 8 | D14: JUMBO | E14: D/S | F14: DD122 | G14: TEX | H14: D Christensen | I14: NORTH | Y14: 1 | AF14: 5
B15: 46238 | C15: 8 | D15: JUMBO | E15: D/S | F15: DD122 | G15: TEX | H15: D Christensen | I15: NORTH
B16: 46238 | C16: 8 | D16: JUMBO | E16: D/S | F16: DD122 | G16: TEX | H16: D Christensen | I16: NORTH
B17: 46238 | C17: 8 | D17: JUMBO | E17: N/S | F17: DD159 | G17: HOGES | H17: D Christensen | I17: NORTH | K17: 1 | AD17: 10
B18: 46238 | C18: 8 | D18: JUMBO | E18: D/S | F18: DD159 | G18: HOGES | H18: D Christensen | I18: NORTH
B19: 46239 | C19: 8 | D19: JUMBO | E19: D/S | F19: DD122 | G19: TEX | H19: D Christensen | I19: NORTH | K19: 1 | AJ19: 1
B20: 46239 | C20: 8 | D20: JUMBO | E20: D/S | F20: DD122 | G20: TEX | H20: D Christensen | I20: SOUTH | AE20: 4
B21: 46239 | C21: 8 | D21: JUMBO | E21: D/S | F21: DD122 | G21: JUNIAS | H21: D Christensen | I21: SOUTH | L21: 2
B22: 46239 | C22: 8 | D22: JUMBO | E22: D/S | F22: DD122 | G22: TEX | H22: D Christensen | I22: NORTH | O22: 2
B23: 46239 | C23: 8 | D23: JUMBO | E23: D/S | F23: DD122 | G23: TEX | H23: D Christensen | I23: SOUTH | AJ23: 2
B24: 46239 | C24: 8 | D24: JUMBO | E24: D/S | F24: DD159 | G24: JUNIAS | H24: D Christensen | I24: SOUTH
B25: 46240 | C25: 8 | D25: JUMBO | E25: D/S | F25: DD122 | G25: TEX | H25: D Christensen | I25: SOUTH | K25: 1
B26: 46240 | C26: 8 | D26: JUMBO | E26: D/S | F26: DD159 | G26: JUNIAS | H26: D Christensen | I26: NORTH
B27: 46240 | C27: 8 | D27: JUMBO | E27: D/S | F27: DD159 | G27: JUNIAS | H27: D Christensen | I27: NORTH | AE27: 10
B28: 46240 | C28: 8 | D28: JUMBO | E28: D/S | F28: DD122 | G28: TEX | H28: D Christensen | I28: SOUTH | AF28: 10
B29: 46241 | C29: 8 | D29: JUMBO | E29: D/S | F29: DD159 | G29: ANDY | H29: D Christensen | I29: NORTH | K29: 2 | Y29: 1
B30: 46242 | C30: 8 | D30: JUMBO | E30: N/S | F30: DD159 | G30: HOGES | H30: D Christensen | I30: NORTH | K30: 1 | AJ30: 1
B31: 46242 | C31: 8 | D31: JUMBO | E31: N/S | F31: DD159 | G31: HOGES | H31: D Christensen | I31: NORTH
B32: 46242 | C32: 8 | D32: JUMBO | E32: N/S | F32: DD122 | G32: MARISE | H32: D Christensen | I32: SOUTH | AC32: 10
B33: 46242 | C33: 8 | D33: JUMBO | E33: N/S | F33: DD122 | G33: MARISE | H33: D Christensen | I33: NORTH | AG33: 4
B34: 46245 | C34: 8 | D34: JUMBO | E34: N/S | F34: DD122 | G34: MARISE | H34: D Christensen | I34: NORTH | L34: 1
B35: 46245 | C35: 8 | D35: JUMBO | E35: N/S | F35: DD159 | G35: MARISE | H35: M Jimmi | I35: NORTH | K35: 1
A36: 1 | B36: 46245 | C36: 8 | D36: JUMBO | E36: N/S | F36: DD159 | G36: MARISE | H36: M Jimmi | I36: NORTH | AJ36: 2
B37: 46245 | C37: 8 | D37: JUMBO | E37: N/S | F37: DD159 | G37: ANDY | H37: M Jimmi | I37: NORTH | K37: 1
B38: 46245 | C38: 8 | D38: JUMBO | E38: N/S | F38: DD159 | G38: ANDY | H38: M Jimmi | I38: NORTH | AJ38: 1
B39: 46245 | C39: 8 | D39: JUMBO | E39: N/S | F39: DD159 | G39: ANDY | H39: M Jimmi | I39: NORTH | AA39: 1
B40: 46245 | C40: 8 | D40: JUMBO | E40: N/S | F40: DD159 | G40: DAN | H40: M Jimmi | I40: NORTH | W40: 1
...
