Workbook
Name _511.56: 'August_2026 eom ug dev'!#REF!
Name arch_profile: Heading_ids!#REF!
Name arch_profile: Heading_profile!$B$3:$D$35
Name arch_profile: Stripping_cal!#REF!
Name arch_profile: #REF!
Name bolt_per_metre: Heading_ids!#REF!
Name bolt_per_metre: Heading_profile!#REF!
Name bolt_per_metre: Stripping_cal!#REF!
Name bolt_per_metre: #REF!
Name fibre_per_metre: Heading_ids!#REF!
Name fibre_per_metre: Heading_profile!#REF!
Name fibre_per_metre: Stripping_cal!#REF!
Name fibre_per_metre: #REF!
Name gs_01: Heading_ids!#REF!
Name gs_01: Heading_profile!#REF!
Name gs_01: Stripping_cal!#REF!
Name gs_01: #REF!
Name gs_02: Heading_ids!#REF!
Name gs_02: Heading_profile!#REF!
Name gs_02: Stripping_cal!#REF!
Name gs_02: #REF!
Name haul_dist: Heading_ids!#REF!
Name haul_dist: Heading_profile!#REF!
Name haul_dist: Stripping_cal!#REF!
Name haul_dist: #REF!
Name M_ID: [1]Materials!$A$4:$A$77
Name Material_unit_Cost: [2]Materials!$A$4:$I$81
Name Profile: [3]Lookups!$B$3:$B$15
Name Profile: [4]Lookups!$B$3:$B$15
Name raise_profile: Heading_ids!#REF!
Name raise_profile: Heading_profile!$B$45:$C$55
Name raise_profile: Stripping_cal!#REF!
Name raise_profile: #REF!
Name sg: Heading_ids!#REF!
Name sg: Heading_profile!#REF!
Name sg: Stripping_cal!#REF!
Name sg: #REF!
Name split_sets_per_metre: Heading_ids!#REF!
Name split_sets_per_metre: Heading_profile!#REF!
Name split_sets_per_metre: Stripping_cal!#REF!
Name split_sets_per_metre: #REF!
Name sqr_profile: Heading_ids!#REF!
Name sqr_profile: Heading_profile!$F$3:$H$35
Name sqr_profile: Stripping_cal!#REF!
Name sqr_profile: #REF!

Sheet How to use
A1: Instructions for use
A3: 1. Only manually enter data into the yellow coloured cells and on the master data tab!!
A4: 2. Blue coloured cells are a drop down menu. Select an option from the menu
A5: 3. All other cells will automatically populate
A6: 4. DO NOT OVER WRITE THE FORMULAS
A7: 5. The list of headings is populated from the Daily Report spreadsheet Wooly and Mick generate. If there is a heading not on the list, ask and we will put it in
A8: 6. Use one line on the "EOM Summary" sheet for each heading. If there are multiple ground support regimes in the one heading (i.e. we go through a bad patch of ground and upgrade to GS_5), put this on a new line
A9: 7. When using the "Stripping and Fibrecrete" tab, use a different line for each kind of stripping cut. There may be multiple strips on one level i.e. a loading bay and stockpile fillets. Ensure the heading name in Column A is the same, as this drives an auto-sum formula on EOM Summary tab.
A10: 8. If you are unsure, or something isnt working right, ask for help

Sheet Heading_ids
A1: Monthly Development Headings | B1: SIZE ( H x W ) | C1: GRADE | D1: PROFILE | E1: GS Type | F1: COST ACCOUNT | G1: Contract Type Dev | H1: MI NO.
A2: Column7 | B2: Column8 | C2: Column9 | D2: Column10 | E2: Column11 | F2: Column12 | G2: Column6 | H2: Column72
B3: 2 | C3: 3 | D3: 4 | E3: 5 | F3: 6 | G3: 7
A4: SOUTH DECLINE | B4: 5.5mW x 5.8mH - RS | C4: 1:7 Down | D4: Round Shoulders | E4: GSS_01 | F4: Waste | G4: CAP
A5: MS_DSP06 | B5: 5.5mW x 5.8mH - RS | C5: 1:50 Up | D5: Round Shoulders | E5: GSS_01 | F5: Waste | G5: CAP
A6: MS_PMP_STN1 | B6: 5.5mW x 5.5mH - RS | C6: 1:50 Up | D6: Round Shoulders | E6: GSS_01 | F6: Waste | G6: CAP
A7: MS_840_DSMP W | B7: 5.0mW x 5.0mH - RS | C7: 1:6 Down | D7: Round Shoulders | E7: GSS_01 | F7: Waste | G7: CAP
A8: MS_900_RAD_E | B8: 5.5mW x 5.5mH - RS | C8: 1:50 Up | D8: Round Shoulders | E8: GSS_01 | F8: Waste | G8: CAP
A9: MS_900_RAD_N | B9: 5.5mW x 5.5mH - RS | C9: 1:50 Up | D9: Round Shoulders | E9: GSS_01 | F9: Waste | G9: CAP
A10: NORTH DECLINE | B10: 5.5mW x 5.8mH - RS | C10: 1:7 Down | D10: Round Shoulders | E10: GSS_02 | F10: Waste | G10: CAP
A11: NS_1040_ACC_N | B11: 5.5mW x 5.8mH - RS | C11: 1:7 Down | D11: Round Shoulders | E11: GSS_02 | F11: Ore | G11: CAP
A12: NS_1020_ACC_W | B12: 5.5mW x 5.8mH - RS | C12: 1:50 Up | D12: Round Shoulders | E12: GSS_02 | F12: Waste | G12: CAP
A13: NS_1020_DSMP | B13: 5.0mW x 5.0mH - RS | C13: 1:6 Down | D13: Round Shoulders | E13: GSS_02 | F13: Waste | G13: CAP
A14: NS_1020_LSP01 | B14: 5.5mW x 5.8mH - RS | C14: 1:50 Up | D14: Round Shoulders | E14: GSS_02 | F14: Waste | G14: CAP
A15: NS_1020_RAD_N | B15: 5.5mW x 5.5mH - RS | C15: 1:7 Up | D15: Round Shoulders | E15: GSS_02 | F15: Waste | G15: CAP

Sheet Sheet2
E11: 1105_HWDW | F11: L4_1105_HWD_W | H11: 1515_DECLINE | I11: L1_1515____DEC__
E12: 1105_715 | F12: L4_1105_715_DDR_N | H12: 1515_SUMP | I12: L1_1515_SMP
E13: 1355_565 | F13: L4_1355_565__DDR_N | H13: 1530_ESC_N | I13: L1_1530_ESC_N
E14: 1355_685_W | F14: L4_1355_685__DDR_W | H14: 1530_ESC_E | I14: L1_1530_ESC_E
E15: 1355_745 | F15: L4_1355_745__DDR_N | H15: 1530_HWD_N | I15: L1_1530____HWD_N
E16: 1405_745 | F16: L4_1405_745__DDR_N | H16: 1530_HWD_S | I16: L1_1530____HWD_S
E17: 1495_SP | F17: L1_1495_SP | H17: 1530_SUB | I17: L1_1530_SUB
E18: 1495_SUMP | F18: L1_1495_SMP | H18: 1530_060 | I18: L1_1530_060_DDR_W
E19: 1555_760_SLT_E | F19: L4_1555_760A_SLT_E | H19: 1580_HWDN | I19: L1_1580_HWD_N
E20: 1515_DEC | F20: L1_1515____DEC__ | H20: 1580_SP | I20: L1_1580_SPB
E21: 1530_PDR | F21: L1_1530_PDR_E | H21: 1580_150 | I21: L1_1580_150__DDR_W
E22: 1530_HWDS | F22: L1_1530____HWD_S | H22: 1630_120 | I22: L1_1630_120__DDR_W
... E29: 1705_950_E (5.0 X 5.0) | F29: L4_1705_950__DDR_E | H29: 1800_165 | I29: L1_1800_165_DDR_N
E30: 1705_950_E (5.5 X 5.5) | F30: L4_1705_950__DDR_E
E31: 1705_970_N | F31: L4_1705_970__DDR_N | H31: 1255_655_N | I31: L4_1255_655_DDR_N
E32: 1745_410_SLT_NW | F32: L2_1745_410B_SLT_NW | H32: 1355_565_N | I32: L4_1355_565__DDR_N
E33: 1745_410_SLT_SE | F33: L2_1745_410B_SLT_SE | H33: 1355_595 | I33: L4_1355_595_DDR_N
E34: 1800_315_W_A | F34: L1_1800_315_DDR_W | H34: 1355_685_SLT_E | I34: L4_1355_685_SLT_E
E35: 1355 745 PASTE | F35: L4_1355_745_FDO | H35: 1355_685_SLT_W | I35: L4_1355_685_SLT_W
E36: 1495 SP TPB | F36: L1_1495 SP TPB | H36: 1355_835 | I36: L4_1355_835__DDR_N
E37: 1405_745_STRIP | F37: L4_1405_745_STRIP | H37: 1405_745 | I37: L4_1405_745__DDR_N
E38: 1605_760_STRIP | F38: L4_1605_760_STRIP | H38: 1655 950 | I38: L4_1655_950__DDR_N
E39: 1705_805_STRIP | F39: L4_1705_805_STRIP | H39: 1705_775_SLT_W | I39: L4_1705_775_SLT_W
H40: 1705 950 | I40: L4_1705_950__DDR_E
E41: 1555_760_PASTE | F41: L4_1555_760_FDO | H41: 1755 950 E | I41: L4_1755_950__DDR_E
E42: 1605_620_PASTE | F42: L4_1605_620_FDO | H42: 1755 970 E | I42: L4_1755_970__DDR_E
E43: 1605_640_PASTE | F43: L4_1605_640_FDO
E44: 1605_760_PASTE | F44: L4_1605_760_FDO
E45: 1800_315_PASTE | F45: L1_1800_315_FDO

Sheet Sheet3
E7: 1405_745 | G7: L4_1405_745__DDR_N
E8: 1455_670_SLT_W | G8: L4_1455_670_SLT_W
E9: 1455_670_SLT_E | G9: L4_1455_670_SLT_E
E10: 1505_850_SLT_W | G10: L4_1505_850_SLT_W
E11: 1505_850_EXT_N | G11: L4_1505_850_SLT_E
E12: 1555_700_SLT_W | G12: L4_1555_700_SLT_W
E13: 1515_DEC | G13: L1_1515____DEC__
E14: 1530_HWDS | G14: L1_1530____HWD_S | U14: L4_1455_670_SLT_W
E15: 1530_HWDN | G15: L1_1530____HWD_N | U15: L4_1455_670_SLT_E
E16: 1530_SUB | G16: L1_1530____SUB_S | U16: L4_1505_850_SLT_E
E17: 1530_060 | G17: L1_1530_060__DDR_W | U17: L4_1505_850_SLT_W
E18: 1530_090 | G18: L1_1530_090 | U18: L4_1555_700_SLT_E
E19: 1580_SPB | G19: L1_1580____SPB | U19: L4_1555_700_SLT_W
E20: 1630_210 | G20: L1_1630_210 | U20: L1_1530_120
E21: 1630_PDR | G21: L1_1630_PDR | U21: L1_1630_210
E22: 1630_HWDN | G22: L1_1630____HWD_N | U22: L1_1630_PDR
E23: 1655_950_E | G23: L4_1655_950__DDR_E_waste | U23: L1_1800_165_N
E24: 1680_165_N | G24: L1_1680_165__DDR_N | U24: L1_1800_165_S
E25: 1680_165_S | G25: L1_1680_165__DDR_S
E26: 1705_805_SLT_W | G26: L4_1705_805_SLT_W
E27: 1800_165_N | G27: L1_1800_165_N
E28: 1800_165_S | G28: L1_1800_165_S
E29: 1850_315 | G29: L1_1850_315
E30: 1850_330 | G30: L1_1850_330
E31: 1355_745_FDO | G31: L4_1355_745_FDO
E32: 1505_850_FDO | G32: L4_1505_850_FDO
E33: 1555_700_FDO | G33: L4_1555_700_FDO
E34: 1555_850_RHINO_STRIP | G34: L4_1555_850_RHINO_STRIP
E35: 1605_700_RHINO_STRIP | G35: L4_1605_700_RHINO_STRIP
E36: 1705_805_SLT_W_FDO | G36: L4_1705_805_SLT_W_FDO
... E38: 1800_315_FDO | G38: L4_1800_315_FDO

Sheet August_2026 eom ug dev
E2: Byrnecut Development Payment EOM NAVACHAB GOLD MINE
Z3: REPORT TYPE: | AE3: Byrnecut Development Payment EOM
Z4: REPORT START DATE: | AE4: 46232
Z5: REPORT END DATE: | AE5: 46262
Z6: AUTHOR: | AE6: Pythias Kahanji
Z7: PUBLISHED: | AE7: 46265
C8: Heading name | D8: Heading Dimensions | E8: Material | F8: GS Type | G8: Cap/Op | H8: Profile (m²) | I8: EOM Advance | J8: Payment Meters | K8: Design Meters | L8: Stripping (m³) | M8: Design m³ | N8: Actual m³ | O8: Outside design m³ | P8: Inside design m³ | Q8: Under design floor m³ | R8: UnderBreak | S8: OverBreak | T8: Design Tonnes | U8: Actual Tonnes | V8: Overbreak Allowance | W8: Equiv. Meters | X8: 0.1 | Y8: Design+10% | Z8: Claimed Tonnes | AA8: Haulage Dist. | AB8: Pay Volume | AC8: Pay Tonnes | AD8: Tkm | AE8: Comments
T9: (%) | U9: (%) | W9: (%) | X9: (%) | Y9: (%) | Z9: (%)
C10: SOUTH DECLINE | D10: =IF(C10="",0,VLOOKUP(C10,Heading_ids!$A$4:$H$46,2,FALSE)) -> 5.5mW x 5.8mH - RS | E10: =IF(C10="",0,VLOOKUP(C10,Heading_ids!$A$4:$G$46,6,FALSE)) -> Waste | F10: =IF(C10="",0,VLOOKUP(C10,Heading_ids!$A$4:$G$46,5,FALSE)) -> GSS_01 | G10: =IF(C10="",0,VLOOKUP(C10,Heading_ids!$A$4:$G$46,7,FALSE)) -> CAP | H10: =IF(D10="",0,VLOOKUP(D10,Heading_profile!arch_profile,3,FALSE)) -> 31.12 | I10: =IFERROR(IF(C10="",0,VLOOKUP(C10,Input!$A$4:$H$23,7,FALSE)),0) -> 66.894 | J10: =+I10 -> 66.894 | K10: =I10 -> 66.894 | L10: =IFERROR(IF(E10="waste",VLOOKUP(C10,Stripping!$A$9:$I$40,9,FALSE),0),0) -> 97.1 | M10: =(K10*H10)+L10 -> 2178.8413 | N10: =IFERROR(IF(C10="",0,VLOOKUP(C10,Input!$A$4:$H$27,8,FALSE)),0) -> 2423.5 | O10: =IFERROR(IF(C10="",0,VLOOKUP(C10,Input!$A$4:$H$27,4,FALSE)),0) -> 295.9 | P10: =IFERROR(IF(C10="",0,VLOOKUP(C10,Input!$A$4:$H$27,5,FALSE)),0) -> 2127.6 | Q10: =IFERROR(IF(C10="",0,VLOOKUP(C10,Input!$A$4:$H$27,6,FALSE)),0) -> 111.8 | R10: =(P10-M10)/M10 -> -0.023517674 | S10: =(O10-Q10)/M10 -> 0.084494452 | T10: =M10*2.7 -> 5882.8715 | U10: =N10*2.7 -> 6543.45 | V10: 0.1 | X10: =+V10*T10 -> 588.28715 | Y10: =+X10+T10 -> 6471.1586 | Z10: =MIN(Y10,U10) -> 6471.1586 | AA10: 0.633774 | AB10: 1696.45 | AC10: =+AB10*2.7 -> 4580.415 | AD10: =+AC10*AA10 -> 2902.9479
C11: MS_DSP06 | D11: =IF(C11="",0,VLOOKUP(C11,Heading_ids!$A$4:$H$46,2,FALSE)) -> 5.5mW x 5.8mH - RS | E11: =IF(C11="",0,VLOOKUP(C11,Heading_ids!$A$4:$G$46,6,FALSE)) -> Waste | F11: =IF(C11="",0,VLOOKUP(C11,Heading_ids!$A$4:$G$46,5,FALSE)) -> GSS_01 | G11: =IF(C11="",0,VLOOKUP(C11,Heading_ids!$A$4:$G$46,7,FALSE)) -> CAP | H11: =IF(D11="",0,VLOOKUP(D11,Heading_profile!arch_profile,3,FALSE)) -> 31.12 | I11: =IFERROR(IF(C11="",0,VLOOKUP(C11,Input!$A$4:$H$23,7,FALSE)),0) -> 24.425 | J11: =+I11 -> 24.425 | K11: =I11 -> 24.425 | L11: =IFERROR(IF(E11="waste",VLOOKUP(C11,Stripping!$A$9:$I$40,9,FALSE),0),0) -> 109.8 | M11: =(K11*H11)+L11 -> 869.906 | N11: =IFERROR(IF(C11="",0,VLOOKUP(C11,Input!$A$4:$H$27,8,FALSE)),0) -> 1005.9 | O11: =IFERROR(IF(C11="",0,VLOOKUP(C11,Input!$A$4:$H$27,4,FALSE)),0) -> 185.5 | P11: =IFERROR(IF(C11="",0,VLOOKUP(C11,Input!$A$4:$H$27,5,FALSE)),0) -> 820.4 | Q11: =IFERROR(IF(C11="",0,VLOOKUP(C11,Input!$A$4:$H$27,6,FALSE)),0) -> 35.9 | R11: =(P11-M11)/M11 -> -0.056909597 | S11: =(O11-Q11)/M11 -> 0.1719726 | T11: =M11*2.7 -> 2348.7462 | U11: =N11*2.7 -> 2715.93 | V11: 0.1 | X11: =+V11*T11 -> 234.87462 | Y11: =+X11+T11 -> 2583.6208 | Z11: =MIN(Y11,U11) -> 2583.6208 | AA11: 0.633774 | AB11: =+N11+2155 -> 3160.9 | AC11: =+AB11*2.7 -> 8534.43 | AD11: =+AC11*AA11 -> 5408.8998
C12: MS_PMP_STN1 | D12: =IF(C12="",0,VLOOKUP(C12,Heading_ids!$A$4:$H$46,2,FALSE)) -> 5.5mW x 5.5mH - RS | E12: =IF(C12="",0,VLOOKUP(C12,Heading_ids!$A$4:$G$46,6,FALSE)) -> Waste | F12: =IF(C12="",0,VLOOKUP(C12,Heading_ids!$A$4:$G$46,5,FALSE)) -> GSS_01 | G12: =IF(C12="",0,VLOOKUP(C12,Heading_ids!$A$4:$G$46,7,FALSE)) -> CAP | H12: =IF(D12="",0,VLOOKUP(D12,Heading_profile!arch_profile,3,FALSE)) -> 29.81 | I12: =IFERROR(IF(C12="",0,VLOOKUP(C12,Input!$A$4:$H$23,7,FALSE)),0) -> 16.689 | J12: =+I12 -> 16.689 | K12: =I12 -> 16.689 | L12: =IFERROR(IF(E12="waste",VLOOKUP(C12,Stripping!$A$9:$I$40,9,FALSE),0),0) -> 49.5 | M12: =(K12*H12)+L12 -> 546.99909 | N12: =IFERROR(IF(C12="",0,VLOOKUP(C12,Input!$A$4:$H$27,8,FALSE)),0) -> 601.1 | O12: =IFERROR(IF(C12="",0,VLOOKUP(C12,Input!$A$4:$H$27,4,FALSE)),0) -> 82.2 | P12: =IFERROR(IF(C12="",0,VLOOKUP(C12,Input!$A$4:$H$27,5,FALSE)),0) -> 518.9 | Q12: =IFERROR(IF(C12="",0,VLOOKUP(C12,Input!$A$4:$H$27,6,FALSE)),0) -> 31.7 | R12: =(P12-M12)/M12 -> -0.051369537 | S12: =(O12-Q12)/M12 -> 0.092321909 | T12: =M12*2.7 -> 1476.8975 | U12: =N12*2.7 -> 1622.97 | V12: 0.1 | X12: =+V12*T12 -> 147.68975 | Y12: =+X12+T12 -> 1624.5873 | Z12: =MIN(Y12,U12) -> 1622.97 | AA12: 0.633774 | AB12: 344.955 | AC12: =+AB12*2.7 -> 931.3785 | AD12: =+AC12*AA12 -> 590.28348
C13: MS_840_DSMP W | D13: =IF(C13="",0,VLOOKUP(C13,Heading_ids!$A$4:$H$46,2,FALSE)) -> 5.0mW x 5.0mH - RS | E13: =IF(C13="",0,VLOOKUP(C13,Heading_ids!$A$4:$G$46,6,FALSE)) -> Waste | F13: =IF(C13="",0,VLOOKUP(C13,Heading_ids!$A$4:$G$46,5,FALSE)) -> GSS_01 | G13: =IF(C13="",0,VLOOKUP(C13,Heading_ids!$A$4:$G$46,7,FALSE)) -> CAP | H13: =IF(D13="",0,VLOOKUP(D13,Heading_profile!arch_profile,3,FALSE)) -> 24.558 | I13: =IFERROR(IF(C13="",0,VLOOKUP(C13,Input!$A$4:$H$23,7,FALSE)),0) -> 5.739 | J13: =+I13 -> 5.739 | K13: =I13 -> 5.739 | L13: =IFERROR(IF(E13="waste",VLOOKUP(C13,Stripping!$A$9:$I$40,9,FALSE),0),0) -> 12.5 | M13: =(K13*H13)+L13 -> 153.43836 | N13: =IFERROR(IF(C13="",0,VLOOKUP(C13,Input!$A$4:$H$27,8,FALSE)),0) -> 214.9 | O13: =IFERROR(IF(C13="",0,VLOOKUP(C13,Input!$A$4:$H$27,4,FALSE)),0) -> 86.5 | P13: =IFERROR(IF(C13="",0,VLOOKUP(C13,Input!$A$4:$H$27,5,FALSE)),0) -> 128.4 | Q13: =IFERROR(IF(C13="",0,VLOOKUP(C13,Input!$A$4:$H$27,6,FALSE)),0) -> 6.2 | R13: =(P13-M13)/M13 -> -0.16318189 | S13: =(O13-Q13)/M13 -> 0.52333718 | T13: =M13*2.7 -> 414.28358 | U13: =N13*2.7 -> 580.23 | V13: 0.1 | X13: =+V13*T13 -> 41.428358 | Y13: =+X13+T13 -> 455.71194 | Z13: =MIN(Y13,U13) -> 455.71194 | AA13: 3.290303 | AB13: =+N13 -> 214.9 | AC13: =+AB13*2.7 -> 580.23 | AD13: =+AC13*AA13 -> 1909.1325
C14: MS_900_RAD_E | D14: =IF(C14="",0,VLOOKUP(C14,Heading_ids!$A$4:$H$46,2,FALSE)) -> 5.5mW x 5.5mH - RS | E14: =IF(C14="",0,VLOOKUP(C14,Heading_ids!$A$4:$G$46,6,FALSE)) -> Waste | F14: =IF(C14="",0,VLOOKUP(C14,Heading_ids!$A$4:$G$46,5,FALSE)) -> GSS_01 | G14: =IF(C14="",0,VLOOKUP(C14,Heading_ids!$A$4:$G$46,7,FALSE)) -> CAP | H14: =IF(D14="",0,VLOOKUP(D14,Heading_profile!arch_profile,3,FALSE)) -> 29.81 | I14: =IFERROR(IF(C14="",0,VLOOKUP(C14,Input!$A$4:$H$23,7,FALSE)),0) -> 32.861 | J14: =+I14 -> 32.861 | K14: =I14 -> 32.861 | L14: =IFERROR(IF(E14="waste",VLOOKUP(C14,Stripping!$A$9:$I$40,9,FALSE),0),0) -> 0 | M14: =(K14*H14)+L14 -> 979.58641 | N14: =IFERROR(IF(C14="",0,VLOOKUP(C14,Input!$A$4:$H$27,8,FALSE)),0) -> 1148.5 | O14: =IFERROR(IF(C14="",0,VLOOKUP(C14,Input!$A$4:$H$27,4,FALSE)),0) -> 211.1 | P14: =IFERROR(IF(C14="",0,VLOOKUP(C14,Input!$A$4:$H$27,5,FALSE)),0) -> 937.4 | Q14: =IFERROR(IF(C14="",0,VLOOKUP(C14,Input!$A$4:$H$27,6,FALSE)),0) -> 56.1 | R14: =(P14-M14)/M14 -> -0.043065532 | S14: =(O14-Q14)/M14 -> 0.15823004 | T14: =M14*2.7 -> 2644.8833 | U14: =N14*2.7 -> 3100.95 | V14: 0.1 | X14: =+V14*T14 -> 264.48833 | Y14: =+X14+T14 -> 2909.3716 | Z14: =MIN(Y14,U14) -> 2909.3716 | AA14: 0.633774 | AB14: 742.831 | AC14: =+AB14*2.7 -> 2005.6437 | AD14: =+AC14*AA14 -> 1271.1248
C15: SOUTH DECLINE | D15: =IF(C15="",0,VLOOKUP(C15,Heading_ids!$A$4:$H$46,2,FALSE)) -> 5.5mW x 5.8mH - RS | E15: =IF(C15="",0,VLOOKUP(C15,Heading_ids!$A$4:$G$46,6,FALSE)) -> Waste | F15: =IF(C15="",0,VLOOKUP(C15,Heading_ids!$A$4:$G$46,5,FALSE)) -> GSS_01 | G15: =IF(C15="",0,VLOOKUP(C15,Heading_ids!$A$4:$G$46,7,FALSE)) -> CAP | H15: =IF(D15="",0,VLOOKUP(D15,Heading_profile!arch_profile,3,FALSE)) -> 31.12 | AA15: 3.290303 | AB15: 727.05 | AC15: =+AB15*2.7 -> 1963.035 | AD15: =+AC15*AA15 -> 6458.9799 | AE15: Hauled to waste dump after 16/08/2026
C16: MS_PMP_STN1 | D16: =IF(C16="",0,VLOOKUP(C16,Heading_ids!$A$4:$H$46,2,FALSE)) -> 5.5mW x 5.5mH - RS | E16: =IF(C16="",0,VLOOKUP(C16,Heading_ids!$A$4:$G$46,6,FALSE)) -> Waste | F16: =IF(C16="",0,VLOOKUP(C16,Heading_ids!$A$4:$G$46,5,FALSE)) -> GSS_01 | G16: =IF(C16="",0,VLOOKUP(C16,Heading_ids!$A$4:$G$46,7,FALSE)) -> CAP | H16: =IF(D16="",0,VLOOKUP(D16,Heading_profile!arch_profile,3,FALSE)) -> 29.81 | AA16: 3.290303 | AB16: 884.345 | AC16: =+AB16*2.7 -> 2387.7315 | AD16: =+AC16*AA16 -> 7856.3601 | AE16: Hauled to waste dump after 16/08/2027
C17: MS_900_RAD_E | D17: =IF(C17="",0,VLOOKUP(C17,Heading_ids!$A$4:$H$46,2,FALSE)) -> 5.5mW x 5.5mH - RS | E17: =IF(C17="",0,VLOOKUP(C17,Heading_ids!$A$4:$G$46,6,FALSE)) -> Waste | F17: =IF(C17="",0,VLOOKUP(C17,Heading_ids!$A$4:$G$46,5,FALSE)) -> GSS_01 | G17: =IF(C17="",0,VLOOKUP(C17,Heading_ids!$A$4:$G$46,7,FALSE)) -> CAP | H17: =IF(D17="",0,VLOOKUP(D17,Heading_profile!arch_profile,3,FALSE)) -> 29.81 | AA17: 3.290303 | AB17: 405.669 | AC17: =+AB17*2.7 -> 1095.3063 | AD17: =+AC17*AA17 -> 3603.8896 | AE17: Hauled to waste dump after 16/08/2028
C18: MS_900_RAD_N | D18: =IF(C18="",0,VLOOKUP(C18,Heading_ids!$A$4:$H$46,2,FALSE)) -> 5.5mW x 5.5mH - RS | E18: =IF(C18="",0,VLOOKUP(C18,Heading_ids!$A$4:$G$46,6,FALSE)) -> Waste | F18: =IF(C18="",0,VLOOKUP(C18,Heading_ids!$A$4:$G$46,5,FALSE)) -> GSS_01 | G18: =IF(C18="",0,VLOOKUP(C18,Heading_ids!$A$4:$G$46,7,FALSE)) -> CAP | H18: =IF(D18="",0,VLOOKUP(D18,Heading_profile!arch_profile,3,FALSE)) -> 29.81 | I18: =IFERROR(IF(C18="",0,VLOOKUP(C18,Input!$A$4:$H$23,7,FALSE)),0) -> 6.07 | J18: =+I18 -> 6.07 | K18: =I18 -> 6.07 | L18: =IFERROR(IF(E18="waste",VLOOKUP(C18,Stripping!$A$9:$I$40,9,FALSE),0),0) -> 24.75 | M18: =(K18*H18)+L18 -> 205.6967 | N18: =IFERROR(IF(C18="",0,VLOOKUP(C18,Input!$A$4:$H$27,8,FALSE)),0) -> 212.2 | O18: =IFERROR(IF(C18="",0,VLOOKUP(C18,Input!$A$4:$H$27,4,FALSE)),0) -> 18.8 | P18: =IFERROR(IF(C18="",0,VLOOKUP(C18,Input!$A$4:$H$27,5,FALSE)),0) -> 193.4 | Q18: =IFERROR(IF(C18="",0,VLOOKUP(C18,Input!$A$4:$H$27,6,FALSE)),0) -> 2.9 | R18: =(P18-M18)/M18 -> -0.059780735 | S18: =(O18-Q18)/M18 -> 0.077298275 | T18: =M18*2.7 -> 555.38109 | U18: =N18*2.7 -> 572.94 | V18: 0.1 | X18: =+V18*T18 -> 55.538109 | Y18: =+X18+T18 -> 610.9192 | Z18: =MIN(Y18,U18) -> 572.94 | AA18: 0.633774 | AB18: =+N18 -> 212.2 | AC18: =+AB18*2.7 -> 572.94 | AD18: =+AC18*AA18 -> 363.11448
C19: NORTH DECLINE | D19: =IF(C19="",0,VLOOKUP(C19,Heading_ids!$A$4:$H$46,2,FALSE)) -> 5.5mW x 5.8mH - RS | E19: =IF(C19="",0,VLOOKUP(C19,Heading_ids!$A$4:$G$46,6,FALSE)) -> Waste | F19: =IF(C19="",0,VLOOKUP(C19,Heading_ids!$A$4:$G$46,5,FALSE)) -> GSS_02 | G19: =IF(C19="",0,VLOOKUP(C19,Heading_ids!$A$4:$G$46,7,FALSE)) -> CAP | H19: =IF(D19="",0,VLOOKUP(D19,Heading_profile!arch_profile,3,FALSE)) -> 31.12 | I19: =IFERROR(IF(C19="",0,VLOOKUP(C19,Input!$A$4:$H$23,7,FALSE)),0) -> 95.452 | J19: =+I19 -> 95.452 | K19: =I19 -> 95.452 | L19: =IFERROR(IF(E19="waste",VLOOKUP(C19,Stripping!$A$9:$I$40,9,FALSE),0),0) -> 338.6 | M19: =(K19*H19)+L19 -> 3309.0662 | N19: =IFERROR(IF(C19="",0,VLOOKUP(C19,Input!$A$4:$H$27,8,FALSE)),0) -> 3710.6 | O19: =IFERROR(IF(C19="",0,VLOOKUP(C19,Input!$A$4:$H$27,4,FALSE)),0) -> 601.4 | P19: =IFERROR(IF(C19="",0,VLOOKUP(C19,Input!$A$4:$H$27,5,FALSE)),0) -> 3109.2 | Q19: =IFERROR(IF(C19="",0,VLOOKUP(C19,Input!$A$4:$H$27,6,FALSE)),0) -> 280.1 | R19: =(P19-M19)/M19 -> -0.060399589 | S19: =(O19-Q19)/M19 -> 0.097096878 | T19: =M19*2.7 -> 8934.4788 | U19: =N19*2.7 -> 10018.62 | V19: 0.1 | X19: =+V19*T19 -> 893.44788 | Y19: =+X19+T19 -> 9827.9267 | Z19: =MIN(Y19,U19) -> 9827.9267 | AA19: 1.205373 | AB19: =+N19 -> 3710.6 | AC19: =+AB19*2.7 -> 10018.62 | AD19: =+AC19*AA19 -> 12076.174
C20: NS_1020_ACC_W | D20: =IF(C20="",0,VLOOKUP(C20,Heading_ids!$A$4:$H$46,2,FALSE)) -> 5.5mW x 5.8mH - RS | E20: =IF(C20="",0,VLOOKUP(C20,Heading_ids!$A$4:$G$46,6,FALSE)) -> Waste | F20: =IF(C20="",0,VLOOKUP(C20,Heading_ids!$A$4:$G$46,5,FALSE)) -> GSS_02 | G20: =IF(C20="",0,VLOOKUP(C20,Heading_ids!$A$4:$G$46,7,FALSE)) -> CAP | H20: =IF(D20="",0,VLOOKUP(D20,Heading_profile!arch_profile,3,FALSE)) -> 31.12 | I20: =IFERROR(IF(C20="",0,VLOOKUP(C20,Input!$A$4:$H$23,7,FALSE)),0) -> 57.558 | J20: =+I20 -> 57.558 | K20: =I20 -> 57.558 | L20: =IFERROR(IF(E20="waste",VLOOKUP(C20,Stripping!$A$9:$I$40,9,FALSE),0),0) -> 153.8 | M20: =(K20*H20)+L20 -> 1945.005 | N20: =IFERROR(IF(C20="",0,VLOOKUP(C20,Input!$A$4:$H$27,8,FALSE)),0) -> 2418.2 | O20: =IFERROR(IF(C20="",0,VLOOKUP(C20,Input!$A$4:$H$27,4,FALSE)),0) -> 428.6 | P20: =IFERROR(IF(C20="",0,VLOOKUP(C20,Input!$A$4:$H$27,5,FALSE)),0) -> 1989.6 | Q20: =IFERROR(IF(C20="",0,VLOOKUP(C20,Input!$A$4:$H$27,6,FALSE)),0) -> 126.4 | R20: =(P20-M20)/M20 -> 0.022927983 | S20: =(O20-Q20)/M20 -> 0.15537235 | T20: =M20*2.7 -> 5251.5134 | U20: =N20*2.7 -> 6529.14 | V20: 0.1 | X20: =+V20*T20 -> 525.15134 | Y20: =+X20+T20 -> 5776.6647 | Z20: =MIN(Y20,U20) -> 5776.6647 | AA20: 1.205373 | AB20: =+N20 -> 2418.2 | AC20: =+AB20*2.7 -> 6529.14 | AD20: =+AC20*AA20 -> 7870.0491
C21: NS_1020_DSMP | D21: =IF(C21="",0,VLOOKUP(C21,Heading_ids!$A$4:$H$46,2,FALSE)) -> 5.0mW x 5.0mH - RS | E21: =IF(C21="",0,VLOOKUP(C21,Heading_ids!$A$4:$G$46,6,FALSE)) -> Waste | F21: =IF(C21="",0,VLOOKUP(C21,Heading_ids!$A$4:$G$46,5,FALSE)) -> GSS_02 | G21: =IF(C21="",0,VLOOKUP(C21,Heading_ids!$A$4:$G$46,7,FALSE)) -> CAP | H21: =IF(D21="",0,VLOOKUP(D21,Heading_profile!arch_profile,3,FALSE)) -> 24.558 | I21: =IFERROR(IF(C21="",0,VLOOKUP(C21,Input!$A$4:$H$23,7,FALSE)),0) -> 10.505 | J21: =+I21 -> 10.505 | K21: =I21 -> 10.505 | L21: =IFERROR(IF(E21="waste",VLOOKUP(C21,Stripping!$A$9:$I$40,9,FALSE),0),0) -> 21 | M21: =(K21*H21)+L21 -> 278.98179 | N21: =IFERROR(IF(C21="",0,VLOOKUP(C21,Input!$A$4:$H$27,8,FALSE)),0) -> 380.3 | O21: =IFERROR(IF(C21="",0,VLOOKUP(C21,Input!$A$4:$H$27,4,FALSE)),0) -> 134.4 | P21: =IFERROR(IF(C21="",0,VLOOKUP(C21,Input!$A$4:$H$27,5,FALSE)),0) -> 245.9 | Q21: =IFERROR(IF(C21="",0,VLOOKUP(C21,Input!$A$4:$H$27,6,FALSE)),0) -> 17.4 | R21: =(P21-M21)/M21 -> -0.11858046 | S21: =(O21-Q21)/M21 -> 0.41938221 | T21: =M21*2.7 -> 753.25083 | U21: =N21*2.7 -> 1026.81 | V21: 0.1 | X21: =+V21*T21 -> 75.325083 | Y21: =+X21+T21 -> 828.57592 | Z21: =MIN(Y21,U21) -> 828.57592 | AA21: 1.205373 | AB21: =+N21 -> 380.3 | AC21: =+AB21*2.7 -> 1026.81 | AD21: =+AC21*AA21 -> 1237.6891
C22: NS_1020_LSP01 | D22: =IF(C22="",0,VLOOKUP(C22,Heading_ids!$A$4:$H$46,2,FALSE)) -> 5.5mW x 5.8mH - RS | E22: =IF(C22="",0,VLOOKUP(C22,Heading_ids!$A$4:$G$46,6,FALSE)) -> Waste | F22: =IF(C22="",0,VLOOKUP(C22,Heading_ids!$A$4:$G$46,5,FALSE)) -> GSS_02 | G22: =IF(C22="",0,VLOOKUP(C22,Heading_ids!$A$4:$G$46,7,FALSE)) -> CAP | H22: =IF(D22="",0,VLOOKUP(D22,Heading_profile!arch_profile,3,FALSE)) -> 31.12 | I22: =IFERROR(IF(C22="",0,VLOOKUP(C22,Input!$A$4:$H$23,7,FALSE)),0) -> 10.278 | J22: =+I22 -> 10.278 | K22: =I22 -> 10.278 | L22: =IFERROR(IF(E22="waste",VLOOKUP(C22,Stripping!$A$9:$I$40,9,FALSE),0),0) -> 109.8 | M22: =(K22*H22)+L22 -> 429.65136 | N22: =IFERROR(IF(C22="",0,VLOOKUP(C22,Input!$A$4:$H$27,8,FALSE)),0) -> 488.8 | O22: =IFERROR(IF(C22="",0,VLOOKUP(C22,Input!$A$4:$H$27,4,FALSE)),0) -> 73.6 | P22: =IFERROR(IF(C22="",0,VLOOKUP(C22,Input!$A$4:$H$27,5,FALSE)),0) -> 415.2 | Q22: =IFERROR(IF(C22="",0,VLOOKUP(C22,Input!$A$4:$H$27,6,FALSE)),0) -> 19.8 | R22: =(P22-M22)/M22 -> -0.033635085 | S22: =(O22-Q22)/M22 -> 0.1252178 | T22: =M22*2.7 -> 1160.0587 | U22: =N22*2.7 -> 1319.76 | V22: 0.1 | X22: =+V22*T22 -> 116.00587 | Y22: =+X22+T22 -> 1276.0645 | Z22: =MIN(Y22,U22) -> 1276.0645 | AA22: 1.205373 | AB22: =+N22 -> 488.8 | AC22: =+AB22*2.7 -> 1319.76 | AD22: =+AC22*AA22 -> 1590.8031
C23: NS_1020_RAD_N | D23: =IF(C23="",0,VLOOKUP(C23,Heading_ids!$A$4:$H$46,2,FALSE)) -> 5.5mW x 5.5mH - RS | E23: =IF(C23="",0,VLOOKUP(C23,Heading_ids!$A$4:$G$46,6,FALSE)) -> Waste | F23: =IF(C23="",0,VLOOKUP(C23,Heading_ids!$A$4:$G$46,5,FALSE)) -> GSS_02 | G23: =IF(C23="",0,VLOOKUP(C23,Heading_ids!$A$4:$G$46,7,FALSE)) -> CAP | H23: =IF(D23="",0,VLOOKUP(D23,Heading_profile!arch_profile,3,FALSE)) -> 29.81 | I23: =IFERROR(IF(C23="",0,VLOOKUP(C23,Input!$A$4:$H$23,7,FALSE)),0) -> 32.709 | J23: =+I23 -> 32.709 | K23: =I23 -> 32.709 | L23: =IFERROR(IF(E23="waste",VLOOKUP(C23,Stripping!$A$9:$I$40,9,FALSE),0),0) -> 49.5 | M23: =(K23*H23)+L23 -> 1024.5553 | N23: =IFERROR(IF(C23="",0,VLOOKUP(C23,Input!$A$4:$H$27,8,FALSE)),0) -> 1240.9 | O23: =IFERROR(IF(C23="",0,VLOOKUP(C23,Input!$A$4:$H$27,4,FALSE)),0) -> 264.8 | P23: =IFERROR(IF(C23="",0,VLOOKUP(C23,Input!$A$4:$H$27,5,FALSE)),0) -> 976.1 | Q23: =IFERROR(IF(C23="",0,VLOOKUP(C23,Input!$A$4:$H$27,6,FALSE)),0) -> 110.8 | R23: =(P23-M23)/M23 -> -0.047293973 | S23: =(O23-Q23)/M23 -> 0.15030912 | T23: =M23*2.7 -> 2766.2993 | U23: =N23*2.7 -> 3350.43 | V23: 0.1 | X23: =+V23*T23 -> 276.62993 | Y23: =+X23+T23 -> 3042.9292 | Z23: =MIN(Y23,U23) -> 3042.9292 | AA23: 1.205373 | AB23: =+N23 -> 1240.9 | AC23: =+AB23*2.7 -> 3350.43 | AD23: =+AC23*AA23 -> 4038.5179
C24: Waste | E24: Total Waste | I24: =SUM(I8:I23) -> 359.18 | J24: =SUM(J8:J23) -> 359.18 | K24: =SUM(K8:K23) -> 359.18 | L24: =SUM(L10:L23) -> 966.35 | M24: =SUM(M10:M23) -> 11921.727 | N24: =SUM(N10:N23) -> 13844.9 | O24: =SUM(O10:O23) -> 2382.8 | P24: =SUM(P10:P23) -> 11462.1 | Q24: =SUM(Q10:Q23) -> 799.1 | R24: =(P24-M24)/M24 -> -0.038553765 | S24: =(O24-Q24)/M24 -> 0.13284149 | T24: =SUM(T10:T23) -> 32188.664 | U24: =SUM(U10:U23) -> 37381.23 | Z24: =SUM(Z10:Z23) -> 35367.934 | AA24: =SUM(AA10:AA23) -> 22.356947 | AB24: =SUM(AB10:AB23) -> 16628.1 | AC24: =SUM(AC10:AC23) -> 44895.87 | AD24: =SUM(AD10:AD23) -> 57177.966
C25: NS_1040_ACC_N | D25: =IF(C25="",0,VLOOKUP(C25,Heading_ids!$A$4:$H$46,2,FALSE)) -> 5.5mW x 5.8mH - RS | E25: =IF(C25="",0,VLOOKUP(C25,Heading_ids!$A$4:$G$46,6,FALSE)) -> Ore | F25: =IF(C25="",0,VLOOKUP(C25,Heading_ids!$A$4:$G$46,5,FALSE)) -> GSS_02 | G25: =IF(C25="",0,VLOOKUP(C25,Heading_ids!$A$4:$G$46,7,FALSE)) -> CAP | H25: =IF(D25="",0,VLOOKUP(D25,Heading_profile!arch_profile,3,FALSE)) -> 31.12 | I25: =IFERROR(IF(C25="",0,VLOOKUP(C25,Input!$A$11:$H$13,7,FALSE)),0) -> 31.787 | J25: =+I25 -> 31.787 | K25: =I25 -> 31.787 | L25: 24 | M25: =(K25*H25)+L25 -> 1013.2114 | N25: =IFERROR(IF(C25="",0,VLOOKUP(C25,Input!$A$5:$H$13,8,FALSE)),0) -> 1243.3 | O25: =IFERROR(IF(C25="",0,VLOOKUP(C25,Input!$A$5:$H$13,4,FALSE)),0) -> 296.7 | P25: =IFERROR(IF(C25="",0,VLOOKUP(C25,Input!$A$5:$H$13,5,FALSE)),0) -> 946.6 | Q25: =IFERROR(IF(C25="",0,VLOOKUP(C25,Input!$A$5:$H$13,6,FALSE)),0) -> 80.9 | R25: =(P25-M25)/M25 -> -0.065742882 | S25: =(O25-Q25)/M25 -> 0.21298615 | T25: =M25*2.7 -> 2735.6709 | U25: =N25*2.7 -> 3356.91 | V25: 0.1 | X25: =+V25*T25 -> 273.56709 | Y25: =+X25+T25 -> 3009.238 | Z25: =MIN(Y25,U25) -> 3009.238 | AA25: 1.16588 | AB25: =+N25 -> 1243.3 | AC25: =+AB25*2.63 -> 3269.879 | AD25: =+AC25*AA25 -> 3812.2865
C27: ore | E27: Total ore | I27: =SUM(I25:I25) -> 31.787 | J27: =SUM(J25:J25) -> 31.787 | K27: =SUM(K25:K25) -> 31.787 | L27: =SUM(L25:L25) -> 24 | M27: =SUM(M25:M25) -> 1013.2114 | N27: =SUM(N25:N25) -> 1243.3 | O27: =SUM(O25:O25) -> 296.7 | P27: =SUM(P25:P25) -> 946.6 | Q27: =SUM(Q25:Q25) -> 80.9 | R27: =(P27-M27)/M27 -> -0.065742882 | S27: =(O27-Q27)/M27 -> 0.21298615 | T27: =SUM(T25:T25) -> 2735.6709 | U27: =SUM(U25:U25) -> 3356.91 | X27: =SUM(X25:X25) -> 273.56709 | Y27: =SUM(Y25:Y25) -> 3009.238 | Z27: =SUM(Z25:Z25) -> 3009.238 | AA27: =SUM(AA25:AA25) -> 1.16588 | AB27: =SUM(AB25:AB25) -> 1243.3 | AC27: =SUM(AC25:AC25) -> 3269.879 | AD27: =SUM(AD25:AD25) -> 3812.2865
E28: Combined Totals | I28: =+I27+I24 -> 390.967 | J28: =+J27+J24 -> 390.967 | K28: =+K27+K24 -> 390.967 | L28: =+L27+L24 -> 990.35 | M28: =+M27+M24 -> 12934.939 | N28: =+N27+N24 -> 15088.2 | O28: =+O27+O24 -> 2679.5 | P28: =+P27+P24 -> 12408.7 | Q28: =+Q27+Q24 -> 880 | R28: =(P28-M28)/M28 -> -0.040683526 | S28: =(O28-Q28)/M28 -> 0.13911933 | T28: {=SUM(+T27:T27)} -> 2735.6709 | U28: =+U27+U24 -> 40738.14 | Z28: =+Z27+Z24 -> 38377.172 | AA28: =+AA27+AA24 -> 23.522827 | AB28: =+AB27+AB24 -> 17871.4 | AC28: =+AC27+AC24 -> 48165.749 | AD28: =+AD27+AD24 -> 60990.252 | AF28: =IF(#REF!>#REF!,#REF!,#REF!) -> #REF!
AF29: =IF(#REF!>#REF!,#REF!,#REF!) -> #REF!
C30: Position | D30: Name | I30: Signature | L30: Date | AF30: =IF(#REF!>#REF!,#REF!,#REF!) -> #REF!
AF31: =IF(#REF!>#REF!,#REF!,#REF!) -> #REF! | AI31: exceljet.net\keyboard shortcuts
C32: Byrnecut Surveyor | AF32: =IF(#REF!>#REF!,#REF!,#REF!) -> #REF!
S33: For EOM Physicals | T33: Total Actual Ore Tonnes | AE33: =+U27 -> 3356.91 | AF33: =IF(#REF!>#REF!,#REF!,#REF!) -> #REF!
C34: Byrnecut Project Engineer | T34: Total Actual Waste Tonnes | AE34: =+U24 -> 37381.23 | AF34: =IF(#REF!>#REF!,#REF!,#REF!) -> #REF!
T35: Total Payment Meters | AE35: =+I28 -> 390.967 | AF35: =IF(#REF!>#REF!,#REF!,#REF!) -> #REF!
C36: QKR Senior Geologist | T36: Total Equivalent Meters | AE36: =+W24 -> 0 | AF36: =IF(#REF!>#REF!,#REF!,#REF!) -> #REF!
T37: Total Payment Waste Tonnes | AE37: =+Z24 -> 35367.934 | AF37: =IF(#REF!>#REF!,#REF!,#REF!) -> #REF!
C38: UG Project Manager | T38: Total Payment Ore Tonnes | AE38: =+U27 -> 3356.91 | AF38: =IF(#REF!>#REF!,#REF!,#REF!) -> #REF!
T39: Underbreak (%) | AE39: =+R28 -> -0.040683526 | AF39: =IF(#REF!>#REF!,#REF!,#REF!) -> #REF!
C40: Byrnecut Project Manager | T40: Overbreak(%) | AE40: =+S28 -> 0.13911933 | AF40: =IF(#REF!>#REF!,#REF!,#REF!) -> #REF!
S41: For EOM Physicals | T41: Actual Capital Development Metres (m) | AE41: =SUMIF($G$8:$G$54,"CAP",$I$8:$I$54) -> 390.967
S42: For EOM Physicals | T42: Actual Operating Development Metres (m) | AE42: =SUMIF($G$8:$G$54,"op",$I$8:$I$54) -> 0
...

Sheet Input
C1: Column1 | D1: Column2 | E1: Column3 | F1: Column4 | G1: Column5 | H1: Column6 | I1: Column7
A2: 1 | B2: 2 | C2: 3 | D2: 4 | E2: 5 | F2: 6 | G2: 7 | H2: 8
A3: Heading Name | B3: Stripping / Fillets | C3: EOM Design | D3: Outside Design | E3: Inside Design | F3: Under Floor Design | G3: Meters | H3: Actual vol
A4: SOUTH DECLINE | B4: 97.1 | C4: 2081.7413 | D4: 295.9 | E4: 2127.6 | F4: 111.8 | G4: 66.894 | H4: 2423.5
A5: MS_DSP06 | B5: 109.8 | C5: 760.106 | D5: 185.5 | E5: 820.4 | F5: 35.9 | G5: 24.425 | H5: 1005.9
A6: MS_PMP_STN1 | B6: 49.5 | C6: 497.49909 | D6: 82.2 | E6: 518.9 | F6: 31.7 | G6: 16.689 | H6: 601.1
A7: MS_840_DSMP W | B7: 12.5 | C7: 148.2 | D7: 86.5 | E7: 128.4 | F7: 6.2 | G7: 5.739 | H7: 214.9
A8: MS_900_RAD_E | C8: 979.58641 | D8: 211.1 | E8: 937.4 | F8: 56.1 | G8: 32.861 | H8: 1148.5
A9: MS_900_RAD_N | B9: 24.75 | C9: 180.9467 | D9: 18.8 | E9: 193.4 | F9: 2.9 | G9: 6.07 | H9: 212.2
A10: NORTH DECLINE | B10: 338.6 | C10: 2970.4662 | D10: 601.4 | E10: 3109.2 | F10: 280.1 | G10: 95.452 | H10: 3710.6
A11: NS_1040_ACC_N | B11: 24 | C11: 989.21144 | D11: 296.7 | E11: 946.6 | F11: 80.9 | G11: 31.787 | H11: 1243.3
A12: NS_1020_ACC_W | B12: 153.8 | C12: 1791.205 | D12: 428.6 | E12: 1989.6 | F12: 126.4 | G12: 57.558 | H12: 2418.2
A13: NS_1020_DSMP | B13: 21 | C13: 257.98179 | D13: 134.4 | E13: 245.9 | F13: 17.4 | G13: 10.505 | H13: 380.3
A14: NS_1020_LSP01 | B14: 109.8 | C14: 319.85136 | D14: 73.6 | E14: 415.2 | F14: 19.8 | G14: 10.278 | H14: 488.8
A15: NS_1020_RAD_N | B15: 49.5 | C15: 975.05529 | D15: 264.8 | E15: 976.1 | F15: 110.8 | G15: 32.709 | H15: 1240.9

Sheet Sheet5
A1: L1_1680____DEC__ | B1: 61.4 | C1: 53.543
A2: L1_1680____ACC_W | B2: 6.1 | C2: 2.576 | V2: L4_1205_700__DDR_N_waste | W2: 20.431 | AE2: 1205_745_PASTE | AF2: 127
A3: L1_1730____VAD_N | B3: 1.6 | V3: L4_1605_880__DDR_N_waste | W3: 15.511 | AE3: 1255_775_PASTE | AF3: 199
A4: L1_1900_330__DDR_W | B4: 2.7 | V4: L4_1755_950__DDR_E_waste | W4: 27.147 | AE4: 1455_790_PASTE | AF4: 406
A5: L1_1620_BYP__DEC__ | B5: 35.4 | AE5: 1555_670_PASTE | AF5: 165
A6: L1_1620_BYP__VAD__ | B6: 71.1 | AE6: 1605_640_PASTE | AF6: 251
A7: L1_1580_BYP__SP_N3 | B7: 23.8 | AE7: 1655_685_PASTE | AF7: 147
A8: L1_1580_BYP__SP_N4 | B8: 20.1 | AE8: 1655_475_PASTE | AF8: 179
A9: L4_1305_670__OPD_S | B9: 3.5 | AE9: 1655_530_PASTE | AF9: 104
A10: L4_1355_670__OPD_S | B10: 29.4 | AE10: 1705_775_PASTE | AF10: 393
A11: L4_1405_700__OPD_S | B11: 2.7 | AE11: 1705_835_PASTE | AF11: 244
AE12: 1845_440_PASTE | AF12: 230
A14: L4_1755_950__DDR_E | B14: 30.6
A15: L2_1845_455A_SLT_W | B15: 14
A16: L2_1845_455A_SLT_N | B16: 2
A17: L2_1845_455A_SLT_S | B17: 2
A18: L4_1355_685A_SLT_E | B18: 9.9
A19: L4_1205_700__DDR_N | B19: 36
A20: L4_1255_775B_SLT_E | B20: 9.8
A21: L4_1555_670A_SLT_E | B21: 1
A22: L4_1605_880__DDR_N | B22: 49.1
A23: L4_1705_950__DDR_E | B23: 2 | H23: Handle | I23: Figure Type | J23: SSIAttribute1 | K23: length
B24: =SUM(B1:B23) -> 414.2 | H24: 2A5F5 | I24: POLYLINE | J24: L1_1620_BYP__VAD__ | K24: 73.982021 | N24: Handle | O24: Figure Type | P24: SSIAttribute1 | Q24: length
H25: 2A5F6 | I25: POLYLINE | J25: L1_1620_BYP__DEC__ | K25: 35.254016 | N25: 2B0D6 | O25: POLYLINE | V25: 1205_700 | W25: 34.718 | Y25: L4_1205_700__DDR_N | Z25: 941 | AA25: 34.715489 | AB25: =+AA25-W25 -> -0.0025112996
H26: 2A5F7 | I26: POLYLINE | J26: L1_1580_BYP__SP_N4 | K26: 20.530019 | N26: 2AA80 | O26: POLYLINE | V26: 1255_775_SLT_E | W26: 9.493 | Y26: L4_1255_775B_SLT_E | Z26: 288 | AA26: 9.6719458 | AB26: =+AA26-W26 -> 0.17894582
H27: 2A5F8 | I27: POLYLINE | J27: L1_1580_BYP__SP_N3 | K27: 24.626771 | N27: 2AE72 | O27: POLYLINE | V27: 1305_670_OP | W27: 3.722 | Y27: L4_1305_670__OPD_S | Z27: 149 | AA27: 3.7247251 | AB27: =+AA27-W27 -> 0.0027250905
A28: L4_1405_685_RB_STRIP | B28: 61 | C28: 1405_685_STRIP | D28: 61 | H28: 2A62A | I28: POLYLINE | J28: L1_1680____ACC_W | K28: 2.7766919 | N28: 2B054 | O28: POLYLINE | V28: 1355_670_OP | W28: 29.271 | Y28: L4_1355_670__OPD_S | Z28: 922 | AA28: 29.288161 | AB28: =+AA28-W28 -> 0.017161074
A29: L1_1620_BYP VAD JB CUD | B29: 45 | C29: 1620_VAD_JB_CUD | D29: 45 | H29: 2A62B | I29: POLYLINE | J29: L1_1680____DEC__ | K29: 60.181373 | N29: 2ADD7 | O29: POLYLINE | V29: 1355_685_SLT_E | W29: 9.876 | Y29: L4_1355_685A_SLT_E | Z29: 280 | AA29: 9.8549697 | AB29: =+AA29-W29 -> -0.021030274
A30: L1_1680 DEC JB CUD | B30: 34 | C30: 1680_DEC_JB_CUD | D30: 34 | H30: 2A64A | I30: POLYLINE | J30: L1_1730____VAD_E | K30: 1.5863228 | N30: 2ADD6 | O30: POLYLINE | V30: 1405_700_OP | W30: 2.656 | Y30: L4_1405_700__OPD_S | Z30: 66 | AA30: 2.6555291 | AB30: =+AA30-W30 -> -0.00047085328
A31: L4_1655_530_SOLO_STRIP | B31: 24 | C31: 1655_530_STRIP | D31: 24 | H31: 2A681 | I31: POLYLINE | J31: L2_1845_455A_SLT_N | K31: 1.8466299 | N31: 2AE7B | O31: POLYLINE | V31: 1605_880 | W31: 53.915 | Y31: L4_1605_880__DDR_N | Z31: 1332 | AA31: 53.94275 | AB31: =+AA31-W31 -> 0.027750426
H32: 2A682 | I32: POLYLINE | J32: L2_1845_455A_SLT_S | K32: 2.6493556 | N32: 2A680 | O32: POLYLINE | V32: 1620_VAD | W32: 74.015 | Y32: L1_1620_BYP__VAD__ | Z32: 1976 | AA32: 73.982021 | AB32: =+AA32-W32 -> -0.032979346
H33: 2AA80 | I33: POLYLINE | J33: L4_1605_880__DDR_N | K33: 53.94275 | N33: 2A681 | O33: POLYLINE | V33: 1620_DEC | W33: 35.281 | Y33: L1_1620_BYP__DEC__ | Z33: 1228 | AA33: 35.254016 | AB33: =+AA33-W33 -> -0.026983841
H34: 2ADD6 | I34: POLYLINE | J34: L4_1355_670__OPD_S | K34: 29.288161 | N34: 2A682 | O34: POLYLINE | V34: 1580_BYP_SP#03 | W34: 24.484 | Y34: L1_1580_BYP__SP_N3 | Z34: 953 | AA34: 24.626771 | AB34: =+AA34-W34 -> 0.1427715
H35: 2ADD7 | I35: POLYLINE | J35: L4_1355_685A_SLT_E | K35: 9.8549697 | N35: 2A5F5 | O35: POLYLINE | V35: 1580_BYP_SP#04 | W35: 20.506 | Y35: L1_1580_BYP__SP_N4 | Z35: 736 | AA35: 20.530019 | AB35: =+AA35-W35 -> 0.024019021
H36: 2AE69 | I36: POLYLINE | J36: L4_1305_670__OPD_S | K36: 3.7247251 | N36: 2A5F7 | O36: POLYLINE | V36: 1680_DEC | W36: 61.007 | Y36: L1_1680____DEC__ | Z36: 2234 | AA36: 60.181373 | AB36: =+AA36-W36 -> -0.82562745
H37: 2AE72 | I37: POLYLINE | J37: L4_1255_775B_SLT_E | K37: 9.6719458 | N37: 2A5F8 | O37: POLYLINE | V37: 1680_ACC | W37: 2.644 | Y37: L1_1680____ACC_W | Z37: 157 | AA37: 2.7766919 | AB37: =+AA37-W37 -> 0.13269194
H38: 2AE7B | I38: POLYLINE | J38: L4_1205_700__DDR_N | K38: 34.715489 | N38: 2A5F6 | O38: POLYLINE | V38: 1705_950 | W38: 3.399 | Y38: L4_1705_950__DDR_E | Z38: 180 | AA38: 3.7257945 | AB38: =+AA38-W38 -> 0.32679455
H39: 2B054 | I39: POLYLINE | J39: L4_1405_700__OPD_S | K39: 2.6555291 | N39: 2A62B | O39: POLYLINE | V39: 1730_VAD | W39: 1.613 | Y39: L1_1730____VAD_E | Z39: 47 | AA39: 1.5863228 | AB39: =+AA39-W39 -> -0.026677208
H40: 2B0D6 | I40: POLYLINE | J40: L4_1755_950__DDR_E | K40: 30.93844 | N40: 2A62A | O40: POLYLINE | V40: 1755_950 | W40: 30.924 | Y40: L4_1755_950__DDR_E | Z40: 1050 | AA40: 30.93844 | AB40: =+AA40-W40 -> 0.014440136
H41: 2B0FF | I41: POLYLINE | J41: L4_1705_950__DDR_E | K41: 3.7257945 | N41: 2A64A | O41: POLYLINE | V41: 1845_420_S | W41: 2.444 | Y41: L2_1845_455A_SLT_S | Z41: 60 | AA41: 2.6493556 | AB41: =+AA41-W41 -> 0.20535558
...

Sheet Instructions
A2: End of Month Survey Data
A3: 1 | B3: Enter the month the End Of Month Survey report is for in cell A2 in XXXX 216 worksheet.
A4: 2 | B4: Enter the development name or number in colunm A of XXXX 2016 sheet
A5: 3 | B5: Select development dimensions for each heading form drop down menu in column B
A6: 4 | B6: Enter design gradient for each development headingin Column C
A7: 5 | B7: Select profile type from drop down menu in column D. Profile and dimension will automatically give an design area of the development which appears in Column E
A8: 6 | B8: Enter the metres of advance measured for each development heading in Column F
A9: 7 | B9: After confirmation from the geology manager enter the advance in ore for each of the development heading in column H. This will then calculate the advance in waste (total metres - ore metres), this will appear in column G
A10: 8 | B10: Enter the measured volumes for ore, waste and total for the development.
A11: 9 | B11: Enter the designed stripping for each heading
A12: 10 | B12: Enter the actual stripping for each heading
A15: For End of Month Claim
A16: 11 | B16: Select the nearest truck loading bay from the drop down menu. Truck must be developed. Column T
A17: 12 | B17: Select the haulage destination for waste from the drop down menu column U
A18: 13 | B18: Select the haulage destination for ore from the drop down menu column V
A19: 14 | B19: Select the ground support type from the drop down menu column W.
A20: 15 | B20: Select the Contract item number for the development heading from the drop down list. Item number and description can be found in the "Lists" worksheet
A21: 16 | B21: Development advance for the different Contract items is summarised in Claim Sum worksheet. You should be able to copy and paste this into the monthly claim calculator
A22: 17 | B22: Estimates for over break, rock bolts, fibrecrete m2, mesh m2 and haulage t.km are calculated and shown for each development heading. These can be used to check as default numbers and checks against the claim.

Sheet Stripping
C2: BOSA
C3: END OF MONTH STRIPPING
H5: Manual Add
A6: 1 | B6: 2 | C6: 3 | D6: 4 | E6: 5 | F6: 6 | G6: 7 | H6: 8 | I6: 9
A7: Drive Name | B7: Stripping | C7: Ground Support | D7: Width | E7: Design Strip | F7: Quantity | G7: Total Design Strip | H7: Actual | I7: Stripping Pay
C8: Design Profile | D8: & Height (m) | E8: Volume (m³) | G8: Volume (m3) | I8: Volume (m3)
A9: SOUTH DECLINE | B9: Loading bay | C9: =IF($A9="",0,VLOOKUP($A9,Heading_ids!$A$4:$H$46,5,FALSE)) -> GSS_01 | D9: =IF($A9="",0,VLOOKUP($A9,Heading_ids!$A$4:$H$46,2,FALSE)) -> 5.5mW x 5.8mH - RS | I9: 97.1
A10: MS_DSP06 | B10: Std_Fillet_3M | C10: =IF($A10="",0,VLOOKUP($A10,Heading_ids!$A$4:$H$46,5,FALSE)) -> GSS_01 | D10: 5.5mW x 5.8mH - RS | I10: 109.8
A11: MS_PMP_STN1 | B11: Std_Fillet_3M | C11: =IF($A11="",0,VLOOKUP($A11,Heading_ids!$A$4:$H$46,5,FALSE)) -> GSS_01 | D11: 5.5mW x 5.8mH - RS | I11: 49.5
A12: MS_840_DSMP W | B12: Std_Fillet_2.5M | C12: =IF($A12="",0,VLOOKUP($A12,Heading_ids!$A$4:$H$46,5,FALSE)) -> GSS_01 | D12: 5.5mW x 5.8mH - RS | I12: 12.5
A13: MS_900_RAD_E | C13: =IF($A13="",0,VLOOKUP($A13,Heading_ids!$A$4:$H$46,5,FALSE)) -> GSS_01 | D13: 5.5mW x 5.8mH - RS
A14: MS_900_RAD_N | B14: Std_Fillet_3M | C14: =IF($A14="",0,VLOOKUP($A14,Heading_ids!$A$4:$H$46,5,FALSE)) -> GSS_01 | D14: 5.0mW x 5.0mH - RS | I14: 24.75
A15: NORTH DECLINE | B15: Loading bay | C15: =IF($A15="",0,VLOOKUP($A15,Heading_ids!$A$4:$H$46,5,FALSE)) -> GSS_02 | D15: 5.5mW x 5.8mH - RS | I15: 338.6
A16: NS_1040_ACC_N | B16: Jumbo cuddy | C16: =IF($A16="",0,VLOOKUP($A16,Heading_ids!$A$4:$H$46,5,FALSE)) -> GSS_02 | D16: 5.5mW x 5.8mH - RS | I16: 24
A17: NS_1020_ACC_W | B17: Loading bay | C17: =IF($A17="",0,VLOOKUP($A17,Heading_ids!$A$4:$H$46,5,FALSE)) -> GSS_02 | D17: 5.5mW x 5.8mH - RS | I17: 153.8
A18: NS_1020_DSMP | B18: Std_Fillet_2.5M | C18: =IF($A18="",0,VLOOKUP($A18,Heading_ids!$A$4:$H$46,5,FALSE)) -> GSS_02 | D18: 5.5mW x 5.8mH - RS | I18: 21
A19: NS_1020_LSP01 | B19: SP_backstrip+Fillets | C19: =IF($A19="",0,VLOOKUP($A19,Heading_ids!$A$4:$H$46,5,FALSE)) -> GSS_02 | D19: 5.5mW x 5.8mH - RS | I19: 109.8
A20: NS_1020_RAD_N | B20: Std_Fillet_3M | C20: =IF($A20="",0,VLOOKUP($A20,Heading_ids!$A$4:$H$46,5,FALSE)) -> GSS_02 | D20: 5.5mW x 5.8mH - RS | I20: 49.5
I29: =SUM(I9:I28) -> 990.35
I30: =+'August_2026 eom ug dev'!L28 -> 990.35
I32: =+I30-I29 -> 0

Sheet Stripping_cal
B1: 1 | C1: 2 | D1: 3 | E1: 4 | F1: 5 | G1: 6 | H1: 7
B2: STRIPPING CALCULATIONS
B3: Description | C3: Ground Support | D3: length | E3: Width | F3: Height | G3: Area | H3: Stripping Volume (m3)
B4: Std_Fillet_3M | D4: 3 | E4: 3 | F4: 5.8 | H4: 26
B5: Std_Fillet_2.5M | D5: 2.5 | E5: 2.5 | F5: 5
B6: Loading bay | H6: 196
B7: SP_backstrip | H7: 67
B8: Jumbo cuddy | D8: 2 | E8: 2 | F8: 2 | G8: 4 | H8: =+F8*E8*D8 -> 8
B9: Elect.cuddy | D9: 2 | E9: 2 | F9: 2 | G9: 4 | H9: =+F9*E9*D9 -> 8
B10: SMP_backstrip and Fillets | H10: 4.2
B11: SMP_Pump_strip | H11: 14.7
B12: SP_backstrip+Fillets | H12: =+H4+H4+H7 -> 119

Sheet Heading_profile
A1: 9
B2: Profile selection
B3: Size | C3: profile | D3: Area | F3: Size | G3: profile | H3: Area | J3: Profiles
B4: 5.5mW x 5.8mH - RS | C4: Round Shoulders | D4: 31.12 | F4: 4.5 x 4.5 | G4: Sqr | J4: Arch | K4: Arched backs
B5: 5.0mW x 5.0mH - RS | C5: Round Shoulders | D5: 24.558 | F5: 4.5 x 5.5 | G5: Sqr | J5: Sqr | K5: Square backs
B6: 5.5mW x 5.5mH - RS | C6: Round Shoulders | D6: 29.81 | F6: 5.0 x 5.0 | G6: Sqr | J6: Rnd | K6: Raisebore
F8: 5.5 x 4.5 | G8: Sqr
F11: 4.0X4.0 | G11: Arch
F12: 4.0X4.0 | G12: Flat backs
K15: 24.6 | L15: 3.7
L16: =+L15*K15 -> 91.02
B45: Raise Profiles | C45: Area
B46: 2 dia | C46: =2^2*PI()/4 -> 3.1415927
B47: 2 x 2 | C47: 4
B48: 2.5 dia | C48: =2.5^2*PI()/4 -> 4.9087385
B49: 0.348 dia | C49: =0.348^2*PI()/4 -> 0.095114859
B50: G | C50: =3.5*3.5 -> 12.25
B51: 3.0 dia | C51: =3^2*PI()/4 -> 7.0685835
B52: 3.5 dia | C52: =3.5^2*PI()/4 -> 9.6211275
B53: 3.0 x 4.0 | C53: =3*4 -> 12
B54: 4 x 4 | C54: 16
B55: 4.5 dia | C55: =4.5^2*PI()/4 -> 15.904313
B56: 6 x 4 | C56: 24

Sheet Sheet1
B2: L4_1305_625B_SLT_W | C2: 333
B3: L4_1305_625B_SLT_E | C3: 308
B4: L4_1355_595__DDR_W | C4: 57
B5: L4_1405_715__DDR_N | C5: 114 | H5: L4_1705_950__DDR_E_WASTE
B6: L4_1455_700B_SLT_E | C6: 413 | H6: L4_1755_970__DDR_W_Waste
B7: L4_1455_700B_SLT_W | C7: 479 | H7: L1_1850_330__DDR_N_WASTE
B8: L1_1550____SP_E | C8: 753
B9: L1_1560____DDC_N | C9: 122
B10: L1_1560____DDC_S | C10: 284
B11: L1_1565____DEC__ | C11: 1761
B12: L1_1580____INC__ | C12: 987
B13: L1_1580____ACC_W | C13: 1062
B14: L1_1580____SMP_S | C14: 191
B15: L1_1580____RAD_W | C15: 109
B16: L1_1640____SMP_E | C16: 250
B17: L1_1635____CUD_E | C17: 221
B18: L1_1630____RAD_W | C18: 446
B19: L1_1630____DEC__ | C19: 1826
... B30: L1_1900_315__DDR_W | C30: 101
