Workbook

Sheet Cover
B2: ASSESSMENT OF DRILLING AND GROUND SUPPORT
B3: CONSUMABLE COSTS FOR UNDERGROUND DEVELOPMENT
B4: Navachab Gold Mine Project, Byrnecut. May to August 2026.
B6: STUDY DETAILS
B7: Researcher | C7: Irene Zinyetu Kavhura, student number 221315594
B8: Programme | C8: BSc Honours in Mining Engineering, University of Namibia
B9: Department | C9: Civil and Mining Engineering
B10: Supervisor | C10: Mr. Nekwaya Tuyeni Kelao
B11: Development contractor | C11: Byrnecut
B12: Analysis period | C12: May, June, July and August 2026
B13: Currency | C13: United States dollars, converted at the rate on the Inputs sheet
B15: WHERE EACH OBJECTIVE IS ANSWERED
B16: Objective | C16: Sheet | E16: Status
B17: Objective 1: drilling consumable unit cost per metre | C17: Unit_Cost section 2, C_Face_Drilling | E17: Complete. Reported per metre advanced and per drilled metre.
B18: Objective 2: ground support unit cost per metre, and the main cost drivers | C18: Unit_Cost section 1, Pareto | E18: Complete.
B19: Objective 3: development productivity baseline | C19: Advance section 2, DRM | E19: Complete. Metres per month and per heading, and drilled metres per advance metre.
B20: Objective 4: advance rate against total unit cost | C20: Unit_Cost sections 3 to 5 | E20: Complete. Equation 4 separates the consumption effect from the advance effect.
B21: Analysis by heading and by portal | C21: Portal_Analysis | E21: Complete. All four months, with reconciliation checks.
B22: Design compliance and over consumption | C22: Plan_vs_Actual | E22: Complete for bolts, split sets and mesh against the GSS standards.
B24: CONTENTS
B25: Equations | C25: Every equation used, with its symbols defined
B26: Inputs | C26: Unit costs, exchange rate, design standards, portal split bases
B27: Advance | C27: Survey advance as recorded, and monthly totals
B28: Consumption_PL | C28: Stock counts as recorded, with consumption derived
B29: A_Scaling | C29: Scaling consumables
B30: B_Ground_Support | C30: Bolts, bearing plates and mesh
B31: C_Face_Drilling | C31: Shanks, bits, rods, couplings, centralisers, dollies
B32: D_Cable_Bolting | C32: Cable bolts and hardware
B33: DRM | C33: Drilled metres, and bit life for the 43 mm and 48 mm bits
B34: Plan_vs_Actual | C34: Design quantity against actual, by ground class
B35: Unit_Cost | C35: Equations 1 to 4, and why the unit cost moved
B36: Portal_Analysis | C36: Heading and portal results, with reconciliation checks
... B44: How_to_Read | C44: Symbols, formats and the numbered notes
B46: READING THE WORKBOOK
B47: Blue figures | C47: Entered from a source document
B48: Green figures | C48: Drawn from another sheet
B49: Black figures | C49: Calculated
B50: x | C50: No unit price exists in the source data. Never treated as zero.
B51: - | C51: Cost already carried by another line
B52: ( ) | C52: A negative figure, in the accounting convention
...

Sheet Dashboard
B2: DASHBOARD
B3: Whole underground mine, May to August 2026.
B6: 1 HEADLINE
B7: Measure | C7: Unit | E7: May | F7: June | G7: July | H7: August | J7: Period
B8: Development advance | C8: m | E8: =Advance!E53 -> 270.436 | F8: =Advance!F53 -> 316.617 | G8: =Advance!G53 -> 397.798 | H8: =Advance!H53 -> 390.967 | J8: =Advance!H53 -> 390.967
B9: Ground support consumable cost | C9: US$ | E9: =Unit_Cost!E13 -> 377506.07 | F9: =Unit_Cost!F13 -> 298939.35 | G9: =Unit_Cost!G13 -> 385623.4 | H9: =Unit_Cost!H13 -> 327302.19 | J9: =Unit_Cost!H13 -> 327302.19
B10: Drilling consumable cost | C10: US$ | E10: =Unit_Cost!E24 -> 175938.32 | F10: =Unit_Cost!F24 -> 164342.43 | G10: =Unit_Cost!G24 -> 350729.41 | H10: =Unit_Cost!H24 -> 294906.06 | J10: =Unit_Cost!H24 -> 294906.06
B11: Total consumable cost | C11: US$ | E11: =Unit_Cost!E13+Unit_Cost!E24 -> 553444.39 | F11: =Unit_Cost!F13+Unit_Cost!F24 -> 463281.78 | G11: =Unit_Cost!G13+Unit_Cost!G24 -> 736352.81 | H11: =Unit_Cost!H13+Unit_Cost!H24 -> 622208.25 | J11: =Unit_Cost!H13+Unit_Cost!H24 -> 622208.25
B12: Total drilled metres | C12: drilled m | E12: =DRM!E26 -> 29381.1 | F12: =DRM!F26 -> 33867 | G12: =DRM!G26 -> 49347.6 | H12: =DRM!H26 -> 42289.6 | J12: =DRM!H26 -> 42289.6
B13: Consumable cost per metre advanced | C13: US$/m | E13: =IF(E8=0,0,E11/E8) -> 2046.4893 | F13: =IF(F8=0,0,F11/F8) -> 1463.2246 | G13: =IF(G8=0,0,G11/G8) -> 1851.0722 | H13: =IF(H8=0,0,H11/H8) -> 1591.4598 | J13: =IF(J8=0,0,J11/J8) -> 1591.4598
B14: Consumable cost per drilled metre | C14: US$/drilled m | E14: =IF(E12=0,0,E11/E12) -> 18.836748 | F14: =IF(F12=0,0,F11/F12) -> 13.679445 | G14: =IF(G12=0,0,G11/G12) -> 14.921755 | H14: =IF(H12=0,0,H11/H12) -> 14.713032 | J14: =IF(J12=0,0,J11/J12) -> 14.713032
B15: Drilled metres per metre advanced | C15: ratio | E15: =IF(E8=0,0,E12/E8) -> 108.64345 | F15: =IF(F8=0,0,F12/F8) -> 106.9652 | G15: =IF(G8=0,0,G12/G8) -> 124.05191 | H15: =IF(H8=0,0,H12/H8) -> 108.16667 | J15: =IF(J8=0,0,J12/J8) -> 108.16667
B17: 2 PORTAL AND GROUND CLASS
B18: Portal | C18: Ground | E18: Metres, period | F18: Share of metres | J18: Ground support cost per metre
B19: Northern Portal | C19: All fair to poor, GSS_02 and GSS_03 | E19: =Portal_Analysis!E41 -> 756.39 | F19: =IF(Portal_Analysis!G41=0,0,E19/Portal_Analysis!G41) -> 0.54977475 | J19: =Portal_Analysis!E53 -> 1036.7869
B20: Southern Portal | C20: All good, GSS_01 | E20: =Portal_Analysis!F41 -> 619.428 | F20: =IF(Portal_Analysis!G41=0,0,E20/Portal_Analysis!G41) -> 0.45022525 | J20: =Portal_Analysis!F53 -> 976.95906
B22: Portal and ground class coincide exactly in this data, so the two cannot be separated statistically.
B24: 3 WHERE THE MONEY IS
B25: Consumable | E25: Period cost | F25: Share | G25: Cumulative
B26: =Pareto!B7 -> 1. MD bolt 2.4 m galvanised | E26: =Pareto!E7 -> 904575.32 | F26: =Pareto!H7 -> 0.38082776 | G26: =Pareto!I7 -> 0.38082776
B27: =Pareto!B8 -> 2. Shank T45 RD520/525 D45 L525 | E27: =Pareto!E8 -> 473326.75 | F27: =Pareto!H8 -> 0.19927137 | G27: =Pareto!I8 -> 0.58009913
B28: =Pareto!B9 -> 3. Mesh 2.40 x 4.50 m galvanised | E28: =Pareto!E9 -> 353779.93 | F28: =Pareto!H9 -> 0.14894196 | G28: =Pareto!I9 -> 0.72904109
B29: =Pareto!B10 -> 4. Bit adaptor T45F / T38M | E29: =Pareto!E10 -> 227125.95 | F29: =Pareto!H10 -> 0.095620415 | G29: =Pareto!I10 -> 0.8246615
B30: =Pareto!B11 -> 5. Coupling sleeve T45 / T38 | E30: =Pareto!E11 -> 100124.44 | F30: =Pareto!H11 -> 0.042152561 | G30: =Pareto!I11 -> 0.86681407
B33: 4 DATA COMPLETENESS
B34: Measure | E34: Value | I34: Meaning
B35: Consumption captured by the issue registers | E35: =Consumption_Compare!J176 -> 0 | L35: The registers record about half of what the stock counts measure
B36: Drilling items consumed but unpriced | E36: =COUNTIF(C_Face_Drilling!$E$7:$E$60,"x") -> 0 | L36: Each one shows x rather than zero
B37: Material bought but not recorded as installed | E37: =IF(Triangulation!$E$40=0,0,1-Triangulation!$F$40/Triangulation!$E$40) -> 0.37845136 | L37: Stock count against LiveMine installation record

Sheet Equations
B2: EQUATIONS USED IN THIS MODEL
B3: Every calculated figure in the workbook comes from one of the equations below.
B6: Equation 1 Drilling consumable unit cost
B7: UC drill = ( C bits + C rods + C shanks + C couplings + C centralisers ) ÷ m
B8: UC drill | C8: Drilling consumable unit cost, US$ per metre
B9: C bits, C rods, C shanks, C couplings, C centralisers | C9: Total cost of drill steel consumed in the period, US$. Consumption quantity from the stock reconciliation multiplied by the supplier unit price.
B10: m | C10: Total metres advanced in the same period, from the survey end of month report
B11: Calculated on | C11: Unit_Cost, and the item detail on C_Face_Drilling
B13: Equation 2 Ground support consumable unit cost
B14: UC support = ( C bolts + C mesh + C plates + C resin + C cable ) ÷ m
B15: UC support | C15: Ground support consumable unit cost, US$ per metre
B16: C bolts, C mesh, C plates, C resin, C cable | C16: Total cost of ground support consumed in the period, US$. Bearing plates are quoted inside the bolt price and are not costed separately.
B17: m | C17: Total metres advanced in the same period. Every development metre in this data receives support.
B18: Calculated on | C18: Unit_Cost, and the item detail on B_Ground_Support and D_Cable_Bolting
B20: Equation 3 Total development unit cost
B21: UC total = UC drill + UC support
B22: UC total | C22: Total consumable unit cost, US$ per metre
B23: UC drill, UC support | C23: Consumable unit costs from Equations 1 and 2, US$ per metre
B24: Scope | C24: Consumables only. Labour and equipment operating costs are outside the scope of this study and are not included in any figure in this workbook.
B25: Calculated on | C25: Unit_Cost
B27: Equation 4 Change in unit cost between two periods
B28: U1 − U0 = ( C1 − C0 ) ÷ A0 + C1 × ( 1/A1 − 1/A0 )
B29: U0, U1 | C29: Consumable unit cost in the earlier and later period, US$ per metre
B30: C0, C1 | C30: Total consumable cost in the earlier and later period, US$
B31: A0, A1 | C31: Metres advanced in the earlier and later period
B32: first term | C32: Consumption effect: the cost of using more or less material, holding advance constant
B33: second term | C33: Advance effect: the effect of spreading the same spend over a different number of metres
B34: Calculated on | C34: Unit_Cost, section 4
B36: Equation 5 Pareto contribution
B37: P i = C i ÷ Σ C i × 100 Cum i = Σ ( C 1 … C i ) ÷ Σ C i × 100
B38: P i | C38: Percentage contribution of consumable i to total consumable cost
B39: C i | C39: Total cost of consumable i in the period, with items ranked highest to lowest
B40: Cum i | C40: Cumulative percentage down the ranked list
B41: Calculated on | C41: Pareto
B43: Equation 6 Currency conversion
B44: Cost in US$ = Cost in N$ ÷ R
B45: R | C45: Exchange rate, Namibia dollars per United States dollar
B46: Cost in N$ | C46: Supplier unit cost as stated in the mine price list
B47: Cost in US$ | C47: The reporting currency of this workbook. Drilling prices are already quoted in United States dollars and are not converted.
B48: Calculated on | C48: Inputs, and every cost sheet
...

Sheet Inputs
B2: INPUTS AND ASSUMPTIONS
B3: Unit costs, exchange rate, design standards and drilling geometry used throughout the workbook.
B4: Blue figures are taken directly from a source document. Shaded cells are awaiting data; each one is listed on the Data_Quality sheet.
B6: 1 EXCHANGE RATE
B7: Item | C7: Description | D7: Unit | E7: Value
B8: R | C8: Namibia dollars per United States dollar | D8: N$ / USD | E8: 16.16
B10: 2 CONSUMABLE UNIT COSTS
B11: Item code | C11: Description | D11: Unit | E11: Unit cost (USD) | F11: Unit cost (US$)
B12: FB39090GWA | C12: Friction bolt 39 x 900 galvanised | D12: each | E12: 7.3844946 | F12: =E12*Inputs!$E$8 -> 119.33343
B13: FB47090GWA | C13: Friction bolt 47 x 900 galvanised | D13: each | E13: 12.897225 | F13: =E13*Inputs!$E$8 -> 208.41916
B14: FB47-2400G | C14: Friction bolt 47 x 2400 galvanised | D14: each | E14: 15.931125 | F14: =E14*Inputs!$E$8 -> 257.44698
B15: BMG2024S | C15: MD bolt 2.4 m galvanised | D15: each | E15: 65.878328 | F15: =E15*Inputs!$E$8 -> 1064.5938
B16: CBD1B065DC05WA | C16: Cable bolt twin strand bulbed 15.2 mm | D16: each | E16: 68.071961 | F16: =E16*Inputs!$E$8 -> 1100.0429
B17: MESH2.4X4.5 | C17: Mesh 2.40 x 4.50 m galvanised | D17: sheet | E17: =E20*E21 -> 82.485411 | F17: =E17*Inputs!$E$8 -> 1332.9642
B19: 3 CONVERSION FACTORS
B20: Mesh sheet area | C20: One sheet measures 2.40 m by 4.50 m | D20: m2 | E20: 10.8
B21: Mesh rate | C21: Galvanised mesh, price per square metre | D21: USD / m2 | E21: 7.637538
B23: 4 PORTAL SPLIT OF GROUND SUPPORT COST
B24: Month | C24: Northern Portal | D24: Southern Portal | F24: Basis
B25: May 2026 | C25: 0.39673913 | D25: =1-C25 -> 0.60326087 | F25: LiveMine installed quantities, measured by heading
B26: June 2026 | C26: 0.60118078 | D26: =1-C26 -> 0.39881922 | F26: LiveMine installed quantities, measured by heading
B27: July 2026 | C27: 0.66189193 | D27: =1-C27 -> 0.33810807 | F27: LiveMine installed quantities, measured by heading
B28: August 2026 | C28: 0.60948622 | D28: =1-C28 -> 0.39051378 | F28: Metres advanced. No LiveMine inventory extract was supplied for this month
B30: See Notes sheet, note 1.
B32: 5 PORTAL SPLIT OF DRILLING CONSUMABLE COST
B33: Month | C33: Northern Portal | D33: Southern Portal | F33: Basis
B34: May 2026 | C34: 0.40359578 | D34: =1-C34 -> 0.59640422 | F34: Drilled metres, 8,398 north and 12,410 south
B35: June 2026 | C35: 0.56313131 | D35: =1-C35 -> 0.43686869 | F35: Drilled metres, 12,466 north and 9,671 south
B36: July 2026 | C36: 0.64772425 | D36: =1-C36 -> 0.35227575 | F36: Drilled metres, 20,928 north and 11,382 south
B37: August 2026 | C37: 0.64296728 | D37: =1-C37 -> 0.35703272 | F37: Drilled metres, 16,138 north and 8,961 south
B39: See Notes sheet, note 2.
B41: 6 DRILLING CONSUMABLE UNIT COSTS
B42: Item code | C42: Description | D42: Unit | E42: Unit cost (US$)
B43: 7304-7669-01 | C43: Shank T38 RD520/525 D45 L525 | D43: each | E43: 308.1
B44: 7305-7669-01 | C44: Shank T45 RD520/525 D45 L525 | D44: each | E44: 5568.55
B45: 7335-4401 | C45: Bit adaptor T45F / T38M | D45: each | E45: 4453.45
B46: 7314-6261 | C46: Coupling sleeve T45 / T38 | D46: each | E46: 1925.47
B47: 7314-3652 | C47: Coupling sleeve T38 / T38 | D47: each | E47: 69.96
B48: 7580-5243A-S70 | C48: A340 43 mm button bit | D48: each | E48: 66.52
B49: 7580-5345A-R48 | C49: A340 45 mm button bit | D49: each | E49: 78.93
...

Sheet Advance
B2: SURVEY DEVELOPMENT ADVANCE
B3: Source: Byrnecut Development Payment end of month reports, EOM Advance column, signed by the Byrnecut surveyor.
B4: Ore and waste rows of one heading are consolidated. North Shoot Decline and NS_1040_ACC_N are one location.
B6: 1 ADVANCE AS RECORDED BY SURVEY
B7: Month | C7: Survey period | D7: Heading as recorded | E7: Location used in this model | F7: Portal | G7: Material | H7: GS type | I7: Profile (m2) | J7: Advance (m)
B8: May 2026 | C8: 1 to 31 May 2026 | D8: SOUTH DECLINE | E8: South Decline | F8: Southern Portal | G8: Waste | H8: GSS_01 | I8: 31.12 | J8: 75.154
B9: May 2026 | C9: 1 to 31 May 2026 | D9: NORTH DECLINE | E9: North Decline | F9: Northern Portal | G9: Waste | H9: GSS_02 | I9: 31.12 | J9: 55.882
B10: May 2026 | C10: 1 to 31 May 2026 | D10: MS_1040_ACC_waste | E10: N_1040_ACCESS (NS 1040 access) | F10: Northern Portal | G10: Waste | H10: GSS_02 | I10: 31.12 | J10: 6
B11: May 2026 | C11: 1 to 31 May 2026 | D11: MS900_ACC_E | E11: MS900_ACC_E | F11: Southern Portal | G11: Waste | H11: GSS_01 | I11: 31.12 | J11: 17.508
B12: May 2026 | C12: 1 to 31 May 2026 | D12: MS_1040_ACC_waste | E12: N_1040_ACCESS (NS 1040 access) | F12: Northern Portal | G12: Waste | H12: GSS_01 | I12: 31.12 | J12: 4.278
B13: May 2026 | C13: 1 to 31 May 2026 | D13: MS900_DDR_N_waste | E13: MS900_DDR_N | F13: Southern Portal | G13: Waste | H13: GSS_01 | I13: 31.12 | J13: 22.683
B14: May 2026 | C14: 1 to 31 May 2026 | D14: MS900_DDR_N_waste1 | E14: MS900_DDR_N | F14: Southern Portal | G14: Waste | H14: GSS_01 | I14: 24.519 | J14: 16.102
B15: May 2026 | C15: 1 to 31 May 2026 | D15: S890_SP_W | E15: S890_SP_W | F15: Southern Portal | G15: Waste | H15: GSS_01 | I15: 31.12 | J15: 24.029
B16: May 2026 | C16: 1 to 31 May 2026 | D16: S900_SMP W | E16: S900_SMP_W | F16: Southern Portal | G16: Waste | H16: GSS_01 | I16: 24.519 | J16: 5
B17: May 2026 | C17: 1 to 31 May 2026 | D17: MS_1040_ACC_OD | E17: N_1040_ACCESS (NS 1040 access) | F17: Northern Portal | G17: ORE | H17: GSS_02 | I17: 31.12 | J17: 16.9
B18: May 2026 | C18: 1 to 31 May 2026 | D18: MS900_DDR_N_OD | E18: MS900_DDR_N | F18: Southern Portal | G18: ORE | H18: GSS_01 | I18: 24.519 | J18: 26.9
B19: June 2026 | C19: 29 May to 28 June 2026 | D19: SOUTH DECLINE | E19: South Decline | F19: Southern Portal | G19: Waste | H19: GSS_01 | I19: 31.12 | J19: 70.356
... B48: August 2026 | C48: 29 July to 28 August 2026 | D48: NS_1020_RAD_N | E48: NS_1020_RAD_N | F48: Northern Portal | G48: Waste | H48: GSS_02 | I48: 29.81 | J48: 32.709
B50: 2 MONTHLY TOTALS, WHOLE UNDERGROUND MINE
B51: Measure | C51: Unit | E51: May 2026 | F51: June 2026 | G51: July 2026 | H51: August 2026 | I51: Period total | K51: Mean per month
B52: Days in period | C52: days | E52: 31 | F52: 31 | G52: 30 | H52: 31
B53: Total advance | C53: m | E53: =SUMIFS($J$8:$J$48,$B$8:$B$48,"May 2026") -> 270.436 | F53: =SUMIFS($J$8:$J$48,$B$8:$B$48,"June 2026") -> 316.617 | G53: =SUMIFS($J$8:$J$48,$B$8:$B$48,"July 2026") -> 397.798 | H53: =SUMIFS($J$8:$J$48,$B$8:$B$48,"August 2026") -> 390.967 | I53: =SUM(E53:H53) -> 1375.818 | K53: =AVERAGE(E53:H53) -> 343.9545
B54: Advance rate | C54: m / day | E54: =IF(E52=0,0,E53/E52) -> 8.7237419 | F54: =IF(F52=0,0,F53/F52) -> 10.213452 | G54: =IF(G52=0,0,G53/G52) -> 13.259933 | H54: =IF(H52=0,0,H53/H52) -> 12.611839 | K54: =AVERAGE(E54:H54) -> 11.202241
B55: Advance rate | C55: m / shift | E55: y | F55: y | G55: y | H55: y
B57: See Notes sheet, note 3.

Sheet Consumption_PL
B2: STOCK RECONCILIATION, MEASURED CONSUMPTION
B3: Source: EOM PL Count Sheets for May and June 2026 and the End July EOM Stocktake Sheet.
B4: Consumption = Opening count + Quantity received − Closing count. This measures material actually used, not material signed out of store.
F6: May 2026 | J6: June 2026 | N6: July 2026 | R6: August 2026
B7: Item code | C7: Description | D7: Unit | F7: Opening (units) | G7: Received (units) | H7: Closing (units) | I7: Consumption (units) | J7: Opening (units) | K7: Received (units) | L7: Closing (units) | M7: Consumption (units) | N7: Opening (units) | O7: Received (units) | P7: Closing (units) | Q7: Consumption (units)
B8: 7324-8043-20 | C8: Drifter rod T38 H35 A340 L=430, scaling rod | D8: each | F8: 75 | G8: 0 | H8: 68 | I8: =F8+G8-H8 -> 7 | J8: 68 | L8: 67 | M8: =J8+K8-L8 -> 1 | N8: 67 | O8: 5 | P8: 71 | Q8: =N8+O8-P8 -> 1 | R8: 71 | T8: 72 | U8: =R8+S8-T8 -> -1
B9: 7580-5243A-S70 | C9: A340 43 mm button bit | D9: each | F9: 85 | G9: 50 | H9: 20 | I9: =F9+G9-H9 -> 115 | J9: 20 | L9: 20 | M9: =J9+K9-L9 -> 0 | N9: 20 | O9: 40 | P9: 50 | Q9: =N9+O9-P9 -> 10 | R9: 50 | T9: 50 | U9: =R9+S9-T9 -> 0
B10: 7580-5345A-R48 | C10: A340 45 mm button bit | D10: each | F10: 330 | G10: 0 | H10: 258 | I10: =F10+G10-H10 -> 72 | J10: 258 | L10: 258 | M10: =J10+K10-L10 -> 0 | N10: 258 | P10: 248 | Q10: =N10+O10-P10 -> 10 | R10: 248 | T10: 223 | U10: =R10+S10-T10 -> 25
B11: 7304-7669-01 | C11: Shank T38 RD520/525 D45 L525 | D11: each | F11: 26 | G11: 0 | H11: 25 | I11: =F11+G11-H11 -> 1 | J11: 25 | L11: 20 | M11: =J11+K11-L11 -> 5 | N11: 20 | O11: 45 | P11: 20 | Q11: =N11+O11-P11 -> 45 | R11: 20 | T11: 19 | U11: =R11+S11-T11 -> 1
B12: FB39090GWA | C12: Friction bolt 39 x 900 galvanised | D12: each | F12: 3483 | G12: 0 | H12: 3300 | I12: =F12+G12-H12 -> 183 | J12: 3300 | L12: 3123 | M12: =J12+K12-L12 -> 177 | N12: 3123 | P12: 3380 | Q12: =N12+O12-P12 -> -257 | R12: 3380 | T12: 3300 | U12: =R12+S12-T12 -> 80
B13: FB47090GWA | C13: Friction bolt 47 x 900 galvanised | D13: each | F13: 3750 | G13: 0 | H13: 3450 | I13: =F13+G13-H13 -> 300 | J13: 3450 | L13: 2921 | M13: =J13+K13-L13 -> 529 | N13: 2921 | P13: 2520 | Q13: =N13+O13-P13 -> 401 | R13: 2520 | T13: 2200 | U13: =R13+S13-T13 -> 320
B14: FB47-2400G | C14: Friction bolt 47 x 2400 galvanised | D14: each | F14: 888 | G14: 0 | H14: 145 | I14: =F14+G14-H14 -> 743 | J14: 145 | K14: 4800 | L14: 3996 | M14: =J14+K14-L14 -> 949 | N14: 3996 | O14: 4800 | P14: 6637 | Q14: =N14+O14-P14 -> 2159 | R14: 6486 | T14: 4200 | U14: =R14+S14-T14 -> 2286
B15: BMG2024S | C15: MD bolt 2.4 m galvanised | D15: each | F15: 11095 | G15: 0 | H15: 8520 | I15: =F15+G15-H15 -> 2575 | J15: 8520 | K15: 10080 | L15: 14926 | M15: =J15+K15-L15 -> 3674 | N15: 14926 | P15: 10763 | Q15: =N15+O15-P15 -> 4163 | R15: 10279 | T15: 6960 | U15: =R15+S15-T15 -> 3319
B16: D1515441GWA | C16: Plate dome 150 x 150 x 4, 41H galvanised | D16: each | F16: 3560 | G16: 0 | H16: 3560 | I16: =F16+G16-H16 -> 0 | J16: 3560 | L16: 3545 | M16: =J16+K16-L16 -> 15 | N16: 3545 | P16: 3545 | Q16: =N16+O16-P16 -> 0 | R16: 3545 | T16: 3336 | U16: =R16+S16-T16 -> 209
B17: CBP328154-47G | C17: D/Fly plate 300 x 280 galvanised | D17: each | F17: 4078 | G17: 0 | H17: 3438 | I17: =F17+G17-H17 -> 640 | J17: 3356 | K17: 4800 | L17: 7102 | M17: =J17+K17-L17 -> 1054 | N17: 7102 | O17: 4800 | P17: 9300 | Q17: =N17+O17-P17 -> 2602 | R17: 9200 | T17: 5970 | U17: =R17+S17-T17 -> 3230
B18: BPG3002806 | C18: Combi plate 300 x 280 x 6 mm galvanised | D18: each | F18: 10560 | G18: 0 | H18: 7820 | I18: =F18+G18-H18 -> 2740 | J18: 7820 | K18: 10080 | L18: 15170 | M18: =J18+K18-L18 -> 2730 | N18: 15170 | P18: 10680 | Q18: =N18+O18-P18 -> 4490 | R18: 10638 | T18: 6240 | U18: =R18+S18-T18 -> 4398
B19: MESH2.4X4.5 | C19: Mesh 2.40 x 4.50 m galvanised | D19: sheet | F19: 2256 | G19: 3675 | H19: 3640 | I19: =F19+G19-H19 -> 2291 | J19: 3640 | L19: 3232 | M19: =J19+K19-L19 -> 408 | N19: 3232 | P19: 2411 | Q19: =N19+O19-P19 -> 821 | R19: 2411 | T19: 1642 | U19: =R19+S19-T19 -> 769
B20: 7305-7669-01 | C20: Shank T45 RD520/525 D45 L525 | D20: each | F20: 15 | G20: 50 | H20: 57 | I20: =F20+G20-H20 -> 8 | J20: 57 | K20: 60 | L20: 98 | M20: =J20+K20-L20 -> 19 | N20: 98 | O20: 45 | P20: 109 | Q20: =N20+O20-P20 -> 34 | R20: 109 | T20: 85 | U20: =R20+S20-T20 -> 24
B21: 7335-4401 | C21: Bit adaptor T45F / T38M | D21: each | F21: 39 | G21: 30 | H21: 54 | I21: =F21+G21-H21 -> 15 | J21: 54 | L21: 50 | M21: =J21+K21-L21 -> 4 | N21: 50 | P21: 34 | Q21: =N21+O21-P21 -> 16 | R21: 34 | T21: 18 | U21: =R21+S21-T21 -> 16
B22: 7314-6261 | C22: Coupling sleeve T45 / T38 | D22: each | F22: 13 | G22: 0 | H22: 2 | I22: =F22+G22-H22 -> 11 | J22: 2 | K22: 60 | L22: 55 | M22: =J22+K22-L22 -> 7 | N22: 55 | O22: 45 | P22: 86 | Q22: =N22+O22-P22 -> 14 | R22: 86 | T22: 66 | U22: =R22+S22-T22 -> 20
B23: 7314-3652 | C23: Coupling sleeve T38 / T38 | D23: each | F23: 55 | G23: 0 | H23: 50 | I23: =F23+G23-H23 -> 5 | J23: 50 | L23: 49 | M23: =J23+K23-L23 -> 1 | N23: 49 | P23: 46 | Q23: =N23+O23-P23 -> 3 | R23: 46 | T23: 46 | U23: =R23+S23-T23 -> 0
B24: 7580-5148A-S81 | C24: A340 48 mm TC button bit | D24: each | F24: 0 | G24: 0 | H24: 0 | I24: =F24+G24-H24 -> 0 | J24: 0 | L24: 0 | M24: =J24+K24-L24 -> 0 | N24: 0 | O24: 70 | P24: 70 | Q24: =N24+O24-P24 -> 0 | R24: 70 | T24: 35 | U24: =R24+S24-T24 -> 35
B25: 7580-4651A-S70 | C25: A340 51 mm retrac bit | D25: each | F25: 30 | G25: 0 | H25: 20 | I25: =F25+G25-H25 -> 10 | J25: 20 | L25: 5 | M25: =J25+K25-L25 -> 15 | N25: 5 | O25: 20 | P25: 15 | Q25: =N25+O25-P25 -> 10 | R25: 15 | T25: 0 | U25: =R25+S25-T25 -> 15
B26: 7580-5602P-S70 | C26: Reaming bit A340 102 mm | D26: each | F26: 38 | G26: 0 | H26: 24 | I26: =F26+G26-H26 -> 14 | J26: 24 | L26: 22 | M26: =J26+K26-L26 -> 2 | N26: 22 | O26: 15 | P26: 23 | Q26: =N26+O26-P26 -> 14 | R26: 23 | T26: 11 | U26: =R26+S26-T26 -> 12
B27: 7514-1664-S70 | C27: T38 64 mm button bit | D27: each | F27: 3 | G27: 40 | H27: 21 | I27: =F27+G27-H27 -> 22 | J27: 21 | L27: 1 | M27: =J27+K27-L27 -> 20 | N27: 1 | O27: 20 | P27: 20 | Q27: =N27+O27-P27 -> 1 | R27: 20 | T27: 8 | U27: =R27+S27-T27 -> 12
B28: 7580-6045-F49 | C28: Speedy bit A340 45 mm XT49 | D28: each | F28: 70 | G28: 100 | H28: 108 | I28: =F28+G28-H28 -> 62 | J28: 108 | L28: 66 | M28: =J28+K28-L28 -> 42 | N28: 66 | O28: 70 | P28: 116 | Q28: =N28+O28-P28 -> 20 | R28: 116 | T28: 46 | U28: =R28+S28-T28 -> 70
B29: 7324-8037-20 | C29: Drifter rod T38 H35 A340 L=370, drilling steel | D29: each | F29: 27 | G29: 0 | H29: 26 | I29: =F29+G29-H29 -> 1 | J29: 26 | L29: 26 | M29: =J29+K29-L29 -> 0 | N29: 26 | P29: 19 | Q29: =N29+O29-P29 -> 7 | R29: 19 | T29: 0 | U29: =R29+S29-T29 -> 19
B30: 7324-7949-20 | C30: Drifter rod T38 R39 A340 L=491, speed rod | D30: each | F30: 202 | G30: 0 | H30: 187 | I30: =F30+G30-H30 -> 15 | J30: 187 | L30: 169 | M30: =J30+K30-L30 -> 18 | N30: 169 | O30: 35 | P30: 188 | Q30: =N30+O30-P30 -> 16 | R30: 187 | T30: 163 | U30: =R30+S30-T30 -> 24
B31: 7324-4731-85 | C31: MF rod T38 R39 L=3050 mm | D31: each | F31: 59 | G31: 0 | H31: 57 | I31: =F31+G31-H31 -> 2 | J31: 57 | L31: 56 | M31: =J31+K31-L31 -> 1 | N31: 56 | P31: 53 | Q31: =N31+O31-P31 -> 3 | R31: 53 | T31: 49 | U31: =R31+S31-T31 -> 4
B32: 7324-4331C-30 | C32: T38 extension round rod L=3050 mm | D32: each | F32: 36 | G32: 0 | H32: 21 | I32: =F32+G32-H32 -> 15 | J32: 21 | L32: 9 | M32: =J32+K32-L32 -> 12 | N32: 9 | P32: 9 | Q32: =N32+O32-P32 -> 0 | R32: 9 | T32: 5 | U32: =R32+S32-T32 -> 4
B33: 7324-4309C-30 | C33: Extension rod T38 R39 L=915 mm | D33: each | F33: 7 | G33: 0 | H33: 7 | I33: =F33+G33-H33 -> 0 | J33: 7 | L33: 3 | M33: =J33+K33-L33 -> 4 | N33: 3 | O33: 5 | P33: 7 | Q33: =N33+O33-P33 -> 1 | R33: 7 | T33: 6 | U33: =R33+S33-T33 -> 1
B34: 7324-4709C-20 | C34: MF rod T38 R39 L=915 mm | D34: each | F34: 6 | G34: 0 | H34: 6 | I34: =F34+G34-H34 -> 0 | J34: 6 | L34: 5 | M34: =J34+K34-L34 -> 1 | N34: 5 | O34: 5 | P34: 9 | Q34: =N34+O34-P34 -> 1 | R34: 9 | T34: 8 | U34: =R34+S34-T34 -> 1
B35: M2000354 | C35: Bolting centraliser dia 70 mm front | D35: each | G35: 0 | H35: 48 | I35: =F35+G35-H35 -> -48 | J35: 48 | L35: 39 | M35: =J35+K35-L35 -> 9 | N35: 39 | O35: 60 | P35: 87 | Q35: =N35+O35-P35 -> 12 | R35: 87 | T35: 83 | U35: =R35+S35-T35 -> 4
B36: M2000353 | C36: Bolting centraliser dia 70 mm back | D36: each | F36: 26 | G36: 0 | H36: 60 | I36: =F36+G36-H36 -> -34 | J36: 60 | L36: 60 | M36: =J36+K36-L36 -> 0 | N36: 60 | O36: 60 | P36: 118 | Q36: =N36+O36-P36 -> 2 | R36: 118 | T36: 117 | U36: =R36+S36-T36 -> 1
B37: M33191232 | C37: Boring centraliser dia 48 mm | D37: each | G37: 0 | H37: 48 | I37: =F37+G37-H37 -> -48 | J37: 48 | L37: 48 | M37: =J37+K37-L37 -> 0 | N37: 48 | O37: 50 | P37: 94 | Q37: =N37+O37-P37 -> 4 | R37: 94 | T37: 92 | U37: =R37+S37-T37 -> 2
B38: 33191231 | C38: Boring centraliser dia 41 mm | D38: each | I38: =F38+G38-H38 -> 0 | M38: =J38+K38-L38 -> 0 | N38: 87 | P38: 78 | Q38: =N38+O38-P38 -> 9 | R38: 78 | T38: 77 | U38: =R38+S38-T38 -> 1
B39: 33191232 | C39: Boring centraliser dia 48 mm | D39: each | I39: =F39+G39-H39 -> 0 | M39: =J39+K39-L39 -> 0 | N39: 85 | P39: 83 | Q39: =N39+O39-P39 -> 2 | R39: 83 | T39: 82 | U39: =R39+S39-T39 -> 1
B40: 33191234 | C40: Bolting centraliser dia 66 mm guide | D40: each | I40: =F40+G40-H40 -> 0 | M40: =J40+K40-L40 -> 0 | N40: 163 | P40: 161 | Q40: =N40+O40-P40 -> 2 | R40: 161 | T40: 161 | U40: =R40+S40-T40 -> 0
B41: 7979-2630 | C41: T38 dolly 47 mm | D41: each | F41: 46 | G41: 0 | H41: 46 | I41: =F41+G41-H41 -> 0 | J41: 46 | L41: 43 | M41: =J41+K41-L41 -> 3 | N41: 43 | O41: 5 | P41: 47 | Q41: =N41+O41-P41 -> 1 | R41: 47 | T41: 43 | U41: =R41+S41-T41 -> 4
B42: 7979-2626 | C42: T38 dolly 39 mm | D42: each | F42: 7 | G42: 0 | H42: 7 | I42: =F42+G42-H42 -> 0 | J42: 7 | L42: 7 | M42: =J42+K42-L42 -> 0 | N42: 7 | O42: 5 | P42: 7 | Q42: =N42+O42-P42 -> 5 | R42: 7 | T42: 7 | U42: =R42+S42-T42 -> 0
...

Sheet Consumption_Issues
B2: CONSUMPTION FROM THE STOCK USAGE ISSUE REGISTERS
B3: Source: Stock Usage Sheets, May to August 2026. Sum of the Qty issued column by item and month.
B4: This measures material signed out of store and recorded on a transaction. It is the second, independent measure of consumption.
B6: Item code | C6: Description | D6: Unit | F6: May (units) | G6: June (units) | H6: July (units) | I6: August (units) | J6: Total (units) | L6: Note
B7: 7324-8043-20 | C7: Drifter rod T38 H35 A340 L=430, scaling rod | D7: each | F7: 0 | G7: 2 | H7: 0 | I7: =SUM(F7:H7) -> 2
B8: 7580-5243A-S70 | C8: A340 43 mm button bit | D8: each | F8: 110 | G8: 0 | H8: 10 | I8: =SUM(F8:H8) -> 120
B9: 7580-5345A-R48 | C9: A340 45 mm button bit | D9: each | F9: 62 | G9: 0 | H9: 10 | I9: =SUM(F9:H9) -> 72
B10: 7304-7669-01 | C10: Shank T38 RD520/525 D45 L525 | D10: each | F10: 1 | G10: 7 | H10: 2 | I10: =SUM(F10:H10) -> 10
B11: FB39090GWA | C11: Friction bolt 39 x 900 galvanised | D11: each | F11: 0 | G11: 0 | H11: 150 | I11: =SUM(F11:H11) -> 150
B12: FB47090GWA | C12: Friction bolt 47 x 900 galvanised | D12: each | F12: 26 | G12: 150 | H12: 270 | I12: =SUM(F12:H12) -> 446
B13: FB47-2400G | C13: Friction bolt 47 x 2400 galvanised | D13: each | F13: 156 | G13: 1350 | H13: 728 | I13: =SUM(F13:H13) -> 2234
B14: BMG2024S | C14: MD bolt 2.4 m galvanised | D14: each | F14: 1852 | G14: 885 | H14: 1602 | I14: =SUM(F14:H14) -> 4339
B15: D1515441GWA | C15: Plate dome 150 x 150 x 4, 41H galvanised | D15: each | F15: 0 | G15: 0 | H15: 0 | I15: =SUM(F15:H15) -> 0 | K15: No issue transaction recorded for this item
B16: CBP328154-47G | C16: D/Fly plate 300 x 280 galvanised | D16: each | F16: 20 | G16: 0 | H16: 780 | I16: =SUM(F16:H16) -> 800
B17: BPG3002806 | C17: Combi plate 300 x 280 x 6 mm galvanised | D17: each | F17: 3496 | G17: 2245 | H17: 1733 | I17: =SUM(F17:H17) -> 7474
B18: MESH2.4X4.5 | C18: Mesh 2.40 x 4.50 m galvanised | D18: sheet | F18: 200 | G18: 230 | H18: 369 | I18: =SUM(F18:H18) -> 799
B19: 7305-7669-01 | C19: Shank T45 RD520/525 D45 L525 | D19: each | F19: 6 | G19: 23 | H19: 32 | I19: =SUM(F19:H19) -> 61
B20: 7335-4401 | C20: Bit adaptor T45F / T38M | D20: each | F20: 12 | G20: 4 | H20: 10 | I20: =SUM(F20:H20) -> 26
B21: 7314-6261 | C21: Coupling sleeve T45 / T38 | D21: each | F21: 10 | G21: 7 | H21: 14 | I21: =SUM(F21:H21) -> 31
B22: 7314-3652 | C22: Coupling sleeve T38 / T38 | D22: each | F22: 5 | G22: 1 | H22: 3 | I22: =SUM(F22:H22) -> 9
B23: 7580-5148A-S81 | C23: A340 48 mm TC button bit | D23: each | F23: 0 | G23: 0 | H23: 10 | I23: =SUM(F23:H23) -> 10
B24: 7580-4651A-S70 | C24: A340 51 mm retrac bit | D24: each | F24: 8 | G24: 15 | H24: 10 | I24: =SUM(F24:H24) -> 33
B25: 7580-5602P-S70 | C25: Reaming bit A340 102 mm | D25: each | F25: 12 | G25: 0 | H25: 14 | I25: =SUM(F25:H25) -> 26
B26: 7514-1664-S70 | C26: T38 64 mm button bit | D26: each | F26: 27 | G26: 20 | H26: 3 | I26: =SUM(F26:H26) -> 50
B27: 7580-6045-F49 | C27: Speedy bit A340 45 mm XT49 | D27: each | F27: 60 | G27: 26 | H27: 30 | I27: =SUM(F27:H27) -> 116
... B35: M2000353 | C35: Bolting centraliser dia 70 mm back | D35: each | F35: 0 | G35: 0 | H35: 2 | I35: =SUM(F35:H35) -> 2
B36: M33191232 | C36: Boring centraliser dia 48 mm | D36: each | F36: 0 | G36: 0 | H36: 0 | I36: =SUM(F36:H36) -> 0 | K36: No issue transaction recorded for this item
B37: 33191231 | C37: Boring centraliser dia 41 mm | D37: each | F37: 4 | G37: 3 | H37: 5 | I37: =SUM(F37:H37) -> 12
B38: 33191232 | C38: Boring centraliser dia 48 mm | D38: each | F38: 0 | G38: 5 | H38: 6 | I38: =SUM(F38:H38) -> 11
B39: 33191234 | C39: Bolting centraliser dia 66 mm guide | D39: each | F39: 0 | G39: 2 | H39: 2 | I39: =SUM(F39:H39) -> 4
B40: 7979-2630 | C40: T38 dolly 47 mm | D40: each | F40: 0 | G40: 1 | H40: 2 | I40: =SUM(F40:H40) -> 3
B41: 7979-2626 | C41: T38 dolly 39 mm | D41: each | F41: 0 | G41: 2 | H41: 0 | I41: =SUM(F41:H41) -> 2
B42: CBD1B065DC05WA | C42: Cable bolt twin strand bulbed 15.2 mm | D42: each | F42: 0 | G42: 51 | H42: 18 | I42: =SUM(F42:H42) -> 69
B43: BLW15003RWA | C43: Barrel and 3 piece wedge anchor | D43: each | F43: 50 | G43: 0 | H43: 50 | I43: =SUM(F43:H43) -> 100
B44: FCB20203H222WA | C44: Plate flat 200 x 200 x 12 mm | D44: each | F44: 0 | G44: 0 | H44: 38 | I44: =SUM(F44:H44) -> 38
C45: Total, all items | F45: =SUM(F7:F44) -> 6124 | G45: =SUM(G7:G44) -> 5062 | H45: =SUM(H7:H44) -> 5916 | I45: =SUM(I7:I44) -> 17102 | J45: =SUM(J7:J44) -> 0
B47: See Notes sheet, note 5.

Sheet Consumption_Compare
B2: COMPARISON OF THE TWO CONSUMPTION MEASURES
B3: Stock count consumption against issue register consumption, by item and month.
B4: The stock count is the costing basis. The issue register is the corroborating measure. Neither has been adjusted to match the other.
B6: MAY 2026
B7: Item code | C7: Description | D7: Unit | F7: Stock count (units) | G7: Issue register (units) | H7: Gap (units) | K7: Register capture | M7: Flag
B8: 7324-8043-20 | C8: Drifter rod T38 H35 A340 L=430, scaling rod | D8: each | F8: =Consumption_PL!I8 -> 7 | G8: =Consumption_Issues!F7 -> 0 | H8: =G8-F8 -> -7 | K8: =IF(F8<=0,"n/a",G8/F8) -> 0 | L8: =IF(F8<=0,"",IF(OR(J8<0.5,J8>1.5),"Check","")) -> Check
B9: 7580-5243A-S70 | C9: A340 43 mm button bit | D9: each | F9: =Consumption_PL!I9 -> 115 | G9: =Consumption_Issues!F8 -> 110 | H9: =G9-F9 -> -5 | K9: =IF(F9<=0,"n/a",G9/F9) -> 0.95652174 | L9: =IF(F9<=0,"",IF(OR(J9<0.5,J9>1.5),"Check","")) -> Check
B10: 7580-5345A-R48 | C10: A340 45 mm button bit | D10: each | F10: =Consumption_PL!I10 -> 72 | G10: =Consumption_Issues!F9 -> 62 | H10: =G10-F10 -> -10 | K10: =IF(F10<=0,"n/a",G10/F10) -> 0.86111111 | L10: =IF(F10<=0,"",IF(OR(J10<0.5,J10>1.5),"Check","")) -> Check
B11: 7304-7669-01 | C11: Shank T38 RD520/525 D45 L525 | D11: each | F11: =Consumption_PL!I11 -> 1 | G11: =Consumption_Issues!F10 -> 1 | H11: =G11-F11 -> 0 | K11: =IF(F11<=0,"n/a",G11/F11) -> 1 | L11: =IF(F11<=0,"",IF(OR(J11<0.5,J11>1.5),"Check","")) -> Check
B12: FB39090GWA | C12: Friction bolt 39 x 900 galvanised | D12: each | F12: =Consumption_PL!I12 -> 183 | G12: =Consumption_Issues!F11 -> 0 | H12: =G12-F12 -> -183 | K12: =IF(F12<=0,"n/a",G12/F12) -> 0 | L12: =IF(F12<=0,"",IF(OR(J12<0.5,J12>1.5),"Check","")) -> Check
B13: FB47090GWA | C13: Friction bolt 47 x 900 galvanised | D13: each | F13: =Consumption_PL!I13 -> 300 | G13: =Consumption_Issues!F12 -> 26 | H13: =G13-F13 -> -274 | K13: =IF(F13<=0,"n/a",G13/F13) -> 0.086666667 | L13: =IF(F13<=0,"",IF(OR(J13<0.5,J13>1.5),"Check","")) -> Check
B14: FB47-2400G | C14: Friction bolt 47 x 2400 galvanised | D14: each | F14: =Consumption_PL!I14 -> 743 | G14: =Consumption_Issues!F13 -> 156 | H14: =G14-F14 -> -587 | K14: =IF(F14<=0,"n/a",G14/F14) -> 0.20995962 | L14: =IF(F14<=0,"",IF(OR(J14<0.5,J14>1.5),"Check","")) -> Check
B15: BMG2024S | C15: MD bolt 2.4 m galvanised | D15: each | F15: =Consumption_PL!I15 -> 2575 | G15: =Consumption_Issues!F14 -> 1852 | H15: =G15-F15 -> -723 | K15: =IF(F15<=0,"n/a",G15/F15) -> 0.7192233 | L15: =IF(F15<=0,"",IF(OR(J15<0.5,J15>1.5),"Check","")) -> Check
B16: D1515441GWA | C16: Plate dome 150 x 150 x 4, 41H galvanised | D16: each | F16: =Consumption_PL!I16 -> 0 | G16: =Consumption_Issues!F15 -> 0 | H16: =G16-F16 -> 0 | K16: =IF(F16<=0,"n/a",G16/F16) -> n/a | L16: =IF(F16<=0,"",IF(OR(J16<0.5,J16>1.5),"Check",""))
B17: CBP328154-47G | C17: D/Fly plate 300 x 280 galvanised | D17: each | F17: =Consumption_PL!I17 -> 640 | G17: =Consumption_Issues!F16 -> 20 | H17: =G17-F17 -> -620 | K17: =IF(F17<=0,"n/a",G17/F17) -> 0.03125 | L17: =IF(F17<=0,"",IF(OR(J17<0.5,J17>1.5),"Check","")) -> Check
B18: BPG3002806 | C18: Combi plate 300 x 280 x 6 mm galvanised | D18: each | F18: =Consumption_PL!I18 -> 2740 | G18: =Consumption_Issues!F17 -> 3496 | H18: =G18-F18 -> 756 | K18: =IF(F18<=0,"n/a",G18/F18) -> 1.2759124 | L18: =IF(F18<=0,"",IF(OR(J18<0.5,J18>1.5),"Check","")) -> Check
B19: MESH2.4X4.5 | C19: Mesh 2.40 x 4.50 m galvanised | D19: sheet | F19: =Consumption_PL!I19 -> 2291 | G19: =Consumption_Issues!F18 -> 200 | H19: =G19-F19 -> -2091 | K19: =IF(F19<=0,"n/a",G19/F19) -> 0.087298123 | L19: =IF(F19<=0,"",IF(OR(J19<0.5,J19>1.5),"Check","")) -> Check
... B45: FCB20203H222WA | C45: Plate flat 200 x 200 x 12 mm | D45: each | F45: =Consumption_PL!I45 -> 306 | G45: =Consumption_Issues!F44 -> 0 | H45: =G45-F45 -> -306 | K45: =IF(F45<=0,"n/a",G45/F45) -> 0 | L45: =IF(F45<=0,"",IF(OR(J45<0.5,J45>1.5),"Check","")) -> Check
C46: May 2026 total | F46: =SUM(F8:F45) -> 10053 | G46: =SUM(G8:G45) -> 6124 | H46: =SUM(H8:H45) -> -3929 | K46: =IF(F46<=0,"n/a",G46/F46) -> 0.60917139
B48: JUNE 2026
B49: Item code | C49: Description | D49: Unit | F49: Stock count (units) | G49: Issue register (units) | H49: Gap (units) | K49: Register capture | M49: Flag
B50: 7324-8043-20 | C50: Drifter rod T38 H35 A340 L=430, scaling rod | D50: each | F50: =Consumption_PL!M8 -> 1 | G50: =Consumption_Issues!G7 -> 2 | H50: =G50-F50 -> 1 | K50: =IF(F50<=0,"n/a",G50/F50) -> 2 | L50: =IF(F50<=0,"",IF(OR(J50<0.5,J50>1.5),"Check","")) -> Check
B51: 7580-5243A-S70 | C51: A340 43 mm button bit | D51: each | F51: =Consumption_PL!M9 -> 0 | G51: =Consumption_Issues!G8 -> 0 | H51: =G51-F51 -> 0 | K51: =IF(F51<=0,"n/a",G51/F51) -> n/a | L51: =IF(F51<=0,"",IF(OR(J51<0.5,J51>1.5),"Check",""))
B52: 7580-5345A-R48 | C52: A340 45 mm button bit | D52: each | F52: =Consumption_PL!M10 -> 0 | G52: =Consumption_Issues!G9 -> 0 | H52: =G52-F52 -> 0 | K52: =IF(F52<=0,"n/a",G52/F52) -> n/a | L52: =IF(F52<=0,"",IF(OR(J52<0.5,J52>1.5),"Check",""))
B53: 7304-7669-01 | C53: Shank T38 RD520/525 D45 L525 | D53: each | F53: =Consumption_PL!M11 -> 5 | G53: =Consumption_Issues!G10 -> 7 | H53: =G53-F53 -> 2 | K53: =IF(F53<=0,"n/a",G53/F53) -> 1.4 | L53: =IF(F53<=0,"",IF(OR(J53<0.5,J53>1.5),"Check","")) -> Check
B54: FB39090GWA | C54: Friction bolt 39 x 900 galvanised | D54: each | F54: =Consumption_PL!M12 -> 177 | G54: =Consumption_Issues!G11 -> 0 | H54: =G54-F54 -> -177 | K54: =IF(F54<=0,"n/a",G54/F54) -> 0 | L54: =IF(F54<=0,"",IF(OR(J54<0.5,J54>1.5),"Check","")) -> Check
B55: FB47090GWA | C55: Friction bolt 47 x 900 galvanised | D55: each | F55: =Consumption_PL!M13 -> 529 | G55: =Consumption_Issues!G12 -> 150 | H55: =G55-F55 -> -379 | K55: =IF(F55<=0,"n/a",G55/F55) -> 0.28355388 | L55: =IF(F55<=0,"",IF(OR(J55<0.5,J55>1.5),"Check","")) -> Check
B56: FB47-2400G | C56: Friction bolt 47 x 2400 galvanised | D56: each | F56: =Consumption_PL!M14 -> 949 | G56: =Consumption_Issues!G13 -> 1350 | H56: =G56-F56 -> 401 | K56: =IF(F56<=0,"n/a",G56/F56) -> 1.4225501 | L56: =IF(F56<=0,"",IF(OR(J56<0.5,J56>1.5),"Check","")) -> Check
B57: BMG2024S | C57: MD bolt 2.4 m galvanised | D57: each | F57: =Consumption_PL!M15 -> 3674 | G57: =Consumption_Issues!G14 -> 885 | H57: =G57-F57 -> -2789 | K57: =IF(F57<=0,"n/a",G57/F57) -> 0.24088187 | L57: =IF(F57<=0,"",IF(OR(J57<0.5,J57>1.5),"Check","")) -> Check
B58: D1515441GWA | C58: Plate dome 150 x 150 x 4, 41H galvanised | D58: each | F58: =Consumption_PL!M16 -> 15 | G58: =Consumption_Issues!G15 -> 0 | H58: =G58-F58 -> -15 | K58: =IF(F58<=0,"n/a",G58/F58) -> 0 | L58: =IF(F58<=0,"",IF(OR(J58<0.5,J58>1.5),"Check","")) -> Check
B59: CBP328154-47G | C59: D/Fly plate 300 x 280 galvanised | D59: each | F59: =Consumption_PL!M17 -> 1054 | G59: =Consumption_Issues!G16 -> 0 | H59: =G59-F59 -> -1054 | K59: =IF(F59<=0,"n/a",G59/F59) -> 0 | L59: =IF(F59<=0,"",IF(OR(J59<0.5,J59>1.5),"Check","")) -> Check
B60: BPG3002806 | C60: Combi plate 300 x 280 x 6 mm galvanised | D60: each | F60: =Consumption_PL!M18 -> 2730 | G60: =Consumption_Issues!G17 -> 2245 | H60: =G60-F60 -> -485 | K60: =IF(F60<=0,"n/a",G60/F60) -> 0.82234432 | L60: =IF(F60<=0,"",IF(OR(J60<0.5,J60>1.5),"Check","")) -> Check
B61: MESH2.4X4.5 | C61: Mesh 2.40 x 4.50 m galvanised | D61: sheet | F61: =Consumption_PL!M19 -> 408 | G61: =Consumption_Issues!G18 -> 230 | H61: =G61-F61 -> -178 | K61: =IF(F61<=0,"n/a",G61/F61) -> 0.56372549 | L61: =IF(F61<=0,"",IF(OR(J61<0.5,J61>1.5),"Check","")) -> Check
... B87: FCB20203H222WA | C87: Plate flat 200 x 200 x 12 mm | D87: each | F87: =Consumption_PL!M45 -> 94 | G87: =Consumption_Issues!G44 -> 0 | H87: =G87-F87 -> -94 | K87: =IF(F87<=0,"n/a",G87/F87) -> 0 | L87: =IF(F87<=0,"",IF(OR(J87<0.5,J87>1.5),"Check","")) -> Check
C88: June 2026 total | F88: =SUM(F50:F87) -> 10200 | G88: =SUM(G50:G87) -> 5062 | H88: =SUM(H50:H87) -> -5138 | K88: =IF(F88<=0,"n/a",G88/F88) -> 0.49627451
B90: JULY 2026
B91: Item code | C91: Description | D91: Unit | F91: Stock count (units) | G91: Issue register (units) | H91: Gap (units) | K91: Register capture | M91: Flag
B92: 7324-8043-20 | C92: Drifter rod T38 H35 A340 L=430, scaling rod | D92: each | F92: =Consumption_PL!Q8 -> 1 | G92: =Consumption_Issues!H7 -> 0 | H92: =G92-F92 -> -1 | K92: =IF(F92<=0,"n/a",G92/F92) -> 0 | L92: =IF(F92<=0,"",IF(OR(J92<0.5,J92>1.5),"Check","")) -> Check
B93: 7580-5243A-S70 | C93: A340 43 mm button bit | D93: each | F93: =Consumption_PL!Q9 -> 10 | G93: =Consumption_Issues!H8 -> 10 | H93: =G93-F93 -> 0 | K93: =IF(F93<=0,"n/a",G93/F93) -> 1 | L93: =IF(F93<=0,"",IF(OR(J93<0.5,J93>1.5),"Check","")) -> Check
B94: 7580-5345A-R48 | C94: A340 45 mm button bit | D94: each | F94: =Consumption_PL!Q10 -> 10 | G94: =Consumption_Issues!H9 -> 10 | H94: =G94-F94 -> 0 | K94: =IF(F94<=0,"n/a",G94/F94) -> 1 | L94: =IF(F94<=0,"",IF(OR(J94<0.5,J94>1.5),"Check","")) -> Check
...

Sheet A_Scaling
B2: SHEET A SCALING
B3: Scaling and sounding of the face and walls before development drilling.
B4: Quantities are measured consumption. Cost = quantity x unit cost. All costs in United States dollars.
B6: Item code | C6: Description | D6: Unit | E6: Unit cost (US$) | G6: May (units) | H6: June (units) | I6: July (units) | J6: August (units) | K6: Total (units) | M6: Units per metre | N6: Total cost (US$), period | O6: Cost per metre (US$/m), period
B7: Drilling consumables
B8: 7324-8043-20 | C8: Drifter rod T38 H35 A340 L=430, scaling rod | D8: each | E8: x | G8: =MAX(0,Consumption_PL!I8) -> 7 | H8: =MAX(0,Consumption_PL!M8) -> 1 | I8: =MAX(0,Consumption_PL!Q8) -> 1 | J8: =MAX(0,Consumption_PL!U8) -> 0 | K8: =SUM(G8:J8) -> 9 | M8: =IF(Advance!$I$53=0,0,K8/Advance!$I$53) -> 0.0065415629 | N8: =IF(NOT(ISNUMBER($E8)),$E8,K8*$E8) -> x | O8: =IF(NOT(ISNUMBER($E8)),$E8,N8/Advance!$I$53) -> x
B9: 7580-5243A-S70 | C9: A340 43 mm button bit | D9: each | E9: - | G9: =MAX(0,Consumption_PL!I9) -> 115 | H9: =MAX(0,Consumption_PL!M9) -> 0 | I9: =MAX(0,Consumption_PL!Q9) -> 10 | J9: =MAX(0,Consumption_PL!U9) -> 0 | K9: =SUM(G9:J9) -> 125 | M9: =IF(Advance!$I$53=0,0,K9/Advance!$I$53) -> 0.09085504 | N9: =IF(NOT(ISNUMBER($E9)),$E9,K9*$E9) -> - | O9: =IF(NOT(ISNUMBER($E9)),$E9,N9/Advance!$I$53) -> -
B10: 7580-5345A-R48 | C10: A340 45 mm button bit | D10: each | E10: - | G10: =MAX(0,Consumption_PL!I10) -> 72 | H10: =MAX(0,Consumption_PL!M10) -> 0 | I10: =MAX(0,Consumption_PL!Q10) -> 10 | J10: =MAX(0,Consumption_PL!U10) -> 25 | K10: =SUM(G10:J10) -> 107 | M10: =IF(Advance!$I$53=0,0,K10/Advance!$I$53) -> 0.077771915 | N10: =IF(NOT(ISNUMBER($E10)),$E10,K10*$E10) -> - | O10: =IF(NOT(ISNUMBER($E10)),$E10,N10/Advance!$I$53) -> -
B11: 7304-7669-01 | C11: Shank T38 RD520/525 D45 L525 | D11: each | E11: - | G11: =MAX(0,Consumption_PL!I11) -> 1 | H11: =MAX(0,Consumption_PL!M11) -> 5 | I11: =MAX(0,Consumption_PL!Q11) -> 45 | J11: =MAX(0,Consumption_PL!U11) -> 1 | K11: =SUM(G11:J11) -> 52 | M11: =IF(Advance!$I$53=0,0,K11/Advance!$I$53) -> 0.037795697 | N11: =IF(NOT(ISNUMBER($E11)),$E11,K11*$E11) -> - | O11: =IF(NOT(ISNUMBER($E11)),$E11,N11/Advance!$I$53) -> -
C12: Drilling consumables, subtotal | K12: =SUM(K8:K11) -> 293 | M12: =SUM(M8:M11) -> 0.21296421 | N12: =IF(COUNT(N8:N11)=0,"x",SUM(N8:N11)) -> x | O12: =IF(COUNT(O8:O11)=0,"x",SUM(O8:O11)) -> x
C14: SHEET TOTAL | N14: =IF(COUNT(N12)=0,"x",SUM(N12)) -> x | O14: =IF(COUNT(O12)=0,"x",SUM(O12)) -> x
C16: Key
C17: x | D17: No unit price in the source data.
C18: - | D18: Same item as the face drill uses. Counted once, on sheet C.

Sheet B_Ground_Support
B2: SHEET B GROUND SUPPORT, BOLTING AND MESHING
B3: Installation of primary ground support: bolts, bearing plates and mesh.
B4: Quantities are measured consumption. Cost = quantity x unit cost. All costs in United States dollars.
B6: Item code | C6: Description | D6: Unit | E6: Unit cost (US$) | G6: May (units) | H6: June (units) | I6: July (units) | J6: August (units) | K6: Total (units) | M6: Units per metre | N6: Total cost (US$), period | O6: Cost per metre (US$/m), period
B7: Bolts
B8: FB39090GWA | C8: Friction bolt 39 x 900 galvanised | D8: each | E8: =Inputs!$E$12 -> 7.3844946 | G8: =MAX(0,Consumption_PL!I12) -> 183 | H8: =MAX(0,Consumption_PL!M12) -> 177 | I8: =MAX(0,Consumption_PL!Q12) -> 0 | J8: =MAX(0,Consumption_PL!U12) -> 80 | K8: =SUM(G8:J8) -> 440 | M8: =IF(Advance!$I$53=0,0,K8/Advance!$I$53) -> 0.31980974 | N8: =IF(NOT(ISNUMBER($E8)),$E8,K8*$E8) -> 3249.1776 | O8: =IF(NOT(ISNUMBER($E8)),$E8,N8/Advance!$I$53) -> 2.3616333
B9: FB47090GWA | C9: Friction bolt 47 x 900 galvanised | D9: each | E9: =Inputs!$E$13 -> 12.897225 | G9: =MAX(0,Consumption_PL!I13) -> 300 | H9: =MAX(0,Consumption_PL!M13) -> 529 | I9: =MAX(0,Consumption_PL!Q13) -> 401 | J9: =MAX(0,Consumption_PL!U13) -> 320 | K9: =SUM(G9:J9) -> 1550 | M9: =IF(Advance!$I$53=0,0,K9/Advance!$I$53) -> 1.1266025 | N9: =IF(NOT(ISNUMBER($E9)),$E9,K9*$E9) -> 19990.699 | O9: =IF(NOT(ISNUMBER($E9)),$E9,N9/Advance!$I$53) -> 14.530046
B10: FB47-2400G | C10: Friction bolt 47 x 2400 galvanised | D10: each | E10: =Inputs!$E$14 -> 15.931125 | G10: =MAX(0,Consumption_PL!I14) -> 743 | H10: =MAX(0,Consumption_PL!M14) -> 949 | I10: =MAX(0,Consumption_PL!Q14) -> 2159 | J10: =MAX(0,Consumption_PL!U14) -> 2286 | K10: =SUM(G10:J10) -> 6137 | M10: =IF(Advance!$I$53=0,0,K10/Advance!$I$53) -> 4.4606191 | N10: =IF(NOT(ISNUMBER($E10)),$E10,K10*$E10) -> 97769.314 | O10: =IF(NOT(ISNUMBER($E10)),$E10,N10/Advance!$I$53) -> 71.06268
B11: BMG2024S | C11: MD bolt 2.4 m galvanised | D11: each | E11: =Inputs!$E$15 -> 65.878328 | G11: =MAX(0,Consumption_PL!I15) -> 2575 | H11: =MAX(0,Consumption_PL!M15) -> 3674 | I11: =MAX(0,Consumption_PL!Q15) -> 4163 | J11: =MAX(0,Consumption_PL!U15) -> 3319 | K11: =SUM(G11:J11) -> 13731 | M11: =IF(Advance!$I$53=0,0,K11/Advance!$I$53) -> 9.9802445 | N11: =IF(NOT(ISNUMBER($E11)),$E11,K11*$E11) -> 904575.32 | O11: =IF(NOT(ISNUMBER($E11)),$E11,N11/Advance!$I$53) -> 657.48182
C12: Bolts, subtotal | K12: =SUM(K8:K11) -> 21858 | M12: =SUM(M8:M11) -> 15.887276 | N12: =IF(COUNT(N8:N11)=0,"x",SUM(N8:N11)) -> 1025584.5 | O12: =IF(COUNT(O8:O11)=0,"x",SUM(O8:O11)) -> 745.43617
B14: Bearing plates
B15: D1515441GWA | C15: Plate dome 150 x 150 x 4, 41H galvanised | D15: each | E15: - | G15: =MAX(0,Consumption_PL!I16) -> 0 | H15: =MAX(0,Consumption_PL!M16) -> 15 | I15: =MAX(0,Consumption_PL!Q16) -> 0 | J15: =MAX(0,Consumption_PL!U16) -> 209 | K15: =SUM(G15:J15) -> 224 | M15: =IF(Advance!$I$53=0,0,K15/Advance!$I$53) -> 0.16281223 | N15: =IF(NOT(ISNUMBER($E15)),$E15,K15*$E15) -> - | O15: =IF(NOT(ISNUMBER($E15)),$E15,N15/Advance!$I$53) -> -
B16: CBP328154-47G | C16: D/Fly plate 300 x 280 galvanised | D16: each | E16: - | G16: =MAX(0,Consumption_PL!I17) -> 640 | H16: =MAX(0,Consumption_PL!M17) -> 1054 | I16: =MAX(0,Consumption_PL!Q17) -> 2602 | J16: =MAX(0,Consumption_PL!U17) -> 3230 | K16: =SUM(G16:J16) -> 7526 | M16: =IF(Advance!$I$53=0,0,K16/Advance!$I$53) -> 5.4702003 | N16: =IF(NOT(ISNUMBER($E16)),$E16,K16*$E16) -> - | O16: =IF(NOT(ISNUMBER($E16)),$E16,N16/Advance!$I$53) -> -
B17: BPG3002806 | C17: Combi plate 300 x 280 x 6 mm galvanised | D17: each | E17: - | G17: =MAX(0,Consumption_PL!I18) -> 2740 | H17: =MAX(0,Consumption_PL!M18) -> 2730 | I17: =MAX(0,Consumption_PL!Q18) -> 4490 | J17: =MAX(0,Consumption_PL!U18) -> 4398 | K17: =SUM(G17:J17) -> 14358 | M17: =IF(Advance!$I$53=0,0,K17/Advance!$I$53) -> 10.435973 | N17: =IF(NOT(ISNUMBER($E17)),$E17,K17*$E17) -> - | O17: =IF(NOT(ISNUMBER($E17)),$E17,N17/Advance!$I$53) -> -
C18: Bearing plates, subtotal | K18: =SUM(K15:K17) -> 22108 | M18: =SUM(M15:M17) -> 16.068986 | N18: =IF(COUNT(N15:N17)=0,"x",SUM(N15:N17)) -> x | O18: =IF(COUNT(O15:O17)=0,"x",SUM(O15:O17)) -> x
B20: Mesh
B21: MESH2.4X4.5 | C21: Mesh 2.40 x 4.50 m galvanised | D21: sheet | E21: =Inputs!$E$17 -> 82.485411 | G21: =MAX(0,Consumption_PL!I19) -> 2291 | H21: =MAX(0,Consumption_PL!M19) -> 408 | I21: =MAX(0,Consumption_PL!Q19) -> 821 | J21: =MAX(0,Consumption_PL!U19) -> 769 | K21: =SUM(G21:J21) -> 4289 | M21: =IF(Advance!$I$53=0,0,K21/Advance!$I$53) -> 3.1174181 | N21: =IF(NOT(ISNUMBER($E21)),$E21,K21*$E21) -> 353779.93 | O21: =IF(NOT(ISNUMBER($E21)),$E21,N21/Advance!$I$53) -> 257.14152
C22: Mesh, subtotal | K22: =SUM(K21:K21) -> 4289 | M22: =SUM(M21:M21) -> 3.1174181 | N22: =IF(COUNT(N21:N21)=0,"x",SUM(N21:N21)) -> 353779.93 | O22: =IF(COUNT(O21:O21)=0,"x",SUM(O21:O21)) -> 257.14152
C24: SHEET TOTAL | N24: =IF(COUNT(N12,N18,N22)=0,"x",SUM(N12,N18,N22)) -> 1379364.4 | O24: =IF(COUNT(O12,O18,O22)=0,"x",SUM(O12,O18,O22)) -> 1002.5777
C26: Key
C27: - | D27: Plate cost is inside the bolt price, quoted Bolt and Plate.

Sheet C_Face_Drilling
B2: SHEET C DEVELOPMENT DRILLING, FACE DRILL
B3: Face drilling for blast rounds. This sheet carries all shared drill steel.
B4: Quantities are measured consumption. Cost = quantity x unit cost. All costs in United States dollars.
B6: Item code | C6: Description | D6: Unit | E6: Unit cost (US$) | G6: May (units) | H6: June (units) | I6: July (units) | J6: August (units) | K6: Total (units) | M6: Units per metre | N6: Total cost (US$), period | O6: Cost per metre (US$/m), period
B7: Shanks
B8: 7304-7669-01 | C8: Shank T38 RD520/525 D45 L525 | D8: each | E8: =Inputs!$E$43 -> 308.1 | G8: =MAX(0,Consumption_PL!I11) -> 1 | H8: =MAX(0,Consumption_PL!M11) -> 5 | I8: =MAX(0,Consumption_PL!Q11) -> 45 | J8: =MAX(0,Consumption_PL!U11) -> 1 | K8: =SUM(G8:J8) -> 52 | M8: =IF(Advance!$I$53=0,0,K8/Advance!$I$53) -> 0.037795697 | N8: =IF(NOT(ISNUMBER($E8)),$E8,K8*$E8) -> 16021.2 | O8: =IF(NOT(ISNUMBER($E8)),$E8,N8/Advance!$I$53) -> 11.644854
B9: 7305-7669-01 | C9: Shank T45 RD520/525 D45 L525 | D9: each | E9: =Inputs!$E$44 -> 5568.55 | G9: =MAX(0,Consumption_PL!I20) -> 8 | H9: =MAX(0,Consumption_PL!M20) -> 19 | I9: =MAX(0,Consumption_PL!Q20) -> 34 | J9: =MAX(0,Consumption_PL!U20) -> 24 | K9: =SUM(G9:J9) -> 85 | M9: =IF(Advance!$I$53=0,0,K9/Advance!$I$53) -> 0.061781427 | N9: =IF(NOT(ISNUMBER($E9)),$E9,K9*$E9) -> 473326.75 | O9: =IF(NOT(ISNUMBER($E9)),$E9,N9/Advance!$I$53) -> 344.03297
C10: Shanks, subtotal | K10: =SUM(K8:K9) -> 137 | M10: =SUM(M8:M9) -> 0.099577124 | N10: =IF(COUNT(N8:N9)=0,"x",SUM(N8:N9)) -> 489347.95 | O10: =IF(COUNT(O8:O9)=0,"x",SUM(O8:O9)) -> 355.67782
B12: Couplings and adaptors
B13: 7335-4401 | C13: Bit adaptor T45F / T38M | D13: each | E13: =Inputs!$E$45 -> 4453.45 | G13: =MAX(0,Consumption_PL!I21) -> 15 | H13: =MAX(0,Consumption_PL!M21) -> 4 | I13: =MAX(0,Consumption_PL!Q21) -> 16 | J13: =MAX(0,Consumption_PL!U21) -> 16 | K13: =SUM(G13:J13) -> 51 | M13: =IF(Advance!$I$53=0,0,K13/Advance!$I$53) -> 0.037068856 | N13: =IF(NOT(ISNUMBER($E13)),$E13,K13*$E13) -> 227125.95 | O13: =IF(NOT(ISNUMBER($E13)),$E13,N13/Advance!$I$53) -> 165.0843
B14: 7314-6261 | C14: Coupling sleeve T45 / T38 | D14: each | E14: =Inputs!$E$46 -> 1925.47 | G14: =MAX(0,Consumption_PL!I22) -> 11 | H14: =MAX(0,Consumption_PL!M22) -> 7 | I14: =MAX(0,Consumption_PL!Q22) -> 14 | J14: =MAX(0,Consumption_PL!U22) -> 20 | K14: =SUM(G14:J14) -> 52 | M14: =IF(Advance!$I$53=0,0,K14/Advance!$I$53) -> 0.037795697 | N14: =IF(NOT(ISNUMBER($E14)),$E14,K14*$E14) -> 100124.44 | O14: =IF(NOT(ISNUMBER($E14)),$E14,N14/Advance!$I$53) -> 72.77448
B15: 7314-3652 | C15: Coupling sleeve T38 / T38 | D15: each | E15: =Inputs!$E$47 -> 69.96 | G15: =MAX(0,Consumption_PL!I23) -> 5 | H15: =MAX(0,Consumption_PL!M23) -> 1 | I15: =MAX(0,Consumption_PL!Q23) -> 3 | J15: =MAX(0,Consumption_PL!U23) -> 0 | K15: =SUM(G15:J15) -> 9 | M15: =IF(Advance!$I$53=0,0,K15/Advance!$I$53) -> 0.0065415629 | N15: =IF(NOT(ISNUMBER($E15)),$E15,K15*$E15) -> 629.64 | O15: =IF(NOT(ISNUMBER($E15)),$E15,N15/Advance!$I$53) -> 0.45764774
C16: Couplings and adaptors, subtotal | K16: =SUM(K13:K15) -> 112 | M16: =SUM(M13:M15) -> 0.081406116 | N16: =IF(COUNT(N13:N15)=0,"x",SUM(N13:N15)) -> 327880.03 | O16: =IF(COUNT(O13:O15)=0,"x",SUM(O13:O15)) -> 238.31643
B18: Bits
B19: 7580-5243A-S70 | C19: A340 43 mm button bit | D19: each | E19: =Inputs!$E$48 -> 66.52 | G19: =MAX(0,Consumption_PL!I9) -> 115 | H19: =MAX(0,Consumption_PL!M9) -> 0 | I19: =MAX(0,Consumption_PL!Q9) -> 10 | J19: =MAX(0,Consumption_PL!U9) -> 0 | K19: =SUM(G19:J19) -> 125 | M19: =IF(Advance!$I$53=0,0,K19/Advance!$I$53) -> 0.09085504 | N19: =IF(NOT(ISNUMBER($E19)),$E19,K19*$E19) -> 8315 | O19: =IF(NOT(ISNUMBER($E19)),$E19,N19/Advance!$I$53) -> 6.0436773
B20: 7580-5345A-R48 | C20: A340 45 mm button bit | D20: each | E20: =Inputs!$E$49 -> 78.93 | G20: =MAX(0,Consumption_PL!I10) -> 72 | H20: =MAX(0,Consumption_PL!M10) -> 0 | I20: =MAX(0,Consumption_PL!Q10) -> 10 | J20: =MAX(0,Consumption_PL!U10) -> 25 | K20: =SUM(G20:J20) -> 107 | M20: =IF(Advance!$I$53=0,0,K20/Advance!$I$53) -> 0.077771915 | N20: =IF(NOT(ISNUMBER($E20)),$E20,K20*$E20) -> 8445.51 | O20: =IF(NOT(ISNUMBER($E20)),$E20,N20/Advance!$I$53) -> 6.1385372
B21: 7580-5148A-S81 | C21: A340 48 mm TC button bit | D21: each | E21: =Inputs!$E$50 -> 108.19 | G21: =MAX(0,Consumption_PL!I24) -> 0 | H21: =MAX(0,Consumption_PL!M24) -> 0 | I21: =MAX(0,Consumption_PL!Q24) -> 0 | J21: =MAX(0,Consumption_PL!U24) -> 35 | K21: =SUM(G21:J21) -> 35 | M21: =IF(Advance!$I$53=0,0,K21/Advance!$I$53) -> 0.025439411 | N21: =IF(NOT(ISNUMBER($E21)),$E21,K21*$E21) -> 3786.65 | O21: =IF(NOT(ISNUMBER($E21)),$E21,N21/Advance!$I$53) -> 2.7522899
B22: 7580-4651A-S70 | C22: A340 51 mm retrac bit | D22: each | E22: =Inputs!$E$51 -> 94.13 | G22: =MAX(0,Consumption_PL!I25) -> 10 | H22: =MAX(0,Consumption_PL!M25) -> 15 | I22: =MAX(0,Consumption_PL!Q25) -> 10 | J22: =MAX(0,Consumption_PL!U25) -> 15 | K22: =SUM(G22:J22) -> 50 | M22: =IF(Advance!$I$53=0,0,K22/Advance!$I$53) -> 0.036342016 | N22: =IF(NOT(ISNUMBER($E22)),$E22,K22*$E22) -> 4706.5 | O22: =IF(NOT(ISNUMBER($E22)),$E22,N22/Advance!$I$53) -> 3.420874
B23: 7580-5602P-S70 | C23: Reaming bit A340 102 mm | D23: each | E23: =Inputs!$E$52 -> 343.33 | G23: =MAX(0,Consumption_PL!I26) -> 14 | H23: =MAX(0,Consumption_PL!M26) -> 2 | I23: =MAX(0,Consumption_PL!Q26) -> 14 | J23: =MAX(0,Consumption_PL!U26) -> 12 | K23: =SUM(G23:J23) -> 42 | M23: =IF(Advance!$I$53=0,0,K23/Advance!$I$53) -> 0.030527294 | N23: =IF(NOT(ISNUMBER($E23)),$E23,K23*$E23) -> 14419.86 | O23: =IF(NOT(ISNUMBER($E23)),$E23,N23/Advance!$I$53) -> 10.480936
B24: 7514-1664-S70 | C24: T38 64 mm button bit | D24: each | E24: =Inputs!$E$53 -> 136.44 | G24: =MAX(0,Consumption_PL!I27) -> 22 | H24: =MAX(0,Consumption_PL!M27) -> 20 | I24: =MAX(0,Consumption_PL!Q27) -> 1 | J24: =MAX(0,Consumption_PL!U27) -> 12 | K24: =SUM(G24:J24) -> 55 | M24: =IF(Advance!$I$53=0,0,K24/Advance!$I$53) -> 0.039976218 | N24: =IF(NOT(ISNUMBER($E24)),$E24,K24*$E24) -> 7504.2 | O24: =IF(NOT(ISNUMBER($E24)),$E24,N24/Advance!$I$53) -> 5.4543552
B25: 7580-6045-F49 | C25: Speedy bit A340 45 mm XT49 | D25: each | E25: =Inputs!$E$54 -> 79.73 | G25: =MAX(0,Consumption_PL!I28) -> 62 | H25: =MAX(0,Consumption_PL!M28) -> 42 | I25: =MAX(0,Consumption_PL!Q28) -> 20 | J25: =MAX(0,Consumption_PL!U28) -> 70 | K25: =SUM(G25:J25) -> 194 | M25: =IF(Advance!$I$53=0,0,K25/Advance!$I$53) -> 0.14100702 | N25: =IF(NOT(ISNUMBER($E25)),$E25,K25*$E25) -> 15467.62 | O25: =IF(NOT(ISNUMBER($E25)),$E25,N25/Advance!$I$53) -> 11.24249
C26: Bits, subtotal | K26: =SUM(K19:K25) -> 608 | M26: =SUM(M19:M25) -> 0.44191892 | N26: =IF(COUNT(N19:N25)=0,"x",SUM(N19:N25)) -> 62645.34 | O26: =IF(COUNT(O19:O25)=0,"x",SUM(O19:O25)) -> 45.533159
B28: Rods
B29: 7324-8037-20 | C29: Drifter rod T38 H35 A340 L=370, drilling steel | D29: each | E29: =Inputs!$E$55 -> 498.85 | G29: =MAX(0,Consumption_PL!I29) -> 1 | H29: =MAX(0,Consumption_PL!M29) -> 0 | I29: =MAX(0,Consumption_PL!Q29) -> 7 | J29: =MAX(0,Consumption_PL!U29) -> 19 | K29: =SUM(G29:J29) -> 27 | M29: =IF(Advance!$I$53=0,0,K29/Advance!$I$53) -> 0.019624689 | N29: =IF(NOT(ISNUMBER($E29)),$E29,K29*$E29) -> 13468.95 | O29: =IF(NOT(ISNUMBER($E29)),$E29,N29/Advance!$I$53) -> 9.789776
B30: 7324-7949-20 | C30: Drifter rod T38 R39 A340 L=491, speed rod | D30: each | E30: =Inputs!$E$56 -> 639 | G30: =MAX(0,Consumption_PL!I30) -> 15 | H30: =MAX(0,Consumption_PL!M30) -> 18 | I30: =MAX(0,Consumption_PL!Q30) -> 16 | J30: =MAX(0,Consumption_PL!U30) -> 24 | K30: =SUM(G30:J30) -> 73 | M30: =IF(Advance!$I$53=0,0,K30/Advance!$I$53) -> 0.053059344 | N30: =IF(NOT(ISNUMBER($E30)),$E30,K30*$E30) -> 46647 | O30: =IF(NOT(ISNUMBER($E30)),$E30,N30/Advance!$I$53) -> 33.904921
B31: 7324-4731-85 | C31: MF rod T38 R39 L=3050 mm | D31: each | E31: =Inputs!$E$57 -> 439.59 | G31: =MAX(0,Consumption_PL!I31) -> 2 | H31: =MAX(0,Consumption_PL!M31) -> 1 | I31: =MAX(0,Consumption_PL!Q31) -> 3 | J31: =MAX(0,Consumption_PL!U31) -> 4 | K31: =SUM(G31:J31) -> 10 | M31: =IF(Advance!$I$53=0,0,K31/Advance!$I$53) -> 0.0072684032 | N31: =IF(NOT(ISNUMBER($E31)),$E31,K31*$E31) -> 4395.9 | O31: =IF(NOT(ISNUMBER($E31)),$E31,N31/Advance!$I$53) -> 3.1951174
B32: 7324-4331C-30 | C32: T38 extension round rod L=3050 mm | D32: each | E32: =Inputs!$E$58 -> 317.43 | G32: =MAX(0,Consumption_PL!I32) -> 15 | H32: =MAX(0,Consumption_PL!M32) -> 12 | I32: =MAX(0,Consumption_PL!Q32) -> 0 | J32: =MAX(0,Consumption_PL!U32) -> 4 | K32: =SUM(G32:J32) -> 31 | M32: =IF(Advance!$I$53=0,0,K32/Advance!$I$53) -> 0.02253205 | N32: =IF(NOT(ISNUMBER($E32)),$E32,K32*$E32) -> 9840.33 | O32: =IF(NOT(ISNUMBER($E32)),$E32,N32/Advance!$I$53) -> 7.1523486
B33: 7324-4309C-30 | C33: Extension rod T38 R39 L=915 mm | D33: each | E33: =Inputs!$E$59 -> 184.75 | G33: =MAX(0,Consumption_PL!I33) -> 0 | H33: =MAX(0,Consumption_PL!M33) -> 4 | I33: =MAX(0,Consumption_PL!Q33) -> 1 | J33: =MAX(0,Consumption_PL!U33) -> 1 | K33: =SUM(G33:J33) -> 6 | M33: =IF(Advance!$I$53=0,0,K33/Advance!$I$53) -> 0.0043610419 | N33: =IF(NOT(ISNUMBER($E33)),$E33,K33*$E33) -> 1108.5 | O33: =IF(NOT(ISNUMBER($E33)),$E33,N33/Advance!$I$53) -> 0.8057025
B34: 7324-4709C-20 | C34: MF rod T38 R39 L=915 mm | D34: each | E34: =Inputs!$E$60 -> 276.63 | G34: =MAX(0,Consumption_PL!I34) -> 0 | H34: =MAX(0,Consumption_PL!M34) -> 1 | I34: =MAX(0,Consumption_PL!Q34) -> 1 | J34: =MAX(0,Consumption_PL!U34) -> 1 | K34: =SUM(G34:J34) -> 3 | M34: =IF(Advance!$I$53=0,0,K34/Advance!$I$53) -> 0.002180521 | N34: =IF(NOT(ISNUMBER($E34)),$E34,K34*$E34) -> 829.89 | O34: =IF(NOT(ISNUMBER($E34)),$E34,N34/Advance!$I$53) -> 0.60319752
C35: Rods, subtotal | K35: =SUM(K29:K34) -> 150 | M35: =SUM(M29:M34) -> 0.10902605 | N35: =IF(COUNT(N29:N34)=0,"x",SUM(N29:N34)) -> 76290.57 | O35: =IF(COUNT(O29:O34)=0,"x",SUM(O29:O34)) -> 55.451063
B37: Centralisers and dollies
B38: M2000354 | C38: Bolting centraliser dia 70 mm front | D38: each | E38: =Inputs!$E$61 -> 45.12 | G38: =MAX(0,Consumption_PL!I35) -> 0 | H38: =MAX(0,Consumption_PL!M35) -> 9 | I38: =MAX(0,Consumption_PL!Q35) -> 12 | J38: =MAX(0,Consumption_PL!U35) -> 4 | K38: =SUM(G38:J38) -> 25 | M38: =IF(Advance!$I$53=0,0,K38/Advance!$I$53) -> 0.018171008 | N38: =IF(NOT(ISNUMBER($E38)),$E38,K38*$E38) -> 1128 | O38: =IF(NOT(ISNUMBER($E38)),$E38,N38/Advance!$I$53) -> 0.81987588
B39: M2000353 | C39: Bolting centraliser dia 70 mm back | D39: each | E39: =Inputs!$E$62 -> 68 | G39: =MAX(0,Consumption_PL!I36) -> 0 | H39: =MAX(0,Consumption_PL!M36) -> 0 | I39: =MAX(0,Consumption_PL!Q36) -> 2 | J39: =MAX(0,Consumption_PL!U36) -> 1 | K39: =SUM(G39:J39) -> 3 | M39: =IF(Advance!$I$53=0,0,K39/Advance!$I$53) -> 0.002180521 | N39: =IF(NOT(ISNUMBER($E39)),$E39,K39*$E39) -> 204 | O39: =IF(NOT(ISNUMBER($E39)),$E39,N39/Advance!$I$53) -> 0.14827543
B40: M33191232 | C40: Boring centraliser dia 48 mm | D40: each | E40: =Inputs!$E$63 -> 61.09 | G40: =MAX(0,Consumption_PL!I37) -> 0 | H40: =MAX(0,Consumption_PL!M37) -> 0 | I40: =MAX(0,Consumption_PL!Q37) -> 4 | J40: =MAX(0,Consumption_PL!U37) -> 2 | K40: =SUM(G40:J40) -> 6 | M40: =IF(Advance!$I$53=0,0,K40/Advance!$I$53) -> 0.0043610419 | N40: =IF(NOT(ISNUMBER($E40)),$E40,K40*$E40) -> 366.54 | O40: =IF(NOT(ISNUMBER($E40)),$E40,N40/Advance!$I$53) -> 0.26641605
B41: 33191231 | C41: Boring centraliser dia 41 mm | D41: each | E41: =Inputs!$E$64 -> 1884.83 | G41: =MAX(0,Consumption_PL!I38) -> 0 | H41: =MAX(0,Consumption_PL!M38) -> 0 | I41: =MAX(0,Consumption_PL!Q38) -> 9 | J41: =MAX(0,Consumption_PL!U38) -> 1 | K41: =SUM(G41:J41) -> 10 | M41: =IF(Advance!$I$53=0,0,K41/Advance!$I$53) -> 0.0072684032 | N41: =IF(NOT(ISNUMBER($E41)),$E41,K41*$E41) -> 18848.3 | O41: =IF(NOT(ISNUMBER($E41)),$E41,N41/Advance!$I$53) -> 13.699704
