Workbook
Name _511.56: 'May_2026 eom ug dev'!#REF!
Name arch_profile: Heading_ids!#REF!
Name arch_profile: Heading_profile!$B$3:$D$35
Name arch_profile: Stripping_cal!#REF!
Name arch_profile: #REF!
Name bolt_per_metre: Heading_ids!#REF!
Name bolt_per_metre: Heading_profile!#REF!
Name bolt_per_metre: Stripping_cal!#REF!
Name bolt_per_metre: #REF!
Name fibre_per_metre: Heading_ids!#REF!
Name fibre_per_metre: Heading_profile!#REF!
Name fibre_per_metre: Stripping_cal!#REF!
Name fibre_per_metre: #REF!
Name gs_01: Heading_ids!#REF!
Name gs_01: Heading_profile!#REF!
Name gs_01: Stripping_cal!#REF!
Name gs_01: #REF!
Name gs_02: Heading_ids!#REF!
Name gs_02: Heading_profile!#REF!
Name gs_02: Stripping_cal!#REF!
Name gs_02: #REF!
Name haul_dist: Heading_ids!#REF!
Name haul_dist: Heading_profile!#REF!
Name haul_dist: Stripping_cal!#REF!
Name haul_dist: #REF!
Name M_ID: [1]Materials!$A$4:$A$77
Name Material_unit_Cost: [2]Materials!$A$4:$I$81
Name Profile: [3]Lookups!$B$3:$B$15
Name Profile: [4]Lookups!$B$3:$B$15
Name raise_profile: Heading_ids!#REF!
Name raise_profile: Heading_profile!$B$45:$C$55
Name raise_profile: Stripping_cal!#REF!
Name raise_profile: #REF!
Name sg: Heading_ids!#REF!
Name sg: Heading_profile!#REF!
Name sg: Stripping_cal!#REF!
Name sg: #REF!
Name split_sets_per_metre: Heading_ids!#REF!
Name split_sets_per_metre: Heading_profile!#REF!
Name split_sets_per_metre: Stripping_cal!#REF!
Name split_sets_per_metre: #REF!
Name sqr_profile: Heading_ids!#REF!
Name sqr_profile: Heading_profile!$F$3:$H$35
Name sqr_profile: Stripping_cal!#REF!
Name sqr_profile: #REF!

Sheet How to use
A1: Instructions for use
A3: 1. Only manually enter data into the yellow coloured cells and on the master data tab!!
A4: 2. Blue coloured cells are a drop down menu. Select an option from the menu
A5: 3. All other cells will automatically populate
A6: 4. DO NOT OVER WRITE THE FORMULAS
A7: 5. The list of headings is populated from the Daily Report spreadsheet Wooly and Mick generate. If there is a heading not on the list, ask and we will put it in
A8: 6. Use one line on the "EOM Summary" sheet for each heading. If there are multiple ground support regimes in the one heading (i.e. we go through a bad patch of ground and upgrade to GS_5), put this on a new line
A9: 7. When using the "Stripping and Fibrecrete" tab, use a different line for each kind of stripping cut. There may be multiple strips on one level i.e. a loading bay and stockpile fillets. Ensure the heading name in Column A is the same, as this drives an auto-sum formula on EOM Summary tab.
A10: 8. If you are unsure, or something isnt working right, ask for help

Sheet Heading_ids
A1: Monthly Development Headings | B1: SIZE ( H x W ) | C1: GRADE | D1: PROFILE | E1: GS Type | F1: COST ACCOUNT | G1: Contract Type Dev | H1: MI NO.
A2: Column7 | B2: Column8 | C2: Column9 | D2: Column10 | E2: Column11 | F2: Column12 | G2: Column6 | H2: Column72
B3: 2 | C3: 3 | D3: 4 | E3: 5 | F3: 6 | G3: 7
A4: SOUTH DECLINE | B4: 5.5mW x 5.8mH - RS | C4: 1:7 Down | D4: FLAT ARCH | E4: GSS_01 | F4: Waste | G4: CAP
A5: NORTH DECLINE | B5: 5.5mW x 5.8mH - RS | C5: 1:8.9 Down | D5: FLAT ARCH | E5: GSS_02 | F5: Waste | G5: CAP
A6: MS_1040_ACC_waste | B6: 5.5mW x 5.8mH - RS | C6: 1:50 UP | D6: FLAT ARCH | E6: GSS_02 | F6: Waste | G6: CAP
A7: MS_1040_ACC_waste | B7: 5.5mW x 5.8mH - RS | C7: 1:30 Down | D7: FLAT ARCH | E7: GSS_02 | F7: Waste | G7: CAP
A8: MS900_ACC_E | B8: 5.5mW x 5.8mH - RS | C8: 1:50 Up | D8: FLAT ARCH | E8: GSS_01 | F8: Waste | G8: CAP
A9: MS900_ACC_E_VD | B9: 5.5mW x 5.5mH - FA | C9: 1:7 Down | D9: Round Shoulders | E9: GSS_01 | F9: Waste | G9: CAP
A10: MS900_DDR_N_waste | B10: 5.5mW x 5.8mH - RS | C10: 1:50 Up | D10: FLAT ARCH | E10: GSS_01 | F10: Waste | G10: CAP
A11: MS900_DDR_N_waste1 | B11: 5.0mW x 5.0mH - RS | C11: 1:50 Up | D11: FLAT ARCH | E11: GSS_01 | F11: ORE | G11: CAP
A12: S900_SMP W | B12: 5.0mW x 5.0mH - RS | C12: 1:6 Down | D12: FLAT ARCH | E12: GSS_01 | F12: Waste | G12: CAP
A13: S890_SP_W | B13: 5.5mW x 5.8mH - RS | C13: 1:7 Down | D13: FLAT ARCH | E13: GSS_01 | F13: Waste | G13: CAP
A14: MS_1040_ACC_OD | B14: 5.5mW x 5.8mH - RS | C14: 1:50 Up | D14: FLAT ARCH | E14: GSS_02 | F14: ORE | G14: CAP
A15: MS900_DDR_N_OD | B15: 5.0mW x 5.0mH - RS | C15: 1:50 Up | D15: FLAT ARCH | E15: GSS_01 | F15: ORE | G15: CAP

Sheet Sheet2
E11: 1105_HWDW | F11: L4_1105_HWD_W | H11: 1515_DECLINE | I11: L1_1515____DEC__
E12: 1105_715 | F12: L4_1105_715_DDR_N | H12: 1515_SUMP | I12: L1_1515_SMP
E13: 1355_565 | F13: L4_1355_565__DDR_N | H13: 1530_ESC_N | I13: L1_1530_ESC_N
E14: 1355_685_W | F14: L4_1355_685__DDR_W | H14: 1530_ESC_E | I14: L1_1530_ESC_E
E15: 1355_745 | F15: L4_1355_745__DDR_N | H15: 1530_HWD_N | I15: L1_1530____HWD_N
E16: 1405_745 | F16: L4_1405_745__DDR_N | H16: 1530_HWD_S | I16: L1_1530____HWD_S
E17: 1495_SP | F17: L1_1495_SP | H17: 1530_SUB | I17: L1_1530_SUB
E18: 1495_SUMP | F18: L1_1495_SMP | H18: 1530_060 | I18: L1_1530_060_DDR_W
E19: 1555_760_SLT_E | F19: L4_1555_760A_SLT_E | H19: 1580_HWDN | I19: L1_1580_HWD_N
E20: 1515_DEC | F20: L1_1515____DEC__ | H20: 1580_SP | I20: L1_1580_SPB
E21: 1530_PDR | F21: L1_1530_PDR_E | H21: 1580_150 | I21: L1_1580_150__DDR_W
E22: 1530_HWDS | F22: L1_1530____HWD_S | H22: 1630_120 | I22: L1_1630_120__DDR_W
... E29: 1705_950_E (5.0 X 5.0) | F29: L4_1705_950__DDR_E | H29: 1800_165 | I29: L1_1800_165_DDR_N
E30: 1705_950_E (5.5 X 5.5) | F30: L4_1705_950__DDR_E
E31: 1705_970_N | F31: L4_1705_970__DDR_N | H31: 1255_655_N | I31: L4_1255_655_DDR_N
E32: 1745_410_SLT_NW | F32: L2_1745_410B_SLT_NW | H32: 1355_565_N | I32: L4_1355_565__DDR_N
E33: 1745_410_SLT_SE | F33: L2_1745_410B_SLT_SE | H33: 1355_595 | I33: L4_1355_595_DDR_N
E34: 1800_315_W_A | F34: L1_1800_315_DDR_W | H34: 1355_685_SLT_E | I34: L4_1355_685_SLT_E
E35: 1355 745 PASTE | F35: L4_1355_745_FDO | H35: 1355_685_SLT_W | I35: L4_1355_685_SLT_W
E36: 1495 SP TPB | F36: L1_1495 SP TPB | H36: 1355_835 | I36: L4_1355_835__DDR_N
E37: 1405_745_STRIP | F37: L4_1405_745_STRIP | H37: 1405_745 | I37: L4_1405_745__DDR_N
E38: 1605_760_STRIP | F38: L4_1605_760_STRIP | H38: 1655 950 | I38: L4_1655_950__DDR_N
E39: 1705_805_STRIP | F39: L4_1705_805_STRIP | H39: 1705_775_SLT_W | I39: L4_1705_775_SLT_W
H40: 1705 950 | I40: L4_1705_950__DDR_E
E41: 1555_760_PASTE | F41: L4_1555_760_FDO | H41: 1755 950 E | I41: L4_1755_950__DDR_E
E42: 1605_620_PASTE | F42: L4_1605_620_FDO | H42: 1755 970 E | I42: L4_1755_970__DDR_E
E43: 1605_640_PASTE | F43: L4_1605_640_FDO
E44: 1605_760_PASTE | F44: L4_1605_760_FDO
E45: 1800_315_PASTE | F45: L1_1800_315_FDO

Sheet Sheet3
E7: 1405_745 | G7: L4_1405_745__DDR_N
E8: 1455_670_SLT_W | G8: L4_1455_670_SLT_W
E9: 1455_670_SLT_E | G9: L4_1455_670_SLT_E
E10: 1505_850_SLT_W | G10: L4_1505_850_SLT_W
E11: 1505_850_EXT_N | G11: L4_1505_850_SLT_E
E12: 1555_700_SLT_W | G12: L4_1555_700_SLT_W
E13: 1515_DEC | G13: L1_1515____DEC__
E14: 1530_HWDS | G14: L1_1530____HWD_S | U14: L4_1455_670_SLT_W
E15: 1530_HWDN | G15: L1_1530____HWD_N | U15: L4_1455_670_SLT_E
E16: 1530_SUB | G16: L1_1530____SUB_S | U16: L4_1505_850_SLT_E
E17: 1530_060 | G17: L1_1530_060__DDR_W | U17: L4_1505_850_SLT_W
E18: 1530_090 | G18: L1_1530_090 | U18: L4_1555_700_SLT_E
E19: 1580_SPB | G19: L1_1580____SPB | U19: L4_1555_700_SLT_W
E20: 1630_210 | G20: L1_1630_210 | U20: L1_1530_120
E21: 1630_PDR | G21: L1_1630_PDR | U21: L1_1630_210
E22: 1630_HWDN | G22: L1_1630____HWD_N | U22: L1_1630_PDR
E23: 1655_950_E | G23: L4_1655_950__DDR_E_waste | U23: L1_1800_165_N
E24: 1680_165_N | G24: L1_1680_165__DDR_N | U24: L1_1800_165_S
E25: 1680_165_S | G25: L1_1680_165__DDR_S
E26: 1705_805_SLT_W | G26: L4_1705_805_SLT_W
E27: 1800_165_N | G27: L1_1800_165_N
E28: 1800_165_S | G28: L1_1800_165_S
E29: 1850_315 | G29: L1_1850_315
E30: 1850_330 | G30: L1_1850_330
E31: 1355_745_FDO | G31: L4_1355_745_FDO
E32: 1505_850_FDO | G32: L4_1505_850_FDO
E33: 1555_700_FDO | G33: L4_1555_700_FDO
E34: 1555_850_RHINO_STRIP | G34: L4_1555_850_RHINO_STRIP
E35: 1605_700_RHINO_STRIP | G35: L4_1605_700_RHINO_STRIP
E36: 1705_805_SLT_W_FDO | G36: L4_1705_805_SLT_W_FDO
... E38: 1800_315_FDO | G38: L4_1800_315_FDO

Sheet May_2026 eom ug dev
E2: Byrnecut Development Payment EOM NAVACHAB GOLD MINE
W3: REPORT TYPE: | AB3: Byrnecut Development Payment EOM
W4: REPORT START DATE: | AB4: 46140
W5: REPORT END DATE: | AB5: 46171
W6: AUTHOR: | AB6: Luise Uutoni
W7: PUBLISHED: | AB7: 46171
C8: Heading name | D8: Heading Dimensions | E8: Material | F8: GS Type | G8: Cap/Op | H8: Profile (m²) | I8: EOM Advance | J8: Payment Meters | K8: Design Meters | L8: Stripping (m³) | M8: Design m³ | N8: Actual m³ | O8: UnderBreak | P8: OverBreak | Q8: Design Tonnes | R8: Actual Tonnes | S8: Overbreak Allowance | T8: Equiv. Meters | U8: 0.1 | V8: Design+10% | W8: Claimed Tonnes | X8: Haulage Dist. | Y8: Pay Volume | Z8: Pay Tonnes | AA8: Tkm | AB8: Comments
Q9: (%) | R9: (%) | T9: (%) | U9: (%) | V9: (%) | W9: (%)
C10: SOUTH DECLINE | D10: =IF(C10="",0,VLOOKUP(C10,Heading_ids!$A$4:$H$46,2,FALSE)) -> 5.5mW x 5.8mH - RS | E10: =IF(C10="",0,VLOOKUP(C10,Heading_ids!$A$4:$G$46,6,FALSE)) -> Waste | F10: =IF(C10="",0,VLOOKUP(C10,Heading_ids!$A$4:$G$46,5,FALSE)) -> GSS_01 | G10: =IF(C10="",0,VLOOKUP(C10,Heading_ids!$A$4:$G$46,7,FALSE)) -> CAP | H10: =IF(D10="",0,VLOOKUP(D10,Heading_profile!arch_profile,3,FALSE)) -> 31.12 | I10: 75.154 | J10: 75.154 | K10: =I10 -> 75.154 | L10: =IFERROR(IF(E10="waste",VLOOKUP(C10,Stripping!$A$9:$I$42,9,FALSE),0),0) -> 180 | M10: =(K10*H10)+L10 -> 2518.7925 | N10: =IFERROR(IF(C10="",0,VLOOKUP(C10,Input!$C$5:$D$53,2,FALSE)),0) -> 2855.4 | O10: =+Input!I5 -> -0.05194667 | P10: =+Input!H5 -> 0.11253671 | Q10: =M10*2.7 -> 6800.7397 | R10: =N10*2.7 -> 7709.58 | S10: 0.1 | U10: =+S10*Q10 -> 680.07397 | V10: =+U10+Q10 -> 7480.8137 | W10: =MIN(V10,R10) -> 7480.8137 | X10: 0.391589 | Y10: =+N10 -> 2855.4 | Z10: =+Y10*2.7 -> 7709.58 | AA10: =+Z10*X10 -> 3018.9867
C11: NORTH DECLINE | D11: =IF(C11="",0,VLOOKUP(C11,Heading_ids!$A$4:$H$46,2,FALSE)) -> 5.5mW x 5.8mH - RS | E11: =IF(C11="",0,VLOOKUP(C11,Heading_ids!$A$4:$G$46,6,FALSE)) -> Waste | F11: =IF(C11="",0,VLOOKUP(C11,Heading_ids!$A$4:$G$46,5,FALSE)) -> GSS_02 | G11: =IF(C11="",0,VLOOKUP(C11,Heading_ids!$A$4:$G$46,7,FALSE)) -> CAP | H11: =IF(D11="",0,VLOOKUP(D11,Heading_profile!arch_profile,3,FALSE)) -> 31.12 | I11: 55.882 | J11: 55.882 | K11: =I11 -> 55.882 | L11: =IFERROR(IF(E11="waste",VLOOKUP(C11,Stripping!$A$9:$I$42,9,FALSE),0),0) -> 180 | M11: =(K11*H11)+L11 -> 1919.0478 | N11: =IFERROR(IF(C11="",0,VLOOKUP(C11,Input!$C$5:$D$53,2,FALSE)),0) -> 2155 | O11: =+Input!I6 -> -0.031481503 | P11: =+Input!H6 -> 0.11890415 | Q11: =M11*2.7 -> 5181.4292 | R11: =N11*2.7 -> 5818.5 | S11: 0.1 | U11: =+S11*Q11 -> 518.14292 | V11: =+U11+Q11 -> 5699.5721 | W11: =MIN(V11,R11) -> 5699.5721 | X11: 0 | Y11: =+N11 -> 2155 | Z11: =+Y11*2.7 -> 5818.5 | AA11: =+Z11*X11 -> 0
C12: MS_1040_ACC_waste | D12: 5.5mW x 5.8mH - RS | E12: =IF(C12="",0,VLOOKUP(C12,Heading_ids!$A$4:$G$46,6,FALSE)) -> Waste | F12: =IF(C12="",0,VLOOKUP(C12,Heading_ids!$A$4:$G$46,5,FALSE)) -> GSS_02 | G12: =IF(C12="",0,VLOOKUP(C12,Heading_ids!$A$4:$G$46,7,FALSE)) -> CAP | H12: =IF(D12="",0,VLOOKUP(D12,Heading_profile!arch_profile,3,FALSE)) -> 31.12 | I12: 6 | J12: 6 | K12: =I12 -> 6 | L12: =IFERROR(IF(E12="waste",VLOOKUP(C12,Stripping!$A$9:$I$42,9,FALSE),0),0) -> 146.7 | M12: =(K12*H12)+L12 -> 333.42 | N12: =IFERROR(IF(C12="",0,VLOOKUP(C12,Input!$C$5:$D$53,2,FALSE)),0) -> 314.1 | O12: =+Input!I7 -> -0.037596401 | P12: =+Input!H7 -> 0.17245073 | Q12: =M12*2.7 -> 900.234 | R12: =N12*2.7 -> 848.07 | S12: 0.1 | U12: =+S12*Q12 -> 90.0234 | V12: =+U12+Q12 -> 990.2574 | W12: =MIN(V12,R12) -> 848.07 | X12: 0 | Y12: =+N12 -> 314.1 | Z12: =+Y12*2.7 -> 848.07 | AA12: =+Z12*X12 -> 0
C13: MS900_ACC_E | D13: =IF(C13="",0,VLOOKUP(C13,Heading_ids!$A$4:$H$46,2,FALSE)) -> 5.5mW x 5.8mH - RS | E13: =IF(C13="",0,VLOOKUP(C13,Heading_ids!$A$4:$G$46,6,FALSE)) -> Waste | F13: =IF(C13="",0,VLOOKUP(C13,Heading_ids!$A$4:$G$46,5,FALSE)) -> GSS_01 | G13: =IF(C13="",0,VLOOKUP(C13,Heading_ids!$A$4:$G$46,7,FALSE)) -> CAP | H13: =IF(D13="",0,VLOOKUP(D13,Heading_profile!arch_profile,3,FALSE)) -> 31.12 | I13: 17.508 | J13: 17.508 | K13: =I13 -> 17.508 | L13: =IFERROR(IF(E13="waste",VLOOKUP(C13,Stripping!$A$9:$I$42,9,FALSE),0),0) -> 0 | M13: =(K13*H13)+L13 -> 544.84896 | N13: =IFERROR(IF(C13="",0,VLOOKUP(C13,Input!$C$5:$D$53,2,FALSE)),0) -> 591.8 | O13: =+Input!I8 -> -0.059555881 | P13: =+Input!H8 -> 0.10810335 | Q13: =M13*2.7 -> 1471.0922 | R13: =N13*2.7 -> 1597.86 | S13: 0.1 | U13: =+S13*Q13 -> 147.10922 | V13: =+U13+Q13 -> 1618.2014 | W13: =MIN(V13,R13) -> 1597.86 | X13: 0.391589 | Y13: =+N13 -> 591.8 | Z13: =+Y13*2.7 -> 1597.86 | AA13: =+Z13*X13 -> 625.7044
C14: MS_1040_ACC_waste | D14: =IF(C14="",0,VLOOKUP(C14,Heading_ids!$A$4:$H$46,2,FALSE)) -> 5.5mW x 5.8mH - RS | E14: =IF(C14="",0,VLOOKUP(C14,Heading_ids!$A$4:$G$46,6,FALSE)) -> Waste | F14: GSS_01 | G14: =IF(C14="",0,VLOOKUP(C14,Heading_ids!$A$4:$G$46,7,FALSE)) -> CAP | H14: =IF(D14="",0,VLOOKUP(D14,Heading_profile!arch_profile,3,FALSE)) -> 31.12 | I14: 4.278 | J14: 4.278 | K14: =I14 -> 4.278 | L14: =IFERROR(IF(E14="waste",VLOOKUP(C14,Stripping!$A$9:$I$42,9,FALSE),0),0) -> 146.7 | M14: =(K14*H14)+L14 -> 279.83136 | N14: =IFERROR(IF(C14="",0,VLOOKUP(C14,Input!$C$5:$D$53,2,FALSE)),0) -> 314.1 | O14: =+Input!I9 -> -0.096381198 | P14: =+Input!H9 -> 0.19379356 | Q14: =M14*2.7 -> 755.54467 | R14: =N14*2.7 -> 848.07 | S14: 0.1 | U14: =+S14*Q14 -> 75.554467 | V14: =+U14+Q14 -> 831.09914 | W14: =MIN(V14,R14) -> 831.09914 | X14: 0 | Y14: =+N14 -> 314.1 | Z14: =+Y14*2.7 -> 848.07 | AA14: =+Z14*X14 -> 0
C15: MS900_DDR_N_waste | D15: =IF(C15="",0,VLOOKUP(C15,Heading_ids!$A$4:$H$46,2,FALSE)) -> 5.5mW x 5.8mH - RS | E15: =IF(C15="",0,VLOOKUP(C15,Heading_ids!$A$4:$G$46,6,FALSE)) -> Waste | F15: =IF(C15="",0,VLOOKUP(C15,Heading_ids!$A$4:$G$46,5,FALSE)) -> GSS_01 | G15: =IF(C15="",0,VLOOKUP(C15,Heading_ids!$A$4:$G$46,7,FALSE)) -> CAP | H15: =IF(D15="",0,VLOOKUP(D15,Heading_profile!arch_profile,3,FALSE)) -> 31.12 | I15: 22.683 | J15: =I15 -> 22.683 | K15: =I15 -> 22.683 | L15: =IFERROR(IF(E15="waste",VLOOKUP(C15,Stripping!$A$9:$I$42,9,FALSE),0),0) -> 0 | M15: =(K15*H15)+L15 -> 705.89496 | N15: =IFERROR(IF(C15="",0,VLOOKUP(C15,Input!$C$5:$D$53,2,FALSE)),0) -> 858.3 | O15: =+Input!I10 -> -0.011042663 | P15: =+Input!H10 -> 0.18019678 | Q15: =M15*2.7 -> 1905.9164 | R15: =N15*2.7 -> 2317.41 | S15: 0.1 | U15: =+S15*Q15 -> 190.59164 | V15: =+U15+Q15 -> 2096.508 | W15: =MIN(V15,R15) -> 2096.508 | X15: 0.391589 | Y15: =+N15 -> 858.3 | Z15: =+Y15*2.7 -> 2317.41 | AA15: =+Z15*X15 -> 907.47226
C16: MS900_DDR_N_waste1 | D16: =IF(C16="",0,VLOOKUP(C16,Heading_ids!$A$4:$H$46,2,FALSE)) -> 5.0mW x 5.0mH - RS | E16: Waste | F16: =IF(C16="",0,VLOOKUP(C16,Heading_ids!$A$4:$G$46,5,FALSE)) -> GSS_01 | G16: =IF(C16="",0,VLOOKUP(C16,Heading_ids!$A$4:$G$46,7,FALSE)) -> CAP | H16: =IF(D16="",0,VLOOKUP(D16,Heading_profile!arch_profile,3,FALSE)) -> 24.519 | I16: 16.102 | J16: =I16 -> 16.102 | K16: =I16 -> 16.102 | L16: =IFERROR(IF(E16="waste",VLOOKUP(C16,Stripping!$A$9:$I$42,9,FALSE),0),0) -> 0 | M16: =(K16*H16)+L16 -> 394.80494 | N16: =IFERROR(IF(C16="",0,VLOOKUP(C16,Input!$C$5:$D$53,2,FALSE)),0) -> 464.3 | O16: =+Input!I11 -> 0.042569823 | P16: =+Input!H11 -> 0.052849162 | Q16: =M16*2.7 -> 1065.9733 | R16: =N16*2.7 -> 1253.61 | S16: 0.1 | U16: =+S16*Q16 -> 106.59733 | V16: =+U16+Q16 -> 1172.5707 | W16: =MIN(V16,R16) -> 1172.5707 | X16: 0.391589 | Y16: =+N16 -> 464.3 | Z16: =+Y16*2.7 -> 1253.61 | AA16: =+Z16*X16 -> 490.89989
C17: S890_SP_W | D17: 5.5mW x 5.8mH - RS | E17: =IF(C17="",0,VLOOKUP(C17,Heading_ids!$A$4:$G$46,6,FALSE)) -> Waste | F17: =IF(C17="",0,VLOOKUP(C17,Heading_ids!$A$4:$G$46,5,FALSE)) -> GSS_01 | G17: =IF(C17="",0,VLOOKUP(C17,Heading_ids!$A$4:$G$46,7,FALSE)) -> CAP | H17: =IF(D17="",0,VLOOKUP(D17,Heading_profile!arch_profile,3,FALSE)) -> 31.12 | I17: 24.029 | J17: 24.029 | K17: =I17 -> 24.029 | L17: =IFERROR(IF(E17="waste",VLOOKUP(C17,Stripping!$A$9:$I$42,9,FALSE),0),0) -> 109.3 | M17: =(K17*H17)+L17 -> 857.08248 | N17: =IFERROR(IF(C17="",0,VLOOKUP(C17,Input!$C$5:$D$53,2,FALSE)),0) -> 992.25362 | O17: =+Input!I12 -> -0.0032233832 | P17: =+Input!H12 -> 0.084381961 | Q17: =M17*2.7 -> 2314.1227 | R17: =N17*2.7 -> 2679.0848 | S17: 0.1 | U17: =+S17*Q17 -> 231.41227 | V17: =+U17+Q17 -> 2545.535 | W17: =MIN(V17,R17) -> 2545.535 | X17: 0.391589 | Y17: =+N17 -> 992.25362 | Z17: =+Y17*2.7 -> 2679.0848 | AA17: =+Z17*X17 -> 1049.1001
C18: S900_SMP W | D18: =IF(C18="",0,VLOOKUP(C18,Heading_ids!$A$4:$H$46,2,FALSE)) -> 5.0mW x 5.0mH - RS | E18: =IF(C18="",0,VLOOKUP(C18,Heading_ids!$A$4:$G$46,6,FALSE)) -> Waste | F18: =IF(C18="",0,VLOOKUP(C18,Heading_ids!$A$4:$G$46,5,FALSE)) -> GSS_01 | G18: =IF(C18="",0,VLOOKUP(C18,Heading_ids!$A$4:$G$46,7,FALSE)) -> CAP | H18: =IF(D18="",0,VLOOKUP(D18,Heading_profile!arch_profile,3,FALSE)) -> 24.519 | I18: 5 | J18: =I18 -> 5 | K18: =I18 -> 5 | L18: =IFERROR(IF(E18="waste",VLOOKUP(C18,Stripping!$A$9:$I$42,9,FALSE),0),0) -> 0 | M18: =(K18*H18)+L18 -> 122.595 | N18: =IFERROR(IF(C18="",0,VLOOKUP(C18,Input!$C$5:$D$53,2,FALSE)),0) -> 151.6 | O18: =+Input!I13 -> -0.19869707 | P18: =+Input!H13 -> 0.21091205 | Q18: =M18*2.7 -> 331.0065 | R18: =N18*2.7 -> 409.32 | S18: 0.1 | U18: =+S18*Q18 -> 33.10065 | V18: =+U18+Q18 -> 364.10715 | W18: =MIN(V18,R18) -> 364.10715 | X18: 0.391589 | Y18: =+N18 -> 151.6 | Z18: =+Y18*2.7 -> 409.32 | AA18: =+Z18*X18 -> 160.28521
C19: MS_1040_ACC_OD | D19: =IF(C19="",0,VLOOKUP(C19,Heading_ids!$A$4:$H$46,2,FALSE)) -> 5.5mW x 5.8mH - RS | E19: =IF(C19="",0,VLOOKUP(C19,Heading_ids!$A$4:$G$46,6,FALSE)) -> ORE | F19: =IF(C19="",0,VLOOKUP(C19,Heading_ids!$A$4:$G$46,5,FALSE)) -> GSS_02 | G19: =IF(C19="",0,VLOOKUP(C19,Heading_ids!$A$4:$G$46,7,FALSE)) -> CAP | H19: =IF(D19="",0,VLOOKUP(D19,Heading_profile!arch_profile,3,FALSE)) -> 31.12 | I19: 16.9 | J19: 16.9 | K19: =I19 -> 16.9 | L19: =IFERROR(IF(E19="waste",VLOOKUP(C19,Stripping!$A$9:$I$42,9,FALSE),0),0) -> 0 | M19: =(K19*H19)+L19 -> 525.928 | N19: =IFERROR(IF(C19="",0,VLOOKUP(C19,Input!$C$5:$D$53,2,FALSE)),0) -> 574.4 | O19: =+Input!I14 -> -0.03178339 | P19: =+Input!H14 -> 0.092120472 | Q19: =M19*2.86 -> 1504.1541 | R19: =N19*2.86 -> 1642.784 | S19: 0.1 | U19: =+S19*Q19 -> 150.41541 | V19: =+U19+Q19 -> 1654.5695 | W19: =MIN(V19,R19) -> 1642.784 | X19: 1.043 | Y19: =+N19 -> 574.4 | Z19: =+Y19*2.73 -> 1568.112 | AA19: =+Z19*X19 -> 1635.5408
C20: MS900_DDR_N_OD | D20: =IF(C20="",0,VLOOKUP(C20,Heading_ids!$A$4:$H$46,2,FALSE)) -> 5.0mW x 5.0mH - RS | E20: =IF(C20="",0,VLOOKUP(C20,Heading_ids!$A$4:$G$46,6,FALSE)) -> ORE | F20: =IF(C20="",0,VLOOKUP(C20,Heading_ids!$A$4:$G$46,5,FALSE)) -> GSS_01 | G20: =IF(C20="",0,VLOOKUP(C20,Heading_ids!$A$4:$G$46,7,FALSE)) -> CAP | H20: =IF(D20="",0,VLOOKUP(D20,Heading_profile!arch_profile,3,FALSE)) -> 24.519 | I20: 26.9 | J20: 26.9 | K20: =I20 -> 26.9 | L20: =IFERROR(IF(E20="waste",VLOOKUP(C20,Stripping!$A$9:$I$42,9,FALSE),0),0) -> 0 | M20: =(K20*H20)+L20 -> 659.5611 | N20: =IFERROR(IF(C20="",0,VLOOKUP(C20,Input!$C$5:$D$53,2,FALSE)),0) -> 856.4 | O20: =+Input!I15 -> 0.079168046 | P20: =+Input!H15 -> 0.098972921 | Q20: =M20*2.73 -> 1800.6018 | R20: =N20*2.73 -> 2337.972 | S20: 0.1 | U20: =+S20*Q20 -> 180.06018 | V20: =+U20+Q20 -> 1980.662 | W20: =MIN(V20,R20) -> 1980.662 | X20: 0.391589 | Y20: =+N20 -> 856.4 | Z20: =+Y20*2.86 -> 2449.304 | AA20: =+Z20*X20 -> 959.1205
C22: Waste | E22: Total Waste | I22: =SUM(I10:I18) -> 226.636 | J22: =SUM(J10:J18) -> 226.636 | K22: =SUM(K10:K18) -> 226.636 | L22: =SUM(L10:L21) -> 762.7 | M22: =SUM(M10:M18) -> 7676.318 | N22: =SUM(N10:N18) -> 8696.8536 | O22: =AVERAGE(O10:O21) -> -0.036360935 | P22: =AVERAGE(P10:P21) -> 0.12956562 | Q22: =SUM(Q10:Q18) -> 20726.059 | R22: =SUM(R10:R18) -> 23481.505 | W22: =SUM(W10:W21) -> 26259.582 | X22: =SUM(X10:X21) -> 3.784123 | Y22: =SUM(Y10:Y21) -> 10127.654 | Z22: =SUM(Z10:Z21) -> 27498.921 | AA22: =SUM(AA10:AA21) -> 8847.1099
C23: Ore | E23: Total Ore | I23: =SUM(I19:I20) -> 43.8 | J23: =SUM(J19:J20) -> 43.8 | K23: =SUM(K19:K20) -> 43.8 | L23: =SUM(L10:L21) -> 762.7 | M23: =SUM(M19:M20) -> 1185.4891 | N23: =SUM(N19:N20) -> 1430.8 | O23: =AVERAGE(O10:O21) -> -0.036360935 | P23: =AVERAGE(P10:P21) -> 0.12956562 | Q23: =SUM(Q19:Q20) -> 3304.7559 | R23: =SUM(R19:R20) -> 3980.756
E24: Combined Totals | I24: {=SUM(+I22:I23)} -> 270.436 | J24: {=SUM(+J22:J23)} -> 270.436 | K24: {=SUM(+K22:K23)} -> 270.436 | L24: {=L22:L23} -> 762.7 | M24: {=SUM(+M22:M23)} -> 8861.8071 | N24: {=SUM(+N22:N23)} -> 10127.654 | Q24: {=SUM(+Q22:Q23)} -> 24030.815 | R24: {=SUM(+R22:R23)} -> 27462.261 | W24: =W22 -> 26259.582 | X24: =X22 -> 3.784123 | Y24: =Y22 -> 10127.654 | Z24: =Z22 -> 27498.921 | AA24: =AA22 -> 8847.1099 | AC24: =IF(#REF!>#REF!,#REF!,#REF!) -> #REF!
L25: 762.7 | AC25: =IF(#REF!>#REF!,#REF!,#REF!) -> #REF!
C26: Position | D26: Name | I26: Signature | L26: Date | AC26: =IF(#REF!>#REF!,#REF!,#REF!) -> #REF!
AC27: =IF(#REF!>#REF!,#REF!,#REF!) -> #REF! | AF27: exceljet.net\keyboard shortcuts
C28: Byrnecut Surveyor | AC28: =IF(#REF!>#REF!,#REF!,#REF!) -> #REF!
P29: For EOM Physicals | Q29: Total Actual Waste Tonnes | AB29: =R22 -> 23481.505 | AC29: =IF(#REF!>#REF!,#REF!,#REF!) -> #REF!
C30: Byrnecut Project Engineer | Q30: Total Payment Meters | AB30: =+J24 -> 270.436 | AC30: =IF(#REF!>#REF!,#REF!,#REF!) -> #REF!
Q31: Total Equivalent Meters | AB31: =T22 -> 0 | AC31: =IF(#REF!>#REF!,#REF!,#REF!) -> #REF!
C32: QKR Senior Geologist | Q32: Total Payment Waste Tonnes | AB32: =W22 -> 26259.582 | AC32: =IF(#REF!>#REF!,#REF!,#REF!) -> #REF!
Q33: Underbreak (%) | AB33: =AVERAGE(O22) -> -0.036360935 | AC33: =IF(#REF!>#REF!,#REF!,#REF!) -> #REF!
C34: UG Project Manager | Q34: Overbreak(%) | AB34: =AVERAGE(P22) -> 0.12956562 | AC34: =IF(#REF!>#REF!,#REF!,#REF!) -> #REF!
P35: For EOM Physicals | Q35: Actual Capital Development Metres (m) | AB35: =SUMIF($G$8:$G$25,"CAP",$I$8:$I$25) -> 270.436 | AC35: =IF(#REF!>#REF!,#REF!,#REF!) -> #REF!
C36: Byrnecut Project Manager | P36: For EOM Physicals | Q36: Actual Operating Development Metres (m) | AB36: =SUMIF($G$8:$G$25,"op",$I$8:$I$25) -> 0 | AC36: =IF(#REF!>#REF!,#REF!,#REF!) -> #REF!
Q37: Actual Development Metres (m) | AB37: =AB35+AB36 -> 270.436 | AC37: =IF(#REF!>#REF!,#REF!,#REF!) -> #REF!
P38: For EOM Physicals | Q38: Actual Capital Tonnes (t) | AB38: =SUMIF($G$8:$G$25,"CAP",$R$8:$R$25) -> 27462.261 | AC38: =IF(#REF!>#REF!,#REF!,#REF!) -> #REF!
AI47: FOR CLAIM- PAYABLE
AD49: Finance_Mine_Physicals.xlsx | AJ49: Payable_Mine_Physicals.xlsx
AE50: Dev m | AF50: Eq Dev m | AG50: Tot m | AK50: Dev m | AL50: Eq Dev m | AM50: Tot m
AD51: Cap Waste | AE51: =SUMIFS($I:$I,$E:$E,"Waste",$G:$G,"Cap") -> 226.636 | AF51: =SUMIFS($T:$T,$E:$E,"Waste",$G:$G,"Cap") -> 0 | AG51: =AE51+AF51 -> 226.636 | AJ51: Cap Waste | AK51: =SUMIFS($J:$J,$E:$E,"Waste",$G:$G,"Cap") -> 226.636 | AL51: =SUMIFS($T:$T,$E:$E,"Waste",$G:$G,"Cap") -> 0 | AM51: =AK51+AL51 -> 226.636
...

Sheet Input
A1: 1 | B1: 2 | C1: 3 | D1: 4 | E1: 5 | G1: 6 | H1: 7 | Q1: 8 | R1: 9 | S1: 10 | T1: 11 | U1: 12 | V1: 13 | X1: 14 | Y1: 15 | Z1: 16
C2: Volume from Deswik | U2: Distances from Deswik
A3: Handle | B3: Figure Type | C3: SSIAttribute1 | D3: Volume | E3: Stripping / Fillets | H3: Overbreak (Outside Design) | I3: Underbreak (Inside Design) | J3: RATIO | K3: UNDERBREAK % | L3: OVERBREAK % | M3: WASTE | O3: ORE RATIO | P3: WASTE RATIO | S3: Handle | T3: Figure Type | U3: SSIAttribute1 | V3: *Length | Y3: VAR | Z3: CHECK HEADING-CUT SHEET
C4: Column1 | D4: Column2 | E4: Column3 | F4: Column4 | G4: Column5 | H4: Column6 | I4: Column7 | U4: =C5 -> SOUTH DECLINE | V4: 107.232 | Y4: =+W4-V4 -> -107.232 | Z4: =+V4+W4 -> 107.232
C5: SOUTH DECLINE | D5: 2855.4 | E5: 180 | H5: 0.11253671 | I5: -0.05194667 | U5: =C6 -> NORTH DECLINE | V5: 12.017 | Y5: =+W5-V5 -> -12.017 | Z5: =+V5+W5 -> 12.017
C6: NORTH DECLINE | D6: 2155 | H6: 0.11890415 | I6: -0.031481503 | U6: =C7 -> MS_1040_ACC_waste | V6: 22.685 | Y6: =+W6-V6 -> -22.685 | Z6: =+V6+W6 -> 22.685
C7: MS_1040_ACC_waste | D7: 314.1 | E7: 40.05 | H7: 0.17245073 | I7: -0.037596401 | U7: =C8 -> MS900_ACC_E | V7: 2.5 | Y7: =+W7-V7 -> -2.5 | Z7: =+V7+W7 -> 2.5
C8: MS900_ACC_E | D8: 591.8 | H8: 0.10810335 | I8: -0.059555881 | U8: =C9 -> MS_1040_ACC_waste | V8: 19.628 | Y8: =+W8-V7 -> -2.5 | Z8: =+V7+W8 -> 2.5
C9: MS_1040_ACC_waste | D9: 149.3 | H9: 0.19379356 | I9: -0.096381198 | U9: =C10 -> MS900_DDR_N_waste | V9: 5 | Y9: =+W9-V8 -> -19.628 | Z9: =+V8+W9 -> 19.628
C10: MS900_DDR_N_waste | D10: 858.3 | E10: 40.05 | H10: 0.18019678 | I10: -0.011042663 | U10: =C11 -> MS900_DDR_N_waste1 | V10: 14.242 | Y10: =+W10-V10 -> -14.242
C11: MS900_DDR_N_waste1 | D11: 464.3 | H11: 0.052849162 | I11: 0.042569823 | Y11: =+W11-V11 -> 0 | Z11: =+V11+W11 -> 0
C12: S890_SP_W | D12: 992.25362 | E12: 108 | H12: 0.084381961 | I12: -0.0032233832 | U12: =C13 -> S900_SMP W | Y12: =+W12-V12 -> 0 | Z12: =+V12+W12 -> 0
C13: S900_SMP W | D13: 151.6 | E13: 26.8 | H13: 0.21091205 | I13: -0.19869707 | Y13: =+W13-V13 -> 0 | Z13: =+V13+W13 -> 0
C14: MS_1040_ACC_OD | D14: 574.4 | H14: 0.092120472 | I14: -0.03178339 | Y14: =+W14-V14 -> 0 | Z14: =+V14+W14 -> 0
C15: MS900_DDR_N_OD | D15: 856.4 | H15: 0.098972921 | I15: 0.079168046 | Y15: =+W15-V15 -> 0 | Z15: =+V15+W15 -> 0
Y16: =+W16-V16 -> 0 | Z16: =+V16+W16 -> 0
Y17: =+W17-V17 -> 0
Y18: =+W18-V18 -> 0 | Z18: =+V18+W18 -> 0
Y19: =+W19-V19 -> 0 | Z19: =+V19+W19 -> 0
Y20: =+W20-V20 -> 0 | Z20: =+V20+W20 -> 0
Y22: =+W22-V22 -> 0 | Z22: =+V22+W22 -> 0
Y23: =+W23-V23 -> 0
Y24: =+W24-V24 -> 0
Y25: =+W25-V25 -> 0 | Z25: =+V25+W25 -> 0
Y26: =+W26-V26 -> 0 | Z26: =+V26+W26 -> 0
Y27: =+W27-V27 -> 0 | Z27: =+V27+W27 -> 0
Y28: =+W28-V28 -> 0 | Z28: =+V28+W28 -> 0
Y29: =+W29-V29 -> 0 | Z29: =+V29+W29 -> 0
Y30: =+W30-V30 -> 0 | Z30: =+V30+W30 -> 0
Y31: =+W31-V31 -> 0 | Z31: =+V31+W31 -> 0
Y32: =+W32-V32 -> 0 | Z32: =+V32+W32 -> 0
Y33: =+W33-V33 -> 0 | Z33: =+V33+W33 -> 0

Sheet Sheet5
A1: L1_1680____DEC__ | B1: 61.4 | C1: 53.543
A2: L1_1680____ACC_W | B2: 6.1 | C2: 2.576 | V2: L4_1205_700__DDR_N_waste | W2: 20.431 | AE2: 1205_745_PASTE | AF2: 127
A3: L1_1730____VAD_N | B3: 1.6 | V3: L4_1605_880__DDR_N_waste | W3: 15.511 | AE3: 1255_775_PASTE | AF3: 199
A4: L1_1900_330__DDR_W | B4: 2.7 | V4: L4_1755_950__DDR_E_waste | W4: 27.147 | AE4: 1455_790_PASTE | AF4: 406
A5: L1_1620_BYP__DEC__ | B5: 35.4 | AE5: 1555_670_PASTE | AF5: 165
A6: L1_1620_BYP__VAD__ | B6: 71.1 | AE6: 1605_640_PASTE | AF6: 251
A7: L1_1580_BYP__SP_N3 | B7: 23.8 | AE7: 1655_685_PASTE | AF7: 147
A8: L1_1580_BYP__SP_N4 | B8: 20.1 | AE8: 1655_475_PASTE | AF8: 179
A9: L4_1305_670__OPD_S | B9: 3.5 | AE9: 1655_530_PASTE | AF9: 104
A10: L4_1355_670__OPD_S | B10: 29.4 | AE10: 1705_775_PASTE | AF10: 393
A11: L4_1405_700__OPD_S | B11: 2.7 | AE11: 1705_835_PASTE | AF11: 244
AE12: 1845_440_PASTE | AF12: 230
A14: L4_1755_950__DDR_E | B14: 30.6
A15: L2_1845_455A_SLT_W | B15: 14
A16: L2_1845_455A_SLT_N | B16: 2
A17: L2_1845_455A_SLT_S | B17: 2
A18: L4_1355_685A_SLT_E | B18: 9.9
A19: L4_1205_700__DDR_N | B19: 36
A20: L4_1255_775B_SLT_E | B20: 9.8
A21: L4_1555_670A_SLT_E | B21: 1
A22: L4_1605_880__DDR_N | B22: 49.1
A23: L4_1705_950__DDR_E | B23: 2 | H23: Handle | I23: Figure Type | J23: SSIAttribute1 | K23: length
B24: =SUM(B1:B23) -> 414.2 | H24: 2A5F5 | I24: POLYLINE | J24: L1_1620_BYP__VAD__ | K24: 73.982021 | N24: Handle | O24: Figure Type | P24: SSIAttribute1 | Q24: length
H25: 2A5F6 | I25: POLYLINE | J25: L1_1620_BYP__DEC__ | K25: 35.254016 | N25: 2B0D6 | O25: POLYLINE | V25: 1205_700 | W25: 34.718 | Y25: L4_1205_700__DDR_N | Z25: 941 | AA25: 34.715489 | AB25: =+AA25-W25 -> -0.0025112996
H26: 2A5F7 | I26: POLYLINE | J26: L1_1580_BYP__SP_N4 | K26: 20.530019 | N26: 2AA80 | O26: POLYLINE | V26: 1255_775_SLT_E | W26: 9.493 | Y26: L4_1255_775B_SLT_E | Z26: 288 | AA26: 9.6719458 | AB26: =+AA26-W26 -> 0.17894582
H27: 2A5F8 | I27: POLYLINE | J27: L1_1580_BYP__SP_N3 | K27: 24.626771 | N27: 2AE72 | O27: POLYLINE | V27: 1305_670_OP | W27: 3.722 | Y27: L4_1305_670__OPD_S | Z27: 149 | AA27: 3.7247251 | AB27: =+AA27-W27 -> 0.0027250905
A28: L4_1405_685_RB_STRIP | B28: 61 | C28: 1405_685_STRIP | D28: 61 | H28: 2A62A | I28: POLYLINE | J28: L1_1680____ACC_W | K28: 2.7766919 | N28: 2B054 | O28: POLYLINE | V28: 1355_670_OP | W28: 29.271 | Y28: L4_1355_670__OPD_S | Z28: 922 | AA28: 29.288161 | AB28: =+AA28-W28 -> 0.017161074
A29: L1_1620_BYP VAD JB CUD | B29: 45 | C29: 1620_VAD_JB_CUD | D29: 45 | H29: 2A62B | I29: POLYLINE | J29: L1_1680____DEC__ | K29: 60.181373 | N29: 2ADD7 | O29: POLYLINE | V29: 1355_685_SLT_E | W29: 9.876 | Y29: L4_1355_685A_SLT_E | Z29: 280 | AA29: 9.8549697 | AB29: =+AA29-W29 -> -0.021030274
A30: L1_1680 DEC JB CUD | B30: 34 | C30: 1680_DEC_JB_CUD | D30: 34 | H30: 2A64A | I30: POLYLINE | J30: L1_1730____VAD_E | K30: 1.5863228 | N30: 2ADD6 | O30: POLYLINE | V30: 1405_700_OP | W30: 2.656 | Y30: L4_1405_700__OPD_S | Z30: 66 | AA30: 2.6555291 | AB30: =+AA30-W30 -> -0.00047085328
A31: L4_1655_530_SOLO_STRIP | B31: 24 | C31: 1655_530_STRIP | D31: 24 | H31: 2A681 | I31: POLYLINE | J31: L2_1845_455A_SLT_N | K31: 1.8466299 | N31: 2AE7B | O31: POLYLINE | V31: 1605_880 | W31: 53.915 | Y31: L4_1605_880__DDR_N | Z31: 1332 | AA31: 53.94275 | AB31: =+AA31-W31 -> 0.027750426
H32: 2A682 | I32: POLYLINE | J32: L2_1845_455A_SLT_S | K32: 2.6493556 | N32: 2A680 | O32: POLYLINE | V32: 1620_VAD | W32: 74.015 | Y32: L1_1620_BYP__VAD__ | Z32: 1976 | AA32: 73.982021 | AB32: =+AA32-W32 -> -0.032979346
H33: 2AA80 | I33: POLYLINE | J33: L4_1605_880__DDR_N | K33: 53.94275 | N33: 2A681 | O33: POLYLINE | V33: 1620_DEC | W33: 35.281 | Y33: L1_1620_BYP__DEC__ | Z33: 1228 | AA33: 35.254016 | AB33: =+AA33-W33 -> -0.026983841
H34: 2ADD6 | I34: POLYLINE | J34: L4_1355_670__OPD_S | K34: 29.288161 | N34: 2A682 | O34: POLYLINE | V34: 1580_BYP_SP#03 | W34: 24.484 | Y34: L1_1580_BYP__SP_N3 | Z34: 953 | AA34: 24.626771 | AB34: =+AA34-W34 -> 0.1427715
H35: 2ADD7 | I35: POLYLINE | J35: L4_1355_685A_SLT_E | K35: 9.8549697 | N35: 2A5F5 | O35: POLYLINE | V35: 1580_BYP_SP#04 | W35: 20.506 | Y35: L1_1580_BYP__SP_N4 | Z35: 736 | AA35: 20.530019 | AB35: =+AA35-W35 -> 0.024019021
H36: 2AE69 | I36: POLYLINE | J36: L4_1305_670__OPD_S | K36: 3.7247251 | N36: 2A5F7 | O36: POLYLINE | V36: 1680_DEC | W36: 61.007 | Y36: L1_1680____DEC__ | Z36: 2234 | AA36: 60.181373 | AB36: =+AA36-W36 -> -0.82562745
H37: 2AE72 | I37: POLYLINE | J37: L4_1255_775B_SLT_E | K37: 9.6719458 | N37: 2A5F8 | O37: POLYLINE | V37: 1680_ACC | W37: 2.644 | Y37: L1_1680____ACC_W | Z37: 157 | AA37: 2.7766919 | AB37: =+AA37-W37 -> 0.13269194
H38: 2AE7B | I38: POLYLINE | J38: L4_1205_700__DDR_N | K38: 34.715489 | N38: 2A5F6 | O38: POLYLINE | V38: 1705_950 | W38: 3.399 | Y38: L4_1705_950__DDR_E | Z38: 180 | AA38: 3.7257945 | AB38: =+AA38-W38 -> 0.32679455
H39: 2B054 | I39: POLYLINE | J39: L4_1405_700__OPD_S | K39: 2.6555291 | N39: 2A62B | O39: POLYLINE | V39: 1730_VAD | W39: 1.613 | Y39: L1_1730____VAD_E | Z39: 47 | AA39: 1.5863228 | AB39: =+AA39-W39 -> -0.026677208
H40: 2B0D6 | I40: POLYLINE | J40: L4_1755_950__DDR_E | K40: 30.93844 | N40: 2A62A | O40: POLYLINE | V40: 1755_950 | W40: 30.924 | Y40: L4_1755_950__DDR_E | Z40: 1050 | AA40: 30.93844 | AB40: =+AA40-W40 -> 0.014440136
H41: 2B0FF | I41: POLYLINE | J41: L4_1705_950__DDR_E | K41: 3.7257945 | N41: 2A64A | O41: POLYLINE | V41: 1845_420_S | W41: 2.444 | Y41: L2_1845_455A_SLT_S | Z41: 60 | AA41: 2.6493556 | AB41: =+AA41-W41 -> 0.20535558
...

Sheet Instructions
A2: End of Month Survey Data
A3: 1 | B3: Enter the month the End Of Month Survey report is for in cell A2 in XXXX 216 worksheet.
A4: 2 | B4: Enter the development name or number in colunm A of XXXX 2016 sheet
A5: 3 | B5: Select development dimensions for each heading form drop down menu in column B
A6: 4 | B6: Enter design gradient for each development headingin Column C
A7: 5 | B7: Select profile type from drop down menu in column D. Profile and dimension will automatically give an design area of the development which appears in Column E
A8: 6 | B8: Enter the metres of advance measured for each development heading in Column F
A9: 7 | B9: After confirmation from the geology manager enter the advance in ore for each of the development heading in column H. This will then calculate the advance in waste (total metres - ore metres), this will appear in column G
A10: 8 | B10: Enter the measured volumes for ore, waste and total for the development.
A11: 9 | B11: Enter the designed stripping for each heading
A12: 10 | B12: Enter the actual stripping for each heading
A15: For End of Month Claim
A16: 11 | B16: Select the nearest truck loading bay from the drop down menu. Truck must be developed. Column T
A17: 12 | B17: Select the haulage destination for waste from the drop down menu column U
A18: 13 | B18: Select the haulage destination for ore from the drop down menu column V
A19: 14 | B19: Select the ground support type from the drop down menu column W.
A20: 15 | B20: Select the Contract item number for the development heading from the drop down list. Item number and description can be found in the "Lists" worksheet
A21: 16 | B21: Development advance for the different Contract items is summarised in Claim Sum worksheet. You should be able to copy and paste this into the monthly claim calculator
A22: 17 | B22: Estimates for over break, rock bolts, fibrecrete m2, mesh m2 and haulage t.km are calculated and shown for each development heading. These can be used to check as default numbers and checks against the claim.

Sheet Stripping
C2: BOSA
C3: END OF MONTH STRIPPING
H5: Manual Add
A6: 1 | B6: 2 | C6: 3 | D6: 4 | E6: 5 | F6: 6 | G6: 7 | H6: 8 | I6: 9
A7: Drive Name | B7: Stripping | C7: Ground Support | D7: Width | E7: Design Strip | F7: Quantity | G7: Total Design Strip | H7: Actual | I7: Stripping Pay
C8: Design Profile | D8: & Height (m) | E8: Volume (m³) | G8: Volume (m3) | I8: Volume (m3)
A9: SOUTH DECLINE | B9: Back_strip_decline | C9: =IF($A9="",0,VLOOKUP($A9,Heading_ids!$A$4:$H$46,5,FALSE)) -> GSS_01 | D9: =IF($A9="",0,VLOOKUP($A9,Heading_ids!$A$4:$H$46,2,FALSE)) -> 5.5mW x 5.8mH - RS | E9: =IF($B9="",0,VLOOKUP($B9,Stripping_cal!$B$4:$H$33,7,FALSE)) -> 180 | F9: 1 | G9: =+F9*E9 -> 180 | I9: =+G9+I21 -> 180
A10: NORTH DECLINE | B10: Back_strip_decline | C10: =IF($A10="",0,VLOOKUP($A10,Heading_ids!$A$4:$H$46,5,FALSE)) -> GSS_02 | D10: 5.5mW x 5.8mH - RS | E10: =IF($B10="",0,VLOOKUP($B10,Stripping_cal!$B$4:$H$33,7,FALSE)) -> 180 | F10: 1 | G10: =+F10*E10 -> 180 | I10: =+G10+I22 -> 180
A11: MS_1040_ACC_waste | B11: Back_strip_intersection | C11: =IF($A11="",0,VLOOKUP($A11,Heading_ids!$A$4:$H$46,5,FALSE)) -> GSS_02 | D11: 5.5mW x 5.8mH - RS | E11: 48.9 | F11: 1 | G11: =+F11*E11 -> 48.9 | I11: =+G11+G12 -> 146.7
A12: MS_1040_ACC_waste | B12: Std_Fillet | C12: =IF($A12="",0,VLOOKUP($A12,Heading_ids!$A$4:$H$46,5,FALSE)) -> GSS_02 | D12: 5.5mW x 5.8mH - RS | E12: 48.9 | F12: 2 | G12: =+F12*E12 -> 97.8 | I12: =+G12+I24 -> 97.8
A13: MS900_ACC_E | C13: =IF($A13="",0,VLOOKUP($A13,Heading_ids!$A$4:$H$46,5,FALSE)) -> GSS_01 | D13: 5.0mW x 5.0mH - RS | E13: =IF($B13="",0,VLOOKUP($B13,Stripping_cal!$B$4:$H$33,7,FALSE)) -> 0 | G13: =+F13*E13 -> 0 | I13: =+G13+I25 -> 0
A14: MS900_DDR_N_waste | C14: =IF($A14="",0,VLOOKUP($A14,Heading_ids!$A$4:$H$46,5,FALSE)) -> GSS_01 | D14: 5.5mW x 5.8mH - RS | E14: =IF($B14="",0,VLOOKUP($B14,Stripping_cal!$B$4:$H$33,7,FALSE)) -> 0 | G14: =+F14*E14 -> 0 | I14: =+G14+I26 -> 0
A15: MS900_DDR_N_waste | B15: Std_Fillet | C15: =IF($A15="",0,VLOOKUP($A15,Heading_ids!$A$4:$H$46,5,FALSE)) -> GSS_01 | D15: 5.5mW x 5.8mH - RS | E15: =IF($B15="",0,VLOOKUP($B15,Stripping_cal!$B$4:$H$33,7,FALSE)) -> 30.2 | F15: 2 | G15: =+F15*E15 -> 60.4 | I15: =+G15+I27 -> 60.4
A16: MS900_DDR_N_waste1 | C16: =IF($A16="",0,VLOOKUP($A16,Heading_ids!$A$4:$H$46,5,FALSE)) -> GSS_01 | D16: 5.5mW x 5.8mH - RS | E16: =IF($B16="",0,VLOOKUP($B16,Stripping_cal!$B$4:$H$33,7,FALSE)) -> 0 | F16: 1 | G16: =+F16*E16 -> 0 | I16: =+G16+I28 -> 0
A17: S900_SMP W | C17: =IF($A17="",0,VLOOKUP($A17,Heading_ids!$A$4:$H$46,5,FALSE)) -> GSS_01 | D17: 5.0mW x 5.0mH - RS | E17: =IF($B17="",0,VLOOKUP($B17,Stripping_cal!$B$4:$H$33,7,FALSE)) -> 0 | G17: =+F17*E17 -> 0 | I17: =+G17+I29 -> 0
A18: S890_SP_W | B18: Back_strip_intersection | C18: =IF($A18="",0,VLOOKUP($A18,Heading_ids!$A$4:$H$46,5,FALSE)) -> GSS_01 | D18: 5.5mW x 6.5mH - RS | E18: =IF($B18="",0,VLOOKUP($B18,Stripping_cal!$B$4:$H$33,7,FALSE)) -> 48.9 | F18: 1 | G18: =+F18*E18 -> 48.9 | I18: =+G18+G19 -> 109.3
A19: S890_SP_W | B19: Std_Fillet | C19: =IF($A19="",0,VLOOKUP($A19,Heading_ids!$A$4:$H$46,5,FALSE)) -> GSS_01 | D19: 5.5mW x 6.5mH - RS | E19: =IF($B19="",0,VLOOKUP($B19,Stripping_cal!$B$4:$H$33,7,FALSE)) -> 30.2 | F19: 2 | G19: =+F19*E19 -> 60.4 | H19: 83.7 | I19: =+G19+I31 -> 60.4
A20: MS_1040_ACC_OD | C20: =IF($A20="",0,VLOOKUP($A20,Heading_ids!$A$4:$H$46,5,FALSE)) -> GSS_02 | D20: 5.5mW x 5.8mH - RS | E20: =IF($B20="",0,VLOOKUP($B20,Stripping_cal!$B$4:$H$33,7,FALSE)) -> 0 | G20: =+F20*E20 -> 0 | I20: =+G20+I30 -> 0
A21: MS900_DDR_N_OD | C21: =IF($A21="",0,VLOOKUP($A21,Heading_ids!$A$4:$H$46,5,FALSE)) -> GSS_01 | D21: 5.0mW x 5.0mH - RS | E21: =IF($B21="",0,VLOOKUP($B21,Stripping_cal!$B$4:$H$33,7,FALSE)) -> 0 | I21: =+G21+I31 -> 0
C22: =IF($A22="",0,VLOOKUP($A22,Heading_ids!$A$4:$H$46,5,FALSE)) -> 0 | D22: 5.0mW x 5.0mH - RS | E22: =IF($B22="",0,VLOOKUP($B22,Stripping_cal!$B$4:$H$33,7,FALSE)) -> 0

Sheet Stripping_cal
B1: 1 | C1: 2 | D1: 3 | E1: 4 | F1: 5 | G1: 6 | H1: 7
B2: STRIPPING CALCULATIONS
B3: Description | C3: Ground Support | D3: length | E3: Width | F3: Height | G3: Area | H3: Stripping Volume (m3)
B4: Std_Fillet | D4: 3 | E4: 3 | H4: 30.2
B5: Back_strip_intersection | H5: 48.9
B6: Back_strip_decline | H6: 180
B7: S905 DPB_strip | H7: 118.5

Sheet Heading_profile
A1: 9
B2: Profile selection
B3: Size | C3: profile | D3: Area | F3: Size | G3: profile | H3: Area | J3: Profiles
B4: 4.5mW x 5.8mH - RS | C4: Flat backs | D4: 25.7 | F4: 4.5 x 4.5 | G4: Sqr | J4: Arch | K4: Arched backs
B5: 5.0mW x 5.0mH - RS | C5: Flat backs | D5: 24.519 | F5: 4.5 x 5.5 | G5: Sqr | J5: Sqr | K5: Square backs
B6: 5.5mW x 5.5mH - FA | C6: Flat backs | D6: 28.348 | F6: 5.0 x 5.0 | G6: Sqr | J6: Rnd | K6: Raisebore
B7: 5.5mW x 6.0mH - FA | C7: Flat backs | D7: 31.349
B8: 5.5mW x 5.8mH - RS | C8: Round Shoulders | D8: 31.12 | F8: 5.5 x 4.5 | G8: Sqr
B9: 5.0mW x 5.0mH - FA | C9: Flat backs | D9: 23.44
B10: 5.0mW x 6.0mH - RS | C10: Round Shoulders | D10: 29.517
B11: 4.0mW x 4.0mH - RS | C11: Round Shoulders | D11: 32 | F11: 4.0X4.0 | G11: Arch
B12: 4.0mW x 4.0mH - FA | C12: Flat backs | D12: 16 | F12: 4.0X4.0 | G12: Flat backs
B13: 6.0mW x 5.5mH - FA | C13: Flat backs | D13: 30.84
B14: 4.0mW x 4.0mH - RS | C14: Round Shoulders | D14: 16
B15: 5.5mW x 6.5mH - RS | C15: Flat backs | D15: 34.8 | K15: 24.6 | L15: 3.7
L16: =+L15*K15 -> 91.02
B45: Raise Profiles | C45: Area
B46: 2 dia | C46: =2^2*PI()/4 -> 3.1415927
B47: 2 x 2 | C47: 4
B48: 2.5 dia | C48: =2.5^2*PI()/4 -> 4.9087385
B49: 0.348 dia | C49: =0.348^2*PI()/4 -> 0.095114859
B50: G | C50: =3.5*3.5 -> 12.25
B51: 3.0 dia | C51: =3^2*PI()/4 -> 7.0685835
B52: 3.5 dia | C52: =3.5^2*PI()/4 -> 9.6211275
B53: 3.0 x 4.0 | C53: =3*4 -> 12
B54: 4 x 4 | C54: 16
B55: 4.5 dia | C55: =4.5^2*PI()/4 -> 15.904313
B56: 6 x 4 | C56: 24

Sheet Sheet1
B2: L4_1305_625B_SLT_W | C2: 333
B3: L4_1305_625B_SLT_E | C3: 308
B4: L4_1355_595__DDR_W | C4: 57
B5: L4_1405_715__DDR_N | C5: 114 | H5: L4_1705_950__DDR_E_WASTE
B6: L4_1455_700B_SLT_E | C6: 413 | H6: L4_1755_970__DDR_W_Waste
B7: L4_1455_700B_SLT_W | C7: 479 | H7: L1_1850_330__DDR_N_WASTE
B8: L1_1550____SP_E | C8: 753
B9: L1_1560____DDC_N | C9: 122
B10: L1_1560____DDC_S | C10: 284
B11: L1_1565____DEC__ | C11: 1761
B12: L1_1580____INC__ | C12: 987
B13: L1_1580____ACC_W | C13: 1062
B14: L1_1580____SMP_S | C14: 191
B15: L1_1580____RAD_W | C15: 109
B16: L1_1640____SMP_E | C16: 250
B17: L1_1635____CUD_E | C17: 221
B18: L1_1630____RAD_W | C18: 446
B19: L1_1630____DEC__ | C19: 1826
... B30: L1_1900_315__DDR_W | C30: 101
